Workbook

Sheet THANG B.LUONG
A1: THANG BẢNG LƯƠNG | J1: ĐVT: 1000 ĐỒNG
A3: STT | B3: VỊ TRÍ | C3: BẬC LƯƠNG | N3: Hệ số bậc | O3: Điểm tham khảo
C4: 1 | D4: 2 | E4: 3 | F4: 4 | G4: 5 | H4: 6 | I4: 7 | J4: 8 | K4: 9 | L4: 10
A5: =COUNTA($B$4:B5) -> 1 | B5: CHỦ TỊCH | D5: =ROUND(C5*$N$5,-2) -> 0 | E5: =ROUND(D5*$N$5,-2) -> 0 | F5: =ROUND(E5*$N$5,-2) -> 0 | G5: =ROUND(F5*$N$5,-2) -> 0 | H5: =ROUND(G5*$N$5,-2) -> 0 | N5: 1.3
A6: =COUNTA($B$4:B6) -> 2 | B6: TỔNG GIÁM ĐỐC | D6: =ROUND(C6*$N$5,-2) -> 0 | E6: =ROUND(D6*$N$5,-2) -> 0 | F6: =ROUND(E6*$N$5,-2) -> 0 | G6: =ROUND(F6*$N$5,-2) -> 0 | H6: =ROUND(G6*$N$5,-2) -> 0 | N6: 1.3
A7: =COUNTA($B$4:B7) -> 3 | B7: TRƯỞNG BAN ĐMCC | C7: =ROUND(D7/N7,-1) -> 0 | D7: =ROUND(E7/N7,-1) -> 0 | E7: =ROUND(O7,-1) -> 0 | F7: =ROUND(E7*$N7,-1) -> 0 | G7: =ROUND(F7*$N7,-1) -> 0 | H7: =ROUND(G7*$N7,-1) -> 0 | I7: =ROUND(H7*$N7,-1) -> 0 | J7: =ROUND(I7*$N7,-1) -> 0 | K7: =ROUND(J7*$N7,-1) -> 0 | L7: =ROUND(K7*$N7,-1) -> 0 | N7: 1.2
A8: =COUNTA($B$4:B8) -> 4 | B8: TRƯỞNG BAN KIỂM SOÁT NỘI BỘ | C8: =ROUND(D8/N8,-1) -> 0 | D8: =ROUND(E8/N8,-1) -> 0 | E8: =ROUND(O8,-1) -> 0 | F8: =ROUND(E8*$N8,-1) -> 0 | G8: =ROUND(F8*$N8,-1) -> 0 | H8: =ROUND(G8*$N8,-1) -> 0 | I8: =ROUND(H8*$N8,-1) -> 0 | J8: =ROUND(I8*$N8,-1) -> 0 | K8: =ROUND(J8*$N8,-1) -> 0 | L8: =ROUND(K8*$N8,-1) -> 0 | N8: 1.2
A9: =COUNTA($B$4:B9) -> 5 | B9: Chuyên viên pháp chế | C9: =ROUND(O9,-1) -> 0 | D9: =ROUND(C9*$N9,-1) -> 0 | E9: =ROUND(D9*$N9,-1) -> 0 | F9: =ROUND(E9*$N9,-1) -> 0 | G9: =ROUND(F9*$N9,-1) -> 0 | H9: =ROUND(G9*$N9,-1) -> 0 | I9: =ROUND(H9*$N9,-1) -> 0 | J9: =ROUND(I9*$N9,-1) -> 0 | K9: =ROUND(J9*$N9,-1) -> 0 | L9: =ROUND(K9*$N9,-1) -> 0 | N9: 1.11
A10: =COUNTA($B$4:B10) -> 6 | B10: Chuyên viên kiểm soát tài chính | C10: =ROUND(O10,-1) -> 0 | D10: =ROUND(C10*$N10,-1) -> 0 | E10: =ROUND(D10*$N10,-1) -> 0 | F10: =ROUND(E10*$N10,-1) -> 0 | G10: =ROUND(F10*$N10,-1) -> 0 | H10: =ROUND(G10*$N10,-1) -> 0 | I10: =ROUND(H10*$N10,-1) -> 0 | J10: =ROUND(I10*$N10,-1) -> 0 | K10: =ROUND(J10*$N10,-1) -> 0 | L10: =ROUND(K10*$N10,-1) -> 0 | N10: 1.11
A11: =COUNTA($B$4:B11) -> 7 | B11: Chuyên viên kiểm soát quy trình | C11: =ROUND(O11,-1) -> 0 | D11: =ROUND(C11*$N11,-1) -> 0 | E11: =ROUND(D11*$N11,-1) -> 0 | F11: =ROUND(E11*$N11,-1) -> 0 | G11: =ROUND(F11*$N11,-1) -> 0 | H11: =ROUND(G11*$N11,-1) -> 0 | I11: =ROUND(H11*$N11,-1) -> 0 | J11: =ROUND(I11*$N11,-1) -> 0 | K11: =ROUND(J11*$N11,-1) -> 0 | L11: =ROUND(K11*$N11,-1) -> 0 | N11: 1.11
A12: =COUNTA($B$4:B12) -> 8 | B12: GIÁM ĐỐC HCNS | C12: =ROUND(D12/N12,-1) -> 0 | D12: =ROUND(E12/N12,-1) -> 0 | E12: =ROUND(O12,-1) -> 0 | F12: =ROUND(E12*$N12,-1) -> 0 | G12: =ROUND(F12*$N12,-1) -> 0 | H12: =ROUND(G12*$N12,-1) -> 0 | I12: =ROUND(H12*$N12,-1) -> 0 | J12: =ROUND(I12*$N12,-1) -> 0 | K12: =ROUND(J12*$N12,-1) -> 0 | L12: =ROUND(K12*$N12,-1) -> 0 | N12: 1.2
A13: =COUNTA($B$4:B13) -> 9 | B13: Nhân viên hành chính/ HCNS NM | C13: =ROUND(O13,-1) -> 0 | D13: =ROUND(C13*$N13,-1) -> 0 | E13: =ROUND(D13*$N13,-1) -> 0 | F13: =ROUND(E13*$N13,-1) -> 0 | G13: =ROUND(F13*$N13,-1) -> 0 | H13: =ROUND(G13*$N13,-1) -> 0 | I13: =ROUND(H13*$N13,-1) -> 0 | J13: =ROUND(I13*$N13,-1) -> 0 | K13: =ROUND(J13*$N13,-1) -> 0 | L13: =ROUND(K13*$N13,-1) -> 0 | N13: 1.1
A14: =COUNTA($B$4:B14) -> 10 | B14: Nhân viên nhân sự | C14: =ROUND(O14,-1) -> 0 | D14: =ROUND(C14*$N14,-1) -> 0 | E14: =ROUND(D14*$N14,-1) -> 0 | F14: =ROUND(E14*$N14,-1) -> 0 | G14: =ROUND(F14*$N14,-1) -> 0 | H14: =ROUND(G14*$N14,-1) -> 0 | I14: =ROUND(H14*$N14,-1) -> 0 | J14: =ROUND(I14*$N14,-1) -> 0 | K14: =ROUND(J14*$N14,-1) -> 0 | L14: =ROUND(K14*$N14,-1) -> 0 | N14: 1.1
A15: =COUNTA($B$4:B15) -> 11 | B15: Trưởng Giám sát Nhà máy | C15: =ROUND(O15,-1) -> 0 | D15: =ROUND(C15*$N15,-1) -> 0 | E15: =ROUND(D15*$N15,-1) -> 0 | F15: =ROUND(E15*$N15,-1) -> 0 | G15: =ROUND(F15*$N15,-1) -> 0 | H15: =ROUND(G15*$N15,-1) -> 0 | I15: =ROUND(H15*$N15,-1) -> 0 | J15: =ROUND(I15*$N15,-1) -> 0 | K15: =ROUND(J15*$N15,-1) -> 0 | L15: =ROUND(K15*$N15,-1) -> 0 | N15: 1.13
A16: =COUNTA($B$4:B16) -> 12 | B16: Nhân viên Giám sát | C16: =ROUND(O16,-1) -> 0 | D16: =ROUND(C16*$N16,-1) -> 0 | E16: =ROUND(D16*$N16,-1) -> 0 | F16: =ROUND(E16*$N16,-1) -> 0 | G16: =ROUND(F16*$N16,-1) -> 0 | H16: =ROUND(G16*$N16,-1) -> 0 | I16: =ROUND(H16*$N16,-1) -> 0 | J16: =ROUND(I16*$N16,-1) -> 0 | K16: =ROUND(J16*$N16,-1) -> 0 | L16: =ROUND(K16*$N16,-1) -> 0 | N16: 1.1
A17: =COUNTA($B$4:B17) -> 13 | B17: Chuyên viên IT | C17: =ROUND(O17,-1) -> 12670 | D17: =ROUND(C17*$N17,-1) -> 14190 | E17: =ROUND(D17*$N17,-1) -> 15890 | F17: =ROUND(E17*$N17,-1) -> 17800 | G17: =ROUND(F17*$N17,-1) -> 19940 | H17: =ROUND(G17*$N17,-1) -> 22330 | I17: =ROUND(H17*$N17,-1) -> 25010 | J17: =ROUND(I17*$N17,-1) -> 28010 | K17: =ROUND(J17*$N17,-1) -> 31370 | L17: =ROUND(K17*$N17,-1) -> 35130 | N17: 1.12 | O17: 12672
A18: =COUNTA($B$4:B18) -> 14 | B18: Nhân viên IT | C18: =ROUND(O18,-1) -> 0 | D18: =ROUND(C18*$N18,-1) -> 0 | E18: =ROUND(D18*$N18,-1) -> 0 | F18: =ROUND(E18*$N18,-1) -> 0 | G18: =ROUND(F18*$N18,-1) -> 0 | H18: =ROUND(G18*$N18,-1) -> 0 | I18: =ROUND(H18*$N18,-1) -> 0 | J18: =ROUND(I18*$N18,-1) -> 0 | K18: =ROUND(J18*$N18,-1) -> 0 | L18: =ROUND(K18*$N18,-1) -> 0 | N18: 1.1
A19: =COUNTA($B$4:B19) -> 15 | B19: Bảo vệ | C19: =ROUND(O19,-1) -> 0 | D19: =ROUND(C19*$N19,-1) -> 0 | E19: =ROUND(D19*$N19,-1) -> 0 | F19: =ROUND(E19*$N19,-1) -> 0 | G19: =ROUND(F19*$N19,-1) -> 0 | H19: =ROUND(G19*$N19,-1) -> 0 | I19: =ROUND(H19*$N19,-1) -> 0 | J19: =ROUND(I19*$N19,-1) -> 0 | K19: =ROUND(J19*$N19,-1) -> 0 | L19: =ROUND(K19*$N19,-1) -> 0 | N19: 1.05
A20: =COUNTA($B$4:B20) -> 16 | B20: Tạp vụ | C20: =ROUND(O20,-1) -> 0 | D20: =ROUND(C20*$N20,-1) -> 0 | E20: =ROUND(D20*$N20,-1) -> 0 | F20: =ROUND(E20*$N20,-1) -> 0 | G20: =ROUND(F20*$N20,-1) -> 0 | H20: =ROUND(G20*$N20,-1) -> 0 | I20: =ROUND(H20*$N20,-1) -> 0 | J20: =ROUND(I20*$N20,-1) -> 0 | K20: =ROUND(J20*$N20,-1) -> 0 | L20: =ROUND(K20*$N20,-1) -> 0 | N20: 1.05
A21: =COUNTA($B$4:B21) -> 17 | B21: GIÁM ĐỐC TCKT | C21: =ROUND(D21/N21,-1) -> 0 | D21: =ROUND(E21/N21,-1) -> 0 | E21: =ROUND(O21,-1) -> 0 | F21: =ROUND(E21*$N21,-1) -> 0 | G21: =ROUND(F21*$N21,-1) -> 0 | H21: =ROUND(G21*$N21,-1) -> 0 | I21: =ROUND(H21*$N21,-1) -> 0 | J21: =ROUND(I21*$N21,-1) -> 0 | K21: =ROUND(J21*$N21,-1) -> 0 | L21: =ROUND(K21*$N21,-1) -> 0 | N21: 1.2
A22: =COUNTA($B$4:B22) -> 18 | B22: Chuyên viên tài chính | C22: =ROUND(O22,-1) -> 0 | D22: =ROUND(C22*$N22,-1) -> 0 | E22: =ROUND(D22*$N22,-1) -> 0 | F22: =ROUND(E22*$N22,-1) -> 0 | G22: =ROUND(F22*$N22,-1) -> 0 | H22: =ROUND(G22*$N22,-1) -> 0 | I22: =ROUND(H22*$N22,-1) -> 0 | J22: =ROUND(I22*$N22,-1) -> 0 | K22: =ROUND(J22*$N22,-1) -> 0 | L22: =ROUND(K22*$N22,-1) -> 0 | N22: 1.2
A23: =COUNTA($B$4:B23) -> 19 | B23: Kế toán quản trị | C23: =ROUND(O23,-1) -> 0 | D23: =ROUND(C23*$N23,-1) -> 0 | E23: =ROUND(D23*$N23,-1) -> 0 | F23: =ROUND(E23*$N23,-1) -> 0 | G23: =ROUND(F23*$N23,-1) -> 0 | H23: =ROUND(G23*$N23,-1) -> 0 | I23: =ROUND(H23*$N23,-1) -> 0 | J23: =ROUND(I23*$N23,-1) -> 0 | K23: =ROUND(J23*$N23,-1) -> 0 | L23: =ROUND(K23*$N23,-1) -> 0 | N23: 1.12
A24: =COUNTA($B$4:B24) -> 20 | B24: Kế toán ………… | D24: =ROUND(C24*$N24,-1) -> 0 | E24: =ROUND(D24*$N24,-1) -> 0 | F24: =ROUND(E24*$N24,-1) -> 0 | G24: =ROUND(F24*$N24,-1) -> 0 | H24: =ROUND(G24*$N24,-1) -> 0 | I24: =ROUND(H24*$N24,-1) -> 0 | J24: =ROUND(I24*$N24,-1) -> 0 | K24: =ROUND(J24*$N24,-1) -> 0 | L24: =ROUND(K24*$N24,-1) -> 0 | N24: 1.1
A25: =COUNTA($B$4:B25) -> 21 | B25: Kế toán quản lý nội bộ | C25: =ROUND(O25,-1) -> 0 | D25: =ROUND(C25*$N25,-1) -> 0 | E25: =ROUND(D25*$N25,-1) -> 0 | F25: =ROUND(E25*$N25,-1) -> 0 | G25: =ROUND(F25*$N25,-1) -> 0 | H25: =ROUND(G25*$N25,-1) -> 0 | I25: =ROUND(H25*$N25,-1) -> 0 | J25: =ROUND(I25*$N25,-1) -> 0 | K25: =ROUND(J25*$N25,-1) -> 0 | L25: =ROUND(K25*$N25,-1) -> 0 | N25: 1.13
A26: =COUNTA($B$4:B26) -> 22 | B26: Kế toán quản lý thuế | C26: =ROUND(O26,-1) -> 0 | D26: =ROUND(C26*$N26,-1) -> 0 | E26: =ROUND(D26*$N26,-1) -> 0 | F26: =ROUND(E26*$N26,-1) -> 0 | G26: =ROUND(F26*$N26,-1) -> 0 | H26: =ROUND(G26*$N26,-1) -> 0 | I26: =ROUND(H26*$N26,-1) -> 0 | J26: =ROUND(I26*$N26,-1) -> 0 | K26: =ROUND(J26*$N26,-1) -> 0 | L26: =ROUND(K26*$N26,-1) -> 0 | N26: 1.13
A27: =COUNTA($B$4:B27) -> 23 | B27: Kế toán thuế | C27: =ROUND(O27,-1) -> 0 | D27: =ROUND(C27*$N27,-1) -> 0 | E27: =ROUND(D27*$N27,-1) -> 0 | F27: =ROUND(E27*$N27,-1) -> 0 | G27: =ROUND(F27*$N27,-1) -> 0 | H27: =ROUND(G27*$N27,-1) -> 0 | I27: =ROUND(H27*$N27,-1) -> 0 | J27: =ROUND(I27*$N27,-1) -> 0 | K27: =ROUND(J27*$N27,-1) -> 0 | L27: =ROUND(K27*$N27,-1) -> 0 | N27: 1.1
A28: =COUNTA($B$4:B28) -> 24 | B28: Kế toán nội bộ | C28: =ROUND(O28,-1) -> 0 | D28: =ROUND(C28*$N28,-1) -> 0 | E28: =ROUND(D28*$N28,-1) -> 0 | F28: =ROUND(E28*$N28,-1) -> 0 | G28: =ROUND(F28*$N28,-1) -> 0 | H28: =ROUND(G28*$N28,-1) -> 0 | I28: =ROUND(H28*$N28,-1) -> 0 | J28: =ROUND(I28*$N28,-1) -> 0 | K28: =ROUND(J28*$N28,-1) -> 0 | L28: =ROUND(K28*$N28,-1) -> 0 | N28: 1.1
A29: =COUNTA($B$4:B29) -> 25 | B29: Nhân viên thu hồi công nợ | C29: =ROUND(O29,-1) -> 0 | D29: =ROUND(C29*$N29,-1) -> 0 | E29: =ROUND(D29*$N29,-1) -> 0 | F29: =ROUND(E29*$N29,-1) -> 0 | G29: =ROUND(F29*$N29,-1) -> 0 | H29: =ROUND(G29*$N29,-1) -> 0 | I29: =ROUND(H29*$N29,-1) -> 0 | J29: =ROUND(I29*$N29,-1) -> 0 | K29: =ROUND(J29*$N29,-1) -> 0 | L29: =ROUND(K29*$N29,-1) -> 0 | N29: 1.1
A30: =COUNTA($B$4:B30) -> 26 | B30: Thủ quỹ | C30: =ROUND(O30,-1) -> 0 | D30: =ROUND(C30*$N30,-1) -> 0 | E30: =ROUND(D30*$N30,-1) -> 0 | F30: =ROUND(E30*$N30,-1) -> 0 | G30: =ROUND(F30*$N30,-1) -> 0 | H30: =ROUND(G30*$N30,-1) -> 0 | I30: =ROUND(H30*$N30,-1) -> 0 | J30: =ROUND(I30*$N30,-1) -> 0 | K30: =ROUND(J30*$N30,-1) -> 0 | L30: =ROUND(K30*$N30,-1) -> 0 | N30: 1.1
A31: =COUNTA($B$4:B31) -> 27 | B31: Quản lý trạm cân | C31: =ROUND(O31,-1) -> 0 | D31: =ROUND(C31*$N31,-1) -> 0 | E31: =ROUND(D31*$N31,-1) -> 0 | F31: =ROUND(E31*$N31,-1) -> 0 | G31: =ROUND(F31*$N31,-1) -> 0 | H31: =ROUND(G31*$N31,-1) -> 0 | I31: =ROUND(H31*$N31,-1) -> 0 | J31: =ROUND(I31*$N31,-1) -> 0 | K31: =ROUND(J31*$N31,-1) -> 0 | L31: =ROUND(K31*$N31,-1) -> 0 | N31: 1.11
A32: =COUNTA($B$4:B76) -> 72 | B32: NV trạm cân | C32: =ROUND(O32,-1) -> 0 | D32: =ROUND(C32*$N32,-1) -> 0 | E32: =ROUND(D32*$N32,-1) -> 0 | F32: =ROUND(E32*$N32,-1) -> 0 | G32: =ROUND(F32*$N32,-1) -> 0 | H32: =ROUND(G32*$N32,-1) -> 0 | I32: =ROUND(H32*$N32,-1) -> 0 | J32: =ROUND(I32*$N32,-1) -> 0 | K32: =ROUND(J32*$N32,-1) -> 0 | L32: =ROUND(K32*$N32,-1) -> 0 | N32: 1.1
A33: =COUNTA($B$4:B33) -> 29 | B33: TRƯỞNG BAN DỰ ÁN CÔNG | C33: =ROUND(D33/N33,-1) -> 0 | D33: =ROUND(E33/N33,-1) -> 0 | E33: =ROUND(O33,-1) -> 0 | F33: =ROUND(E33*$N33,-1) -> 0 | G33: =ROUND(F33*$N33,-1) -> 0 | H33: =ROUND(G33*$N33,-1) -> 0 | I33: =ROUND(H33*$N33,-1) -> 0 | J33: =ROUND(I33*$N33,-1) -> 0 | K33: =ROUND(J33*$N33,-1) -> 0 | L33: =ROUND(K33*$N33,-1) -> 0 | N33: 1.2
A34: =COUNTA($B$4:B34) -> 30 | B34: NV nghiệm thu thanh toán | C34: =ROUND(O34,-1) -> 0 | D34: =ROUND(C34*$N34,-1) -> 0 | E34: =ROUND(D34*$N34,-1) -> 0 | F34: =ROUND(E34*$N34,-1) -> 0 | G34: =ROUND(F34*$N34,-1) -> 0 | H34: =ROUND(G34*$N34,-1) -> 0 | I34: =ROUND(H34*$N34,-1) -> 0 | J34: =ROUND(I34*$N34,-1) -> 0 | K34: =ROUND(J34*$N34,-1) -> 0 | L34: =ROUND(K34*$N34,-1) -> 0 | N34: 1.1
A35: =COUNTA($B$4:B35) -> 31 | B35: NV triển khai thực hiện dự án | C35: =ROUND(O35,-1) -> 0 | D35: =ROUND(C35*$N35,-1) -> 0 | E35: =ROUND(D35*$N35,-1) -> 0 | F35: =ROUND(E35*$N35,-1) -> 0 | G35: =ROUND(F35*$N35,-1) -> 0 | H35: =ROUND(G35*$N35,-1) -> 0 | I35: =ROUND(H35*$N35,-1) -> 0 | J35: =ROUND(I35*$N35,-1) -> 0 | K35: =ROUND(J35*$N35,-1) -> 0 | L35: =ROUND(K35*$N35,-1) -> 0 | N35: 1.1
A36: =COUNTA($B$4:B36) -> 32 | B36: TRƯỞNG BAN DỰ ÁN NGHIÊN CỨU | C36: =ROUND(D36/N36,-1) -> 0 | D36: =ROUND(E36/N36,-1) -> 0 | E36: =ROUND(O36,-1) -> 0 | F36: =ROUND(E36*$N36,-1) -> 0 | G36: =ROUND(F36*$N36,-1) -> 0 | H36: =ROUND(G36*$N36,-1) -> 0 | I36: =ROUND(H36*$N36,-1) -> 0 | J36: =ROUND(I36*$N36,-1) -> 0 | K36: =ROUND(J36*$N36,-1) -> 0 | L36: =ROUND(K36*$N36,-1) -> 0 | N36: 1.2
A37: =COUNTA($B$4:B37) -> 33 | B37: CV dự án nghiên cứu | C37: =ROUND(O37,-1) -> 0 | D37: =ROUND(C37*$N37,-1) -> 0 | E37: =ROUND(D37*$N37,-1) -> 0 | F37: =ROUND(E37*$N37,-1) -> 0 | G37: =ROUND(F37*$N37,-1) -> 0 | H37: =ROUND(G37*$N37,-1) -> 0 | I37: =ROUND(H37*$N37,-1) -> 0 | J37: =ROUND(I37*$N37,-1) -> 0 | K37: =ROUND(J37*$N37,-1) -> 0 | L37: =ROUND(K37*$N37,-1) -> 0 | N37: 1.11
A38: =COUNTA($B$4:B38) -> 34 | B38: TRƯỞNG BAN KẾ HOẠCH VẬT TƯ | C38: =ROUND(D38/N38,-1) -> 0 | D38: =ROUND(E38/N38,-1) -> 0 | E38: =ROUND(O38,-1) -> 0 | F38: =ROUND(E38*$N38,-1) -> 0 | G38: =ROUND(F38*$N38,-1) -> 0 | H38: =ROUND(G38*$N38,-1) -> 0 | I38: =ROUND(H38*$N38,-1) -> 0 | J38: =ROUND(I38*$N38,-1) -> 0 | K38: =ROUND(J38*$N38,-1) -> 0 | L38: =ROUND(K38*$N38,-1) -> 0 | N38: 1.2
A39: =COUNTA($B$4:B39) -> 35 | B39: CV thu mua vật tư | C39: =ROUND(O39,-1) -> 0 | D39: =ROUND(C39*$N39,-1) -> 0 | E39: =ROUND(D39*$N39,-1) -> 0 | F39: =ROUND(E39*$N39,-1) -> 0 | G39: =ROUND(F39*$N39,-1) -> 0 | H39: =ROUND(G39*$N39,-1) -> 0 | I39: =ROUND(H39*$N39,-1) -> 0 | J39: =ROUND(I39*$N39,-1) -> 0 | K39: =ROUND(J39*$N39,-1) -> 0 | L39: =ROUND(K39*$N39,-1) -> 0 | N39: 1.11
B40: NV Thu mua MMTB | C40: =ROUND(D40/$N40,-1) -> 0 | D40: =ROUND(E40/$N40,-1) -> 0 | E40: =ROUND(F40/$N40,-1) -> 0 | F40: =C39 -> 0 | G40: =ROUND(F40*$N40,-1) -> 0 | H40: =ROUND(G40*$N40,-1) -> 0 | I40: =ROUND(H40*$N40,-1) -> 0 | J40: =ROUND(I40*$N40,-1) -> 0 | K40: =ROUND(J40*$N40,-1) -> 0 | L40: =ROUND(K40*$N40,-1) -> 0 | N40: 1.1
A41: =COUNTA($B$4:B41) -> 37 | B41: CV thu mua MMTB | C41: =ROUND(O41,-1) -> 0 | D41: =ROUND(C41*$N41,-1) -> 0 | E41: =ROUND(D41*$N41,-1) -> 0 | F41: =ROUND(E41*$N41,-1) -> 0 | G41: =ROUND(F41*$N41,-1) -> 0 | H41: =ROUND(G41*$N41,-1) -> 0 | I41: =ROUND(H41*$N41,-1) -> 0 | J41: =ROUND(I41*$N41,-1) -> 0 | K41: =ROUND(J41*$N41,-1) -> 0 | L41: =ROUND(K41*$N41,-1) -> 0 | N41: 1.11
...

Sheet Luong VP
B1: 1 | C1: 2 | D1: 3 | E1: 4 | F1: 5 | G1: 6 | H1: 7 | I1: 8 | J1: 9 | K1: 10 | L1: 11 | M1: 12 | N1: 13 | O1: 14 | P1: 15 | Q1: 16 | R1: 17 | S1: 18 | T1: 19 | U1: 20 | V1: 21 | W1: 22 | X1: 23 | Y1: 24 | Z1: 25 | AA1: 26 | AB1: 27 | AC1: 28 | AD1: 29 | AE1: 30 | AF1: 31 | AG1: 32 | AH1: 33 | AI1: 34 | AJ1: 35 | AK1: 36 | AL1: 37 | AM1: 38 | AN1: 39 | AO1: 40 | AP1: 41
A2: Công ty TNHH CNSH Sài Gòn Xanh
J3: 43337 | X3: BẢNG LƯƠNG THÁNG 08 - BỘ PHẬN QUẢN LÝ | AK3: Tỷ lệ đóng BH | AL3: 0.015 | AN3: 0.105
A5: TT | B5: Mã NV | C5: Họ và tên | D5: Chức vụ | E5: Thâm niên làm việc | F5: Bậc | G5: Thâm niên | J5: Lương CB | K5: PHỤ CẤP (P2) | O5: PHÚC LỢI KHÁC (P2) | V5: Lương cơ bản (tháng) bao gồm phụ cấp | W5: Ngày công làm việc | X5: Ngày nghỉ phép hưởng lương | Y5: Ngày nghỉ Lễ Tết hưởng lương | Z5: Công CN (giờ) | AA5: Công tăng ca ngày thường (giờ) | AB5: Công lễ tết | AC5: Công tác xa | AD5: Mức đạt trong tháng | AE5: Lương theo doanh thu doanh số | AF5: Tổng bùn bốc | AG5: Thành tiền bốc bùn | AH5: Lương khác | AI5: Thi đua | AJ5: Hỗ trợ ngoài lương | AK5: Tổng thu nhập | AL5: BHXH BHYT | AM5: Lương tham gia BHXH | AN5: Tạm ứng | AO5: Thưởng lễ tết | AP5: Thực lãnh
G6: Năm | H6: Tháng | I6: Ngày | K6: NẶNG NHỌC ĐỘC HẠI | L6: TRÁCH NHIỆM | M6: THÂM NIÊN | N6: THU HÚT | O6: XĂNG | P6: ĐIỆN THOẠI | Q6: CƠM | R6: Kiêm nhiệm | S6: BHYT ĐẶC BIỆT | T6: VỊ TRÍ CẦN KN NHIỀU NĂM | U6: Vị trí đặc thù
O7: XĂNG | P7: ĐIỆN THOẠI | Q7: NHÀ Ở | R7: Kiêm nhiệm | S7: BHYT ĐẶC BIỆT | T7: VỊ TRÍ CẦN KN NHIỀU NĂM | U7: Vị trí đặc thù
B8: VĂN PHÒNG | AP8: =AP9+AP12+AP24+AP26+AP34+AP44+AP51+AP60+AP71+AP74+AP76+AP85+AP89+AP106+AP111+AP119+AP57+AP122+AP126+AP128+AP130+AP154+AP166+AP182 -> #REF!
C9: Ban lãnh đạo | AK9: =SUM(AK10:AK11) -> #REF! | AL9: =SUM(AL10:AL11) -> 1249.5 | AM9: =SUM(AM10:AM11) -> 11900 | AN9: =SUM(AN10:AN11) -> #REF! | AO9: =SUM(AO10:AO11) -> 0 | AP9: =SUM(AP10:AP11) -> #REF!
B10: LĐ01 | C10: Ngô Pa Ri | D10: CHỦ TỊCH | E10: 37987 | F10: 2 | G10: =DATEDIF(E10,$J$3,"y") -> 14 | H10: =DATEDIF(E10,$J$3,"ym") -> 7 | I10: =DATEDIF(E10,$J$3,"md") -> 24 | J10: =VLOOKUP(D10,'THANG B.LUONG'!$B$5:$I$513,F10+1,0) -> 0 | K10: 0 | L10: 8000 | M10: =IF(G10>=3,J10*(0.03+(G10-3)*0.01),0) -> 0 | N10: 0 | O10: 1000 | P10: 2000 | Q10: 0 | R10: 0 | S10: 0 | T10: 4000 | U10: 0 | V10: =SUM(J10:U10)-P10 -> 13000 | W10: =VLOOKUP(B10,#REF!,35,0) -> #REF! | X10: =VLOOKUP(B10,#REF!,37,0) -> #REF! | Y10: =VLOOKUP(B10,#REF!,38,0) -> #REF! | Z10: =VLOOKUP(B10,#REF!,72,0) -> #REF! | AA10: =VLOOKUP(B10,#REF!,71,0) -> #REF! | AB10: =VLOOKUP(B10,#REF!,36,0) -> #REF! | AK10: =V10/#REF!*(W10+Z10/8*2+AA10/8*1.5+AB10*3)+J10/#REF!*(X10+Y10)+AC10+P10+AE10+AG10+AH10+AI10+AJ10 -> #REF! | AL10: =AM10*$AN$3 -> 0 | AM10: 0 | AN10: =VLOOKUP(B10,#REF!,75,0) -> #REF! | AP10: =ROUND(AK10-AL10-AN10+AO10,-1) -> #REF!
B11: LĐ02 | C11: Nguyễn Văn Thảo | D11: TỔNG GIÁM ĐỐC | E11: 37347 | F11: 2 | G11: =DATEDIF(E11,$J$3,"y") -> 16 | H11: =DATEDIF(E11,$J$3,"ym") -> 4 | I11: =DATEDIF(E11,$J$3,"md") -> 24 | J11: =VLOOKUP(D11,'THANG B.LUONG'!$B$5:$I$513,F11+1,0) -> 0 | K11: 0 | L11: 6000 | M11: =IF(G11>=3,J11*(0.03+(G11-3)*0.01),0) -> 0 | N11: 0 | O11: 1000 | P11: 2000 | Q11: 0 | R11: 0 | S11: 0 | T11: 4000 | U11: 0 | V11: =SUM(J11:U11)-P11 -> 11000 | W11: =VLOOKUP(B11,#REF!,35,0) -> #REF! | X11: =VLOOKUP(B11,#REF!,37,0) -> #REF! | Y11: =VLOOKUP(B11,#REF!,38,0) -> #REF! | Z11: =VLOOKUP(B11,#REF!,72,0) -> #REF! | AA11: =VLOOKUP(B11,#REF!,71,0) -> #REF! | AB11: =VLOOKUP(B11,#REF!,36,0) -> #REF! | AK11: =V11/#REF!*(W11+Z11/8*2+AA11/8*1.5+AB11*3)+J11/#REF!*(X11+Y11)+AC11+P11+AE11+AG11+AH11+AI11+AJ11 -> #REF! | AL11: =AM11*$AN$3 -> 1249.5 | AM11: 11900 | AN11: =VLOOKUP(B11,#REF!,75,0) -> #REF! | AP11: =ROUND(AK11-AL11-AN11+AO11,-1) -> #REF!
C12: Phòng HCNS - NS | AK12: =SUM(AK13:AK23) -> #REF! | AL12: =SUM(AL13:AL23) -> 2864.085 | AM12: =SUM(AM13:AM23) -> 27277 | AN12: =SUM(AN13:AN23) -> #REF! | AO12: =SUM(AO13:AO23) -> 0 | AP12: =SUM(AP13:AP23) -> #REF!
B13: NS01 | C13: Nguyễn Đỗ Q. Phương | D13: GIÁM ĐỐC HCNS | E13: 40040 | F13: 1 | G13: =DATEDIF(E13,$J$3,"y") -> 9 | H13: =DATEDIF(E13,$J$3,"ym") -> 0 | I13: =DATEDIF(E13,$J$3,"md") -> 10 | J13: =VLOOKUP(D13,'THANG B.LUONG'!$B$5:$I$513,F13+1,0) -> 0 | K13: 0 | L13: 3000 | M13: =IF(G13>=3,J13*(0.03+(G13-3)*0.01),0) -> 0 | N13: 0 | O13: 1000 | P13: 1000 | Q13: 0 | R13: 0 | S13: 0 | T13: 0 | U13: 0 | V13: =SUM(J13:U13)-P13 -> 4000 | W13: =VLOOKUP(B13,#REF!,35,0) -> #REF! | X13: =VLOOKUP(B13,#REF!,37,0) -> #REF! | Y13: =VLOOKUP(B13,#REF!,38,0) -> #REF! | Z13: =VLOOKUP(B13,#REF!,72,0) -> #REF! | AA13: =VLOOKUP(B13,#REF!,71,0) -> #REF! | AB13: =VLOOKUP(B13,#REF!,36,0) -> #REF! | AK13: =V13/#REF!*(W13+Z13/8*2+AA13/8*1.5+AB13*3)+J13/#REF!*(X13+Y13)+AC13+P13+AE13+AG13+AH13+AI13+AJ13 -> #REF! | AL13: =AM13*$AN$3 -> 871.5 | AM13: 8300 | AN13: =VLOOKUP(B13,#REF!,75,0) -> #REF! | AP13: =ROUND(AK13-AL13-AN13+AO13,-1) -> #REF!
B14: NS02 | C14: Lê Hoàng Tuấn | D14: Bảo vệ | E14: 41838 | F14: 2 | G14: =DATEDIF(E14,$J$3,"y") -> 4 | H14: =DATEDIF(E14,$J$3,"ym") -> 1 | I14: =DATEDIF(E14,$J$3,"md") -> 7 | J14: =VLOOKUP(D14,'THANG B.LUONG'!$B$5:$I$513,F14+1,0) -> 0 | K14: 0 | L14: 200 | M14: =IF(G14>=3,J14*(0.03+(G14-3)*0.01),0) -> 0 | N14: 0 | O14: 0 | P14: 0 | Q14: 0 | R14: 0 | S14: 0 | T14: 0 | U14: 0 | V14: =SUM(J14:U14)-P14 -> 200 | W14: =VLOOKUP(B14,#REF!,35,0) -> #REF! | X14: =VLOOKUP(B14,#REF!,37,0) -> #REF! | Y14: =VLOOKUP(B14,#REF!,38,0) -> #REF! | Z14: =VLOOKUP(B14,#REF!,72,0) -> #REF! | AA14: =VLOOKUP(B14,#REF!,71,0) -> #REF! | AB14: =VLOOKUP(B14,#REF!,36,0) -> #REF! | AK14: =V14/#REF!*(W14+Z14/8*2+AA14/8*1.5+AB14*3)+J14/#REF!*(X14+Y14)+AC14+P14+AE14+AG14+AH14+AI14+AJ14 -> #REF! | AL14: =AM14*$AN$3 -> 480.585 | AM14: 4577 | AN14: =VLOOKUP(B14,#REF!,75,0) -> #REF! | AP14: =ROUND(AK14-AL14-AN14+AO14,-1) -> #REF!
B15: NS03 | C15: Nguyễn T. Hồng Anh | D15: Nhân viên hành chính/ HCNS NM | E15: 40045 | F15: 2 | G15: =DATEDIF(E15,$J$3,"y") -> 9 | H15: =DATEDIF(E15,$J$3,"ym") -> 0 | I15: =DATEDIF(E15,$J$3,"md") -> 5 | J15: =VLOOKUP(D15,'THANG B.LUONG'!$B$5:$I$513,F15+1,0) -> 0 | K15: 0 | L15: 0 | M15: =IF(G15>=3,J15*(0.03+(G15-3)*0.01),0) -> 0 | N15: 0 | O15: 0 | P15: 0 | Q15: 0 | R15: 0 | S15: 0 | T15: 0 | U15: 0 | V15: =SUM(J15:U15)-P15 -> 0 | W15: =VLOOKUP(B15,#REF!,35,0) -> #REF! | X15: =VLOOKUP(B15,#REF!,37,0) -> #REF! | Y15: =VLOOKUP(B15,#REF!,38,0) -> #REF! | Z15: =VLOOKUP(B15,#REF!,72,0) -> #REF! | AA15: =VLOOKUP(B15,#REF!,71,0) -> #REF! | AB15: =VLOOKUP(B15,#REF!,36,0) -> #REF! | AK15: =V15/#REF!*(W15+Z15/8*2+AA15/8*1.5+AB15*3)+J15/#REF!*(X15+Y15)+AC15+P15+AE15+AG15+AH15+AI15+AJ15 -> #REF! | AL15: =AM15*$AN$3 -> 504 | AM15: 4800 | AN15: =VLOOKUP(B15,#REF!,75,0) -> #REF! | AP15: =ROUND(AK15-AL15-AN15+AO15,-1) -> #REF!
B16: NS07 | C16: Đỗ Ngọc Thiên Thanh | D16: Nhân viên hành chính/ HCNS NM | E16: 42842 | F16: 2 | G16: =DATEDIF(E16,$J$3,"y") -> 1 | H16: =DATEDIF(E16,$J$3,"ym") -> 4 | I16: =DATEDIF(E16,$J$3,"md") -> 8 | J16: =VLOOKUP(D16,'THANG B.LUONG'!$B$5:$I$513,F16+1,0) -> 0 | K16: 0 | L16: 0 | M16: =IF(G16>=3,J16*(0.03+(G16-3)*0.01),0) -> 0 | N16: 0 | O16: 0 | P16: 0 | Q16: 0 | R16: 0 | S16: 0 | T16: 0 | U16: 0 | V16: =SUM(J16:U16)-P16 -> 0 | W16: =VLOOKUP(B16,#REF!,35,0) -> #REF! | X16: =VLOOKUP(B16,#REF!,37,0) -> #REF! | Y16: =VLOOKUP(B16,#REF!,38,0) -> #REF! | Z16: =VLOOKUP(B16,#REF!,72,0) -> #REF! | AA16: =VLOOKUP(B16,#REF!,71,0) -> #REF! | AB16: =VLOOKUP(B16,#REF!,36,0) -> #REF! | AK16: =V16/#REF!*(W16+Z16/8*2+AA16/8*1.5+AB16*3)+J16/#REF!*(X16+Y16)+AC16+P16+AE16+AG16+AH16+AI16+AJ16 -> #REF! | AL16: =AM16*$AN$3 -> 504 | AM16: 4800 | AN16: =VLOOKUP(B16,#REF!,75,0) -> #REF! | AP16: =ROUND(AK16-AL16-AN16+AO16,-1) -> #REF!
B17: NS04 | C17: Nguyễn Chu Thy | D17: Chuyên viên IT | E17: 43101 | F17: 3 | G17: =DATEDIF(E17,$J$3,"y") -> 0 | H17: =DATEDIF(E17,$J$3,"ym") -> 7 | I17: =DATEDIF(E17,$J$3,"md") -> 24 | J17: =VLOOKUP(D17,'THANG B.LUONG'!$B$5:$I$513,F17+1,0) -> 15890 | K17: 0 | L17: 1000 | M17: =IF(G17>=3,J17*(0.03+(G17-3)*0.01),0) -> 0 | N17: 0 | O17: 200 | P17: 200 | Q17: 0 | R17: 0 | S17: 0 | T17: 0 | U17: 0 | V17: =SUM(J17:U17)-P17 -> 17090 | W17: =VLOOKUP(B17,#REF!,35,0) -> #REF! | X17: =VLOOKUP(B17,#REF!,37,0) -> #REF! | Y17: =VLOOKUP(B17,#REF!,38,0) -> #REF! | Z17: =VLOOKUP(B17,#REF!,72,0) -> #REF! | AA17: =VLOOKUP(B17,#REF!,71,0) -> #REF! | AB17: =VLOOKUP(B17,#REF!,36,0) -> #REF! | AK17: =V17/#REF!*(W17+Z17/8*2+AA17/8*1.5+AB17*3)+J17/#REF!*(X17+Y17)+AC17+P17+AE17+AG17+AH17+AI17+AJ17 -> #REF! | AL17: =AM17*$AN$3 -> 0 | AM17: 0 | AN17: =VLOOKUP(B17,#REF!,75,0) -> #REF! | AP17: =ROUND(AK17-AL17-AN17+AO17,-1) -> #REF!
B18: NS08 | C18: Trần Minh Xuân | D18: Chuyên viên IT | E18: 43137 | F18: 6 | G18: =DATEDIF(E18,$J$3,"y") -> 0 | H18: =DATEDIF(E18,$J$3,"ym") -> 6 | I18: =DATEDIF(E18,$J$3,"md") -> 19 | J18: =VLOOKUP(D18,'THANG B.LUONG'!$B$5:$I$513,F18+1,0) -> 22330 | K18: 0 | L18: 1000 | M18: =IF(G18>=3,J18*(0.03+(G18-3)*0.01),0) -> 0 | N18: 0 | O18: 200 | P18: 200 | Q18: 0 | R18: 0 | S18: 0 | T18: 0 | U18: 6200 | V18: =SUM(J18:U18)-P18 -> 29730 | W18: =VLOOKUP(B18,#REF!,35,0) -> #REF! | X18: =VLOOKUP(B18,#REF!,37,0) -> #REF! | Y18: =VLOOKUP(B18,#REF!,38,0) -> #REF! | Z18: =VLOOKUP(B18,#REF!,72,0) -> #REF! | AA18: =VLOOKUP(B18,#REF!,71,0) -> #REF! | AB18: =VLOOKUP(B18,#REF!,36,0) -> #REF! | AK18: =V18/#REF!*(W18+Z18/8*2+AA18/8*1.5+AB18*3)+J18/#REF!*(X18+Y18)+AC18+P18+AE18+AG18+AH18+AI18+AJ18 -> #REF! | AL18: =AM18*$AN$3 -> 0 | AM18: 0 | AN18: =VLOOKUP(B18,#REF!,75,0) -> #REF! | AP18: =ROUND(AK18-AL18-AN18+AO18,-1) -> #REF!
B19: NS06 | C19: Nguyễn Đức Cường | D19: ='THANG B.LUONG'!$B$49 -> Tài xế | E19: 43040 | F19: 5 | G19: =DATEDIF(E19,$J$3,"y") -> 0 | H19: =DATEDIF(E19,$J$3,"ym") -> 9 | I19: =DATEDIF(E19,$J$3,"md") -> 24 | J19: =VLOOKUP(D19,'THANG B.LUONG'!$B$5:$I$513,F19+1,0) -> 0 | K19: 0 | L19: 0 | M19: =IF(G19>=3,J19*(0.03+(G19-3)*0.01),0) -> 0 | N19: 0 | O19: 0 | P19: 0 | Q19: 0 | R19: 0 | S19: 0 | T19: 0 | U19: 2660 | V19: =SUM(J19:U19)-P19 -> 2660 | W19: =VLOOKUP(B19,#REF!,35,0) -> #REF! | X19: =VLOOKUP(B19,#REF!,37,0) -> #REF! | Y19: =VLOOKUP(B19,#REF!,38,0) -> #REF! | Z19: =VLOOKUP(B19,#REF!,72,0) -> #REF! | AA19: =VLOOKUP(B19,#REF!,71,0) -> #REF! | AB19: =VLOOKUP(B19,#REF!,36,0) -> #REF! | AK19: =V19/#REF!*(W19+Z19/8*2+AA19/8*1.5+AB19*3)+J19/#REF!*(X19+Y19)+AC19+P19+AE19+AG19+AH19+AI19+AJ19 -> #REF! | AL19: =AM19*$AN$3 -> 0 | AM19: 0 | AN19: =VLOOKUP(B19,#REF!,75,0) -> #REF! | AP19: =ROUND(AK19-AL19-AN19+AO19,-1) -> #REF!
B20: NS10 | C20: Lê Hà | D20: ='THANG B.LUONG'!$B$49 -> Tài xế | E20: 43228 | F20: 5 | G20: =DATEDIF(E20,$J$3,"y") -> 0 | H20: =DATEDIF(E20,$J$3,"ym") -> 3 | I20: =DATEDIF(E20,$J$3,"md") -> 17 | J20: =VLOOKUP(D20,'THANG B.LUONG'!$B$5:$I$513,F20+1,0) -> 0 | K20: 0 | L20: 0 | M20: =IF(G20>=3,J20*(0.03+(G20-3)*0.01),0) -> 0 | N20: 0 | O20: 0 | P20: 0 | Q20: 0 | R20: 0 | S20: 0 | T20: 0 | U20: 2660 | V20: =SUM(J20:U20)-P20 -> 2660 | W20: =VLOOKUP(B20,#REF!,35,0) -> #REF! | X20: =VLOOKUP(B20,#REF!,37,0) -> #REF! | Y20: =VLOOKUP(B20,#REF!,38,0) -> #REF! | Z20: =VLOOKUP(B20,#REF!,72,0) -> #REF! | AA20: =VLOOKUP(B20,#REF!,71,0) -> #REF! | AB20: =VLOOKUP(B20,#REF!,36,0) -> #REF! | AK20: =V20/#REF!*(W20+Z20/8*2+AA20/8*1.5+AB20*3)+J20/#REF!*(X20+Y20)+AC20+P20+AE20+AG20+AH20+AI20+AJ20 -> #REF! | AL20: =AM20*$AN$3 -> 0 | AM20: 0 | AN20: 0 | AP20: =ROUND(AK20-AL20-AN20+AO20,-1) -> #REF!
B21: NS11 | C21: Lê Viết Thuật | D21: ='THANG B.LUONG'!$B$49 -> Tài xế | E21: 43253 | F21: 5 | G21: =DATEDIF(E21,$J$3,"y") -> 0 | H21: =DATEDIF(E21,$J$3,"ym") -> 2 | I21: =DATEDIF(E21,$J$3,"md") -> 23 | J21: =VLOOKUP(D21,'THANG B.LUONG'!$B$5:$I$513,F21+1,0) -> 0 | K21: 0 | L21: 0 | M21: =IF(G21>=3,J21*(0.03+(G21-3)*0.01),0) -> 0 | N21: 0 | O21: 0 | P21: 0 | Q21: 0 | R21: 0 | S21: 0 | T21: 0 | U21: 2660 | V21: =(SUM(J21:U21)-P21)*0.85 -> 2261 | W21: 2 | X21: =VLOOKUP(B21,#REF!,37,0) -> #REF! | Y21: =VLOOKUP(B21,#REF!,38,0) -> #REF! | Z21: =VLOOKUP(B21,#REF!,72,0) -> #REF! | AA21: =VLOOKUP(B21,#REF!,71,0) -> #REF! | AB21: =VLOOKUP(B21,#REF!,36,0) -> #REF! | AK21: =V21/#REF!*(W21+Z21/8*2+AA21/8*1.5+AB21*3)+J21/#REF!*(X21+Y21)+AC21+P21+AE21+AG21+AH21+AI21+AJ21 -> #REF! | AL21: =AM21*$AN$3 -> 0 | AM21: 0 | AN21: 0 | AP21: =ROUND(AK21-AL21-AN21+AO21,-1) -> #REF!
B22: NS11 | C22: Lê Viết Thuật | D22: ='THANG B.LUONG'!$B$49 -> Tài xế | E22: 43253 | F22: 5 | G22: =DATEDIF(E22,$J$3,"y") -> 0 | H22: =DATEDIF(E22,$J$3,"ym") -> 2 | I22: =DATEDIF(E22,$J$3,"md") -> 23 | J22: =VLOOKUP(D22,'THANG B.LUONG'!$B$5:$I$513,F22+1,0) -> 0 | K22: 0 | L22: 0 | M22: =IF(G22>=3,J22*(0.03+(G22-3)*0.01),0) -> 0 | N22: 0 | O22: 0 | P22: 0 | Q22: 0 | R22: 0 | S22: 0 | T22: 0 | U22: 2660 | V22: =SUM(J22:U22)-P22 -> 2660 | W22: 25 | X22: =VLOOKUP(B22,#REF!,37,0) -> #REF! | Y22: =VLOOKUP(B22,#REF!,38,0) -> #REF! | Z22: =VLOOKUP(B22,#REF!,72,0) -> #REF! | AA22: =VLOOKUP(B22,#REF!,71,0) -> #REF! | AB22: =VLOOKUP(B22,#REF!,36,0) -> #REF! | AK22: =V22/#REF!*(W22+Z22/8*2+AA22/8*1.5+AB22*3)+J22/#REF!*(X22+Y22)+AC22+P22+AE22+AG22+AH22+AI22+AJ22 -> #REF! | AL22: =AM22*$AN$3 -> 0 | AM22: 0 | AN22: 0 | AP22: =ROUND(AK22-AL22-AN22+AO22,-1) -> #REF!
B23: NS09 | C23: Cao Thị Minh Thoa | D23: Nhân viên hành chính/ HCNS NM | E23: 42983 | F23: 2 | G23: =DATEDIF(E23,$J$3,"y") -> 0 | H23: =DATEDIF(E23,$J$3,"ym") -> 11 | I23: =DATEDIF(E23,$J$3,"md") -> 20 | J23: =VLOOKUP(D23,'THANG B.LUONG'!$B$5:$I$513,F23+1,0) -> 0 | K23: 0 | L23: 0 | M23: =IF(G23>=3,J23*(0.03+(G23-3)*0.01),0) -> 0 | N23: 0 | O23: 0 | P23: 0 | Q23: 0 | R23: 0 | S23: 0 | T23: 0 | U23: 0 | V23: =SUM(J23:U23)-P23 -> 0 | W23: =VLOOKUP(B23,#REF!,35,0) -> #REF! | X23: =VLOOKUP(B23,#REF!,37,0) -> #REF! | Y23: =VLOOKUP(B23,#REF!,38,0) -> #REF! | Z23: =VLOOKUP(B23,#REF!,72,0) -> #REF! | AA23: =VLOOKUP(B23,#REF!,71,0) -> #REF! | AB23: =VLOOKUP(B23,#REF!,36,0) -> #REF! | AK23: =V23/#REF!*(W23+Z23/8*2+AA23/8*1.5+AB23*3)+J23/#REF!*(X23+Y23)+AC23+P23+AE23+AG23+AH23+AI23+AJ23 -> #REF! | AL23: =AM23*$AN$3 -> 504 | AM23: 4800 | AN23: =VLOOKUP(B23,#REF!,75,0) -> #REF! | AP23: =ROUND(AK23-AL23-AN23+AO23,-1) -> #REF!
C24: Ban KSNB - NB | AK24: =SUM(AK25:AK25) -> #REF! | AL24: =SUM(AL25:AL25) -> 525 | AM24: =SUM(AM25:AM25) -> 5000 | AN24: =SUM(AN25:AN25) -> #REF! | AO24: =SUM(AO25:AO25) -> 0 | AP24: =SUM(AP25:AP25) -> #REF!
B25: NB02 | C25: Nguyễn Trinh Nguyên | D25: Chuyên viên pháp chế | E25: 42555 | F25: 1 | G25: =DATEDIF(E25,$J$3,"y") -> 2 | H25: =DATEDIF(E25,$J$3,"ym") -> 1 | I25: =DATEDIF(E25,$J$3,"md") -> 21 | J25: =VLOOKUP(D25,'THANG B.LUONG'!$B$5:$I$513,F25+1,0) -> 0 | K25: 0 | L25: 0 | M25: =IF(G25>=3,J25*(0.03+(G25-3)*0.01),0) -> 0 | N25: 0 | O25: 0 | P25: 100 | Q25: 0 | R25: 0 | S25: 0 | T25: 0 | U25: 0 | V25: =SUM(J25:U25)-P25 -> 0 | W25: =VLOOKUP(B25,#REF!,35,0) -> #REF! | X25: =VLOOKUP(B25,#REF!,37,0) -> #REF! | Y25: =VLOOKUP(B25,#REF!,38,0) -> #REF! | Z25: =VLOOKUP(B25,#REF!,72,0) -> #REF! | AA25: =VLOOKUP(B25,#REF!,71,0) -> #REF! | AB25: =VLOOKUP(B25,#REF!,36,0) -> #REF! | AK25: =V25/#REF!*(W25+Z25/8*2+AA25/8*1.5+AB25*3)+J25/#REF!*(X25+Y25)+AC25+P25+AE25+AG25+AH25+AI25+AJ25 -> #REF! | AL25: =AM25*$AN$3 -> 525 | AM25: 5000 | AN25: =VLOOKUP(B25,#REF!,75,0) -> #REF! | AP25: =ROUND(AK25-AL25-AN25+AO25,-1) -> #REF!
C26: Phòng TCKT - KT | AK26: =SUM(AK27:AK33) -> #REF! | AL26: =SUM(AL27:AL33) -> 2614.5 | AM26: =SUM(AM27:AM33) -> 33200 | AN26: =SUM(AN27:AN33) -> #REF! | AO26: =SUM(AO27:AO33) -> 0 | AP26: =SUM(AP27:AP33) -> #REF!
B27: KT07 | C27: Nguyễn Văn Bảy | D27: GIÁM ĐỐC TCKT | E27: 41852 | F27: 3 | G27: =DATEDIF(E27,$J$3,"y") -> 4 | H27: =DATEDIF(E27,$J$3,"ym") -> 0 | I27: =DATEDIF(E27,$J$3,"md") -> 24 | J27: =VLOOKUP(D27,'THANG B.LUONG'!$B$5:$I$513,F27+1,0) -> 0 | K27: 0 | L27: 3000 | M27: =IF(G27>=3,J27*(0.03+(G27-3)*0.01),0) -> 0 | N27: 0 | O27: 1000 | P27: 1000 | Q27: 0 | R27: 0 | S27: 0 | T27: 0 | U27: 0 | V27: =SUM(J27:U27)-P27 -> 4000 | W27: =VLOOKUP(B27,#REF!,35,0) -> #REF! | X27: =VLOOKUP(B27,#REF!,37,0) -> #REF! | Y27: =VLOOKUP(B27,#REF!,38,0) -> #REF! | Z27: =VLOOKUP(B27,#REF!,72,0) -> #REF! | AA27: =VLOOKUP(B27,#REF!,71,0) -> #REF! | AB27: =VLOOKUP(B27,#REF!,36,0) -> #REF! | AK27: =V27/#REF!*(W27+Z27/8*2+AA27/8*1.5+AB27*3)+J27/#REF!*(X27+Y27)+AC27+P27+AE27+AG27+AH27+AI27+AJ27 -> #REF! | AL27: 0 | AM27: 8300 | AN27: =VLOOKUP(B27,#REF!,75,0) -> #REF! | AP27: =ROUND(AK27-AL27-AN27+AO27,-1) -> #REF!
B28: KT02 | C28: Ninh Phương Hạnh | D28: Thủ quỹ | E28: 40239 | F28: 3 | G28: =DATEDIF(E28,$J$3,"y") -> 8 | H28: =DATEDIF(E28,$J$3,"ym") -> 5 | I28: =DATEDIF(E28,$J$3,"md") -> 23 | J28: =VLOOKUP(D28,'THANG B.LUONG'!$B$5:$I$513,F28+1,0) -> 0 | K28: 0 | L28: 2000 | M28: =IF(G28>=3,J28*(0.03+(G28-3)*0.01),0) -> 0 | N28: 0 | O28: 0 | P28: 0 | Q28: 0 | R28: 0 | S28: 0 | T28: 0 | U28: 0 | V28: =SUM(J28:U28)-P28 -> 2000 | W28: =VLOOKUP(B28,#REF!,35,0) -> #REF! | X28: =VLOOKUP(B28,#REF!,37,0) -> #REF! | Y28: =VLOOKUP(B28,#REF!,38,0) -> #REF! | Z28: =VLOOKUP(B28,#REF!,72,0) -> #REF! | AA28: =VLOOKUP(B28,#REF!,71,0) -> #REF! | AB28: =VLOOKUP(B28,#REF!,36,0) -> #REF! | AK28: =V28/#REF!*(W28+Z28/8*2+AA28/8*1.5+AB28*3)+J28/#REF!*(X28+Y28)+AC28+P28+AE28+AG28+AH28+AI28+AJ28 -> #REF! | AL28: =AM28*$AN$3 -> 504 | AM28: 4800 | AN28: =VLOOKUP(B28,#REF!,75,0) -> #REF! | AP28: =ROUND(AK28-AL28-AN28+AO28,-1) -> #REF!
B29: KT03 | C29: Nguyễn Thái Ngân | D29: Kế toán nội bộ | E29: 42187 | F29: 2 | G29: =DATEDIF(E29,$J$3,"y") -> 3 | H29: =DATEDIF(E29,$J$3,"ym") -> 1 | I29: =DATEDIF(E29,$J$3,"md") -> 23 | J29: =VLOOKUP(D29,'THANG B.LUONG'!$B$5:$I$513,F29+1,0) -> 0 | K29: 0 | L29: 0 | M29: =IF(G29>=3,J29*(0.03+(G29-3)*0.01),0) -> 0 | N29: 0 | O29: 0 | P29: 200 | Q29: 0 | R29: =30%*'THANG B.LUONG'!C25 -> 0 | S29: 0 | T29: 0 | U29: 0 | V29: =SUM(J29:U29)-P29 -> 0 | W29: =VLOOKUP(B29,#REF!,35,0) -> #REF! | X29: =VLOOKUP(B29,#REF!,37,0) -> #REF! | Y29: =VLOOKUP(B29,#REF!,38,0) -> #REF! | Z29: =VLOOKUP(B29,#REF!,72,0) -> #REF! | AA29: =VLOOKUP(B29,#REF!,71,0) -> #REF! | AB29: =VLOOKUP(B29,#REF!,36,0) -> #REF! | AK29: =V29/#REF!*(W29+Z29/8*2+AA29/8*1.5+AB29*3)+J29/#REF!*(X29+Y29)+AC29+P29+AE29+AG29+AH29+AI29+AJ29 -> #REF! | AL29: =AM29*$AN$3 -> 504 | AM29: 4800 | AN29: =VLOOKUP(B29,#REF!,75,0) -> #REF! | AP29: =ROUND(AK29-AL29-AN29+AO29,-1) -> #REF!
B30: KT05 | C30: Từ Thị Hoàng Oanh | D30: Kế toán nội bộ | E30: 42537 | F30: 2 | G30: =DATEDIF(E30,$J$3,"y") -> 2 | H30: =DATEDIF(E30,$J$3,"ym") -> 2 | I30: =DATEDIF(E30,$J$3,"md") -> 9 | J30: =VLOOKUP(D30,'THANG B.LUONG'!$B$5:$I$513,F30+1,0) -> 0 | K30: 0 | L30: 0 | M30: =IF(G30>=3,J30*(0.03+(G30-3)*0.01),0) -> 0 | N30: 0 | O30: 0 | P30: 0 | Q30: 0 | R30: 0 | S30: 0 | T30: 0 | U30: 0 | V30: =SUM(J30:U30)-P30 -> 0 | W30: =VLOOKUP(B30,#REF!,35,0) -> #REF! | X30: =VLOOKUP(B30,#REF!,37,0) -> #REF! | Y30: =VLOOKUP(B30,#REF!,38,0) -> #REF! | Z30: =VLOOKUP(B30,#REF!,72,0) -> #REF! | AA30: =VLOOKUP(B30,#REF!,71,0) -> #REF! | AB30: =VLOOKUP(B30,#REF!,36,0) -> #REF! | AK30: =V30/#REF!*(W30+Z30/8*2+AA30/8*1.5+AB30*3)+J30/#REF!*(X30+Y30)+AC30+P30+AE30+AG30+AH30+AI30+AJ30 -> #REF! | AL30: =AM30*$AN$3 -> 504 | AM30: 4800 | AN30: =VLOOKUP(B30,#REF!,75,0) -> #REF! | AP30: =ROUND(AK30-AL30-AN30+AO30,-1) -> #REF!
B31: KT08 | C31: Kiều Thị Thủy Tiên | D31: Kế toán quản lý thuế | E31: 42795 | F31: 2 | G31: =DATEDIF(E31,$J$3,"y") -> 1 | H31: =DATEDIF(E31,$J$3,"ym") -> 5 | I31: =DATEDIF(E31,$J$3,"md") -> 24 | J31: =VLOOKUP(D31,'THANG B.LUONG'!$B$5:$I$513,F31+1,0) -> 0 | K31: 0 | L31: 0 | M31: =IF(G31>=3,J31*(0.03+(G31-3)*0.01),0) -> 0 | N31: 0 | O31: 0 | P31: 0 | Q31: 0 | R31: 0 | S31: 0 | T31: 0 | U31: 0 | V31: =SUM(J31:U31)-P31 -> 0 | W31: =VLOOKUP(B31,#REF!,35,0) -> #REF! | X31: =VLOOKUP(B31,#REF!,37,0) -> #REF! | Y31: =VLOOKUP(B31,#REF!,38,0) -> #REF! | Z31: =VLOOKUP(B31,#REF!,72,0) -> #REF! | AA31: =VLOOKUP(B31,#REF!,71,0) -> #REF! | AB31: =VLOOKUP(B31,#REF!,36,0) -> #REF! | AK31: =V31/#REF!*(W31+Z31/8*2+AA31/8*1.5+AB31*3)+J31/#REF!*(X31+Y31)+AC31+P31+AE31+AG31+AH31+AI31+AJ31 -> #REF! | AL31: =AM31*$AN$3 -> 577.5 | AM31: 5500 | AN31: =VLOOKUP(B31,#REF!,75,0) -> #REF! | AP31: =ROUND(AK31-AL31-AN31+AO31,-1) -> #REF!
B32: KT09 | C32: Huỳnh Ngọc Giang | D32: Kế toán quản trị | E32: 42809 | F32: 3 | G32: =DATEDIF(E32,$J$3,"y") -> 1 | H32: =DATEDIF(E32,$J$3,"ym") -> 5 | I32: =DATEDIF(E32,$J$3,"md") -> 10 | J32: =VLOOKUP(D32,'THANG B.LUONG'!$B$5:$I$513,F32+1,0) -> 0 | K32: 0 | L32: 0 | M32: =IF(G32>=3,J32*(0.03+(G32-3)*0.01),0) -> 0 | N32: 0 | O32: 200 | P32: 0 | Q32: 0 | R32: 0 | S32: 0 | T32: 0 | U32: 0 | V32: =SUM(J32:U32)-P32 -> 200 | W32: =VLOOKUP(B32,#REF!,35,0) -> #REF! | X32: =VLOOKUP(B32,#REF!,37,0) -> #REF! | Y32: =VLOOKUP(B32,#REF!,38,0) -> #REF! | Z32: =VLOOKUP(B32,#REF!,72,0) -> #REF! | AA32: =VLOOKUP(B32,#REF!,71,0) -> #REF! | AB32: =VLOOKUP(B32,#REF!,36,0) -> #REF! | AK32: =V32/#REF!*(W32+Z32/8*2+AA32/8*1.5+AB32*3)+J32/#REF!*(X32+Y32)+AC32+P32+AE32+AG32+AH32+AI32+AJ32 -> #REF! | AL32: =AM32*$AN$3 -> 525 | AM32: 5000 | AN32: =VLOOKUP(B32,#REF!,75,0) -> #REF! | AP32: =ROUND(AK32-AL32-AN32+AO32,-1) -> #REF!
B33: KT11 | C33: Nguyễn Thị Phượng Nhi | D33: ='THANG B.LUONG'!B28 -> Kế toán nội bộ | E33: 43070 | F33: 1 | G33: =DATEDIF(E33,$J$3,"y") -> 0 | H33: =DATEDIF(E33,$J$3,"ym") -> 8 | I33: =DATEDIF(E33,$J$3,"md") -> 24 | J33: =VLOOKUP(D33,'THANG B.LUONG'!$B$5:$I$513,F33+1,0) -> 0 | K33: 0 | L33: 0 | M33: =IF(G33>=3,J33*(0.03+(G33-3)*0.01),0) -> 0 | N33: 0 | O33: 0 | P33: 0 | Q33: 0 | R33: 0 | S33: 0 | T33: 0 | U33: 0 | V33: =SUM(J33:U33)-P33 -> 0 | W33: =VLOOKUP(B33,#REF!,35,0) -> #REF! | X33: =VLOOKUP(B33,#REF!,37,0) -> #REF! | Y33: =VLOOKUP(B33,#REF!,38,0) -> #REF! | Z33: =VLOOKUP(B33,#REF!,72,0) -> #REF! | AA33: =VLOOKUP(B33,#REF!,71,0) -> #REF! | AB33: =VLOOKUP(B33,#REF!,36,0) -> #REF! | AK33: =V33/#REF!*(W33+Z33/8*2+AA33/8*1.5+AB33*3)+J33/#REF!*(X33+Y33)+AC33+P33+AE33+AG33+AH33+AI33+AJ33 -> #REF! | AL33: =AM33*$AN$3 -> 0 | AM33: 0 | AN33: =VLOOKUP(B33,#REF!,75,0) -> #REF! | AP33: =ROUND(AK33-AL33-AN33+AO33,-1) -> #REF!
C34: Ban XDCB - XD | AK34: =SUM(AK35:AK43) -> #REF! | AL34: =SUM(AL35:AL43) -> 1680 | AM34: =SUM(AM35:AM43) -> 16000 | AN34: =SUM(AN35:AN43) -> #REF! | AO34: =SUM(AO35:AO43) -> 0 | AP34: =SUM(AP35:AP43) -> #REF!
B35: XD02 | C35: Châu Phước Thuần | D35: ='THANG B.LUONG'!B69 -> CV giám sát thi công | E35: 42338 | F35: 4 | G35: =DATEDIF(E35,$J$3,"y") -> 2 | H35: =DATEDIF(E35,$J$3,"ym") -> 8 | I35: =DATEDIF(E35,$J$3,"md") -> 26 | J35: =VLOOKUP(D35,'THANG B.LUONG'!$B$5:$I$513,F35+1,0) -> 0 | K35: 0 | L35: 500 | M35: =IF(G35>=3,J35*(0.03+(G35-3)*0.01),0) -> 0 | N35: 0 | O35: 200 | P35: 300 | Q35: 0 | R35: 0 | S35: 0 | T35: 0 | U35: 0 | V35: =SUM(J35:U35)-P35 -> 700 | W35: =VLOOKUP(B35,#REF!,35,0) -> #REF! | X35: =VLOOKUP(B35,#REF!,37,0) -> #REF! | Y35: =VLOOKUP(B35,#REF!,38,0) -> #REF! | Z35: =VLOOKUP(B35,#REF!,72,0) -> #REF! | AA35: =VLOOKUP(B35,#REF!,71,0) -> #REF! | AB35: =VLOOKUP(B35,#REF!,36,0) -> #REF! | AJ35: 300 | AK35: =V35/#REF!*(W35+Z35/8*2+AA35/8*1.5+AB35*3)+J35/#REF!*(X35+Y35)+AC35+P35+AE35+AG35+AH35+AI35+AJ35 -> #REF! | AL35: =AM35*$AN$3 -> 525 | AM35: 5000 | AN35: =VLOOKUP(B35,#REF!,75,0) -> #REF! | AP35: =ROUND(AK35-AL35-AN35+AO35,-1) -> #REF!
B36: XD03 | C36: Nguyễn Duy Long | D36: ='THANG B.LUONG'!B67 -> Trưởng BP GS kỹ thuật | E36: 42475 | F36: 2 | G36: =DATEDIF(E36,$J$3,"y") -> 2 | H36: =DATEDIF(E36,$J$3,"ym") -> 4 | I36: =DATEDIF(E36,$J$3,"md") -> 10 | J36: =VLOOKUP(D36,'THANG B.LUONG'!$B$5:$I$513,F36+1,0) -> 0 | K36: 0 | L36: 1000 | M36: =IF(G36>=3,J36*(0.03+(G36-3)*0.01),0) -> 0 | N36: 0 | O36: 500 | P36: 500 | Q36: 0 | R36: 0 | S36: 0 | T36: 0 | U36: 0 | V36: =SUM(J36:U36)-P36 -> 1500 | W36: =VLOOKUP(B36,#REF!,35,0) -> #REF! | X36: =VLOOKUP(B36,#REF!,37,0) -> #REF! | Y36: =VLOOKUP(B36,#REF!,38,0) -> #REF! | Z36: =VLOOKUP(B36,#REF!,72,0) -> #REF! | AA36: =VLOOKUP(B36,#REF!,71,0) -> #REF! | AB36: =VLOOKUP(B36,#REF!,36,0) -> #REF! | AK36: =V36/#REF!*(W36+Z36/8*2+AA36/8*1.5+AB36*3)+J36/#REF!*(X36+Y36)+AC36+P36+AE36+AG36+AH36+AI36+AJ36 -> #REF! | AL36: =AM36*$AN$3 -> 577.5 | AM36: 5500 | AN36: =VLOOKUP(B36,#REF!,75,0) -> #REF! | AP36: =ROUND(AK36-AL36-AN36+AO36,-1) -> #REF!
B37: XD04 | C37: Nguyễn Trần Duy Anh | D37: ='THANG B.LUONG'!B62 -> Trưởng BP thiết kế kỹ thuật | E37: 42485 | F37: 4 | G37: =DATEDIF(E37,$J$3,"y") -> 2 | H37: =DATEDIF(E37,$J$3,"ym") -> 4 | I37: =DATEDIF(E37,$J$3,"md") -> 0 | J37: =VLOOKUP(D37,'THANG B.LUONG'!$B$5:$I$513,F37+1,0) -> 0 | K37: 0 | L37: 1000 | M37: =IF(G37>=3,J37*(0.03+(G37-3)*0.01),0) -> 0 | N37: 0 | O37: 500 | P37: 500 | Q37: 0 | R37: 0 | S37: 0 | T37: 0 | U37: 0 | V37: =SUM(J37:U37)-P37 -> 1500 | W37: =VLOOKUP(B37,#REF!,35,0) -> #REF! | X37: =VLOOKUP(B37,#REF!,37,0) -> #REF! | Y37: =VLOOKUP(B37,#REF!,38,0) -> #REF! | Z37: =VLOOKUP(B37,#REF!,72,0) -> #REF! | AA37: =VLOOKUP(B37,#REF!,71,0) -> #REF! | AB37: =VLOOKUP(B37,#REF!,36,0) -> #REF! | AK37: =V37/#REF!*(W37+Z37/8*2+AA37/8*1.5+AB37*3)+J37/#REF!*(X37+Y37)+AC37+P37+AE37+AG37+AH37+AI37+AJ37 -> #REF! | AL37: =AM37*$AN$3 -> 577.5 | AM37: 5500 | AN37: =VLOOKUP(B37,#REF!,75,0) -> #REF! | AP37: =ROUND(AK37-AL37-AN37+AO37,-1) -> #REF!
B38: XD05 | C38: Chế Thanh Thân | D38: ='THANG B.LUONG'!B64 -> CV KCS xây dựng | E38: 43222 | F38: 1 | G38: =DATEDIF(E38,$J$3,"y") -> 0 | H38: =DATEDIF(E38,$J$3,"ym") -> 3 | I38: =DATEDIF(E38,$J$3,"md") -> 23 | J38: =VLOOKUP(D38,'THANG B.LUONG'!$B$5:$I$513,F38+1,0) -> 0 | K38: 0 | L38: 0 | M38: =IF(G38>=3,J38*(0.03+(G38-3)*0.01),0) -> 0 | N38: 0 | O38: 0 | P38: 200 | Q38: 0 | R38: 0 | S38: 0 | T38: 0 | U38: 0 | V38: =(SUM(J38:U38)-P38) -> 0 | W38: =VLOOKUP(B38,#REF!,35,0) -> #REF! | X38: =VLOOKUP(B38,#REF!,37,0) -> #REF! | Y38: =VLOOKUP(B38,#REF!,38,0) -> #REF! | Z38: =VLOOKUP(B38,#REF!,72,0) -> #REF! | AA38: =VLOOKUP(B38,#REF!,71,0) -> #REF! | AB38: =VLOOKUP(B38,#REF!,36,0) -> #REF! | AK38: =V38/#REF!*(W38+Z38/8*2+AA38/8*1.5+AB38*3)+J38/#REF!*(X38+Y38)+AC38+P38+AE38+AG38+AH38+AI38+AJ38 -> #REF! | AL38: =AM38*$AN$3 -> 0 | AM38: 0 | AN38: =VLOOKUP(B38,#REF!,75,0) -> #REF! | AP38: =ROUND(AK38-AL38-AN38+AO38,-1) -> #REF!
B39: XD06 | C39: Chau Ri Na | D39: ='THANG B.LUONG'!B66 -> NV thiết kế xây dựng | E39: 43227 | F39: 2 | G39: =DATEDIF(E39,$J$3,"y") -> 0 | H39: =DATEDIF(E39,$J$3,"ym") -> 3 | I39: =DATEDIF(E39,$J$3,"md") -> 18 | J39: =VLOOKUP(D39,'THANG B.LUONG'!$B$5:$I$513,F39+1,0) -> 0 | K39: 0 | L39: 0 | M39: =IF(G39>=3,J39*(0.03+(G39-3)*0.01),0) -> 0 | N39: 0 | O39: 0 | P39: 200 | Q39: 0 | R39: 0 | S39: 0 | T39: 0 | U39: 0 | V39: =(SUM(J39:U39)-P39) -> 0 | W39: =VLOOKUP(B39,#REF!,35,0) -> #REF! | X39: =VLOOKUP(B39,#REF!,37,0) -> #REF! | Y39: =VLOOKUP(B39,#REF!,38,0) -> #REF! | Z39: =VLOOKUP(B39,#REF!,72,0) -> #REF! | AA39: =VLOOKUP(B39,#REF!,71,0) -> #REF! | AB39: =VLOOKUP(B39,#REF!,36,0) -> #REF! | AK39: =V39/#REF!*(W39+Z39/8*2+AA39/8*1.5+AB39*3)+J39/#REF!*(X39+Y39)+AC39+P39+AE39+AG39+AH39+AI39+AJ39 -> #REF! | AL39: =AM39*$AN$3 -> 0 | AM39: 0 | AN39: =VLOOKUP(B39,#REF!,75,0) -> #REF! | AP39: =ROUND(AK39-AL39-AN39+AO39,-1) -> #REF!
B40: XD07 | C40: Nguyễn Văn Bích | D40: ='THANG B.LUONG'!B69 -> CV giám sát thi công | E40: 43250 | F40: 3 | G40: =DATEDIF(E40,$J$3,"y") -> 0 | H40: =DATEDIF(E40,$J$3,"ym") -> 2 | I40: =DATEDIF(E40,$J$3,"md") -> 26 | J40: =VLOOKUP(D40,'THANG B.LUONG'!$B$5:$I$513,F40+1,0) -> 0 | K40: 0 | L40: 0 | M40: =IF(G40>=3,J40*(0.03+(G40-3)*0.01),0) -> 0 | N40: 0 | O40: 0 | P40: 200 | Q40: 0 | R40: 0 | S40: 0 | T40: 0 | U40: 0 | V40: =(SUM(J40:U40)-P40)*0.85 -> 0 | W40: 3 | X40: =VLOOKUP(B40,#REF!,37,0) -> #REF! | Y40: =VLOOKUP(B40,#REF!,38,0) -> #REF! | Z40: =VLOOKUP(B40,#REF!,72,0) -> #REF! | AA40: =VLOOKUP(B40,#REF!,71,0) -> #REF! | AB40: =VLOOKUP(B40,#REF!,36,0) -> #REF! | AK40: =V40/#REF!*(W40+Z40/8*2+AA40/8*1.5+AB40*3)+J40/#REF!*(X40+Y40)+AC40+P40+AE40+AG40+AH40+AI40+AJ40 -> #REF! | AL40: =AM40*$AN$3 -> 0 | AM40: 0 | AN40: 0 | AP40: =ROUND(AK40-AL40-AN40+AO40,-1) -> #REF!
B41: XD07 | C41: Nguyễn Văn Bích | D41: ='THANG B.LUONG'!B69 -> CV giám sát thi công | E41: 43250 | F41: 3 | G41: =DATEDIF(E41,$J$3,"y") -> 0 | H41: =DATEDIF(E41,$J$3,"ym") -> 2 | I41: =DATEDIF(E41,$J$3,"md") -> 26 | J41: =VLOOKUP(D41,'THANG B.LUONG'!$B$5:$I$513,F41+1,0) -> 0 | K41: 0 | L41: 0 | M41: =IF(G41>=3,J41*(0.03+(G41-3)*0.01),0) -> 0 | N41: 0 | O41: 0 | P41: 0 | Q41: 0 | R41: 0 | S41: 0 | T41: 0 | U41: 0 | V41: =SUM(J41:U41)-P41 -> 0 | W41: 24 | X41: =VLOOKUP(B41,#REF!,37,0) -> #REF! | Y41: =VLOOKUP(B41,#REF!,38,0) -> #REF! | Z41: 0 | AA41: =VLOOKUP(B41,#REF!,71,0) -> #REF! | AB41: =VLOOKUP(B41,#REF!,36,0) -> #REF! | AK41: =V41/#REF!*(W41+Z41/8*2+AA41/8*1.5+AB41*3)+J41/#REF!*(X41+Y41)+AC41+P41+AE41+AG41+AH41+AI41+AJ41 -> #REF! | AL41: =AM41*$AN$3 -> 0 | AM41: 0 | AN41: =VLOOKUP(B41,#REF!,75,0) -> #REF! | AP41: =ROUND(AK41-AL41-AN41+AO41,-1) -> #REF!
...

Sheet DT-DS
C2: MÖÙC ÑAÏT
I3: ÑVT: 1.000ñ
A4: Maõ NV | B4: BOÄ PHAÄN TAØI XEÁ | C4: Xe nhoû | D4: Tieàn | E4: xe lôùn | F4: Tieàn | G4: soá chuyeán vöôït | H4: Tieàn | I4: Coäng soá chuyeán | J4: Coäng doanh soá
D5: 80 | F5: 91 | H5: 120
A6: =#REF! -> #REF! | B6: =#REF! -> #REF! | D6: =C6*$D$5 -> 0 | F6: =E6*$F$5 -> 0 | H6: =G6*$H$5 -> 0 | I6: =C6+E6+G6 -> 0 | J6: =H6+F6+D6 -> 0
A7: =#REF! -> #REF! | B7: =#REF! -> #REF! | D7: =C7*$D$5 -> 0 | E7: 59 | F7: =E7*$F$5 -> 5369 | G7: 8 | H7: =G7*$H$5 -> 960 | I7: =C7+E7+G7 -> 67 | J7: =H7+F7+D7 -> 6329
A8: =#REF! -> #REF! | B8: =#REF! -> #REF! | D8: =C8*$D$5 -> 0 | F8: =E8*$F$5 -> 0 | H8: =G8*$H$5 -> 0 | I8: =C8+E8+G8 -> 0 | J8: =H8+F8+D8 -> 0
A9: =#REF! -> #REF! | B9: =#REF! -> #REF! | D9: =C9*$D$5 -> 0 | E9: 50 | F9: =E9*$F$5 -> 4550 | G9: 4 | H9: =G9*$H$5 -> 480 | I9: =C9+E9+G9 -> 54 | J9: =H9+F9+D9 -> 5030
A10: =#REF! -> #REF! | B10: =#REF! -> #REF! | D10: =C10*$D$5 -> 0 | E10: 49 | F10: =E10*$F$5 -> 4459 | G10: 8 | H10: =G10*$H$5 -> 960 | I10: =C10+E10+G10 -> 57 | J10: =H10+F10+D10 -> 5419
A11: =#REF! -> #REF! | B11: =#REF! -> #REF! | D11: =C11*$D$5 -> 0 | E11: 50 | F11: =E11*$F$5 -> 4550 | G11: 8 | H11: =G11*$H$5 -> 960 | I11: =C11+E11+G11 -> 58 | J11: =H11+F11+D11 -> 5510
A12: =#REF! -> #REF! | B12: =#REF! -> #REF! | C12: 4 | D12: =C12*$D$5 -> 320 | E12: 11 | F12: =E12*$F$5 -> 1001 | H12: =G12*$H$5 -> 0 | I12: =C12+E12+G12 -> 15 | J12: =H12+F12+D12 -> 1321
A13: =#REF! -> #REF! | B13: =#REF! -> #REF! | D13: =C13*$D$5 -> 0 | E13: 48 | F13: =E13*$F$5 -> 4368 | G13: 6 | H13: =G13*$H$5 -> 720 | I13: =C13+E13+G13 -> 54 | J13: =H13+F13+D13 -> 5088
A14: =#REF! -> #REF! | B14: =#REF! -> #REF! | D14: =C14*$D$5 -> 0 | E14: 18 | F14: =E14*$F$5 -> 1638 | G14: 1 | H14: =G14*$H$5 -> 120 | I14: =C14+E14+G14 -> 19 | J14: =H14+F14+D14 -> 1758
A15: =#REF! -> #REF! | B15: =#REF! -> #REF! | C15: 48 | D15: =C15*$D$5 -> 3840 | F15: =E15*$F$5 -> 0 | G15: 4 | H15: =G15*$H$5 -> 480 | I15: =C15+E15+G15 -> 52 | J15: =H15+F15+D15 -> 4320
A16: =#REF! -> #REF! | B16: =#REF! -> #REF! | D16: =C16*$D$5 -> 0 | E16: 24 | F16: =E16*$F$5 -> 2184 | H16: =G16*$H$5 -> 0 | I16: =C16+E16+G16 -> 24 | J16: =H16+F16+D16 -> 2184 | O16: khoâng tinh chuyen (löông thaùng) | Q16: 33 chuyeán T9
A17: =A66 -> #REF! | B17: =B66 -> #REF! | D17: =C17*$D$5 -> 0 | E17: 54 | F17: =E17*$F$5 -> 4914 | G17: 5 | H17: =G17*$H$5 -> 600 | I17: =C17+E17+G17 -> 59 | J17: =H17+F17+D17 -> 5514
A19: Maõ NV | B19: BOÄ PHAÄN BAÙN HAØNG | C19: Möùc ñaït TPHCM | D19: Möùc 1: 765tr | E19: Möùc 2: 990tr | F19: Möùc 3: 1,080tr | H19: Ñaït möùc 1 | I19: Ñaït möùc 2 | J19: Ñaït möùc 3 | L19: Coäng
D20: 765000 | E20: 990000 | F20: 1080000 | H20: 2000 | I20: 3000 | J20: 1700
C21: Möùc ñaït TỈNH | D21: Möùc 1: 495tr | E21: Möùc 2: 585tr | F21: Möùc 3: 675tr | H21: Ñaït möùc 1 | I21: Ñaït möùc 2 | J21: Ñaït möùc 3 | L21: Coäng
D22: 495000 | E22: 585000 | F22: 675000 | H22: 2000 | I22: 3000 | J22: 1700
A23: KDS2 | B23: Phan Thanh Tùng | C23: 0 | D23: =IF(C23<$D$20,0,$D$20) -> 0 | E23: =IF(C23<$D$20,0,IF(AND(C23>$D$20,C23<$E$20),C23-$D$20,IF(C23<=$D$20,0,$E$20-$D$20))) -> 0 | F23: =IF(AND(C23<$D$20,C23<$E$20,C23<$F$20),0,IF((C23-D23-E23)>=($F$20-$E$20),$F$20-$E$20,C23-D23-E23)) -> 0 | H23: =IF(D23=$D$20,$H$20,0) -> 0 | I23: =$E23*$I$20/($E$20-$D$20) -> 0 | J23: =$F23*$J$20/($F$20-$E$20) -> 0 | L23: =H23+I23+J23+K23 -> 0
A24: KDS3 | D24: =IF(C24<$D$20,0,$D$20) -> 0 | E24: =IF(C24<$D$20,0,IF(AND(C24>$D$20,C24<$E$20),C24-$D$20,IF(C24<=$D$20,0,$E$20-$D$20))) -> 0 | F24: =IF(AND(C24<$D$20,C24<$E$20,C24<$F$20),0,IF((C24-D24-E24)>=($F$20-$E$20),$F$20-$E$20,C24-D24-E24)) -> 0 | H24: =IF(D24=$D$20,$H$20,0) -> 0 | I24: =$E24*$I$20/($E$20-$D$20) -> 0 | J24: =$F24*$J$20/($F$20-$E$20) -> 0 | L24: =H24+I24+J24+K24 -> 0
A25: KDS5 | D25: =IF(C25<$D$20,0,$D$20) -> 0 | E25: =IF(C25<$D$20,0,IF(AND(C25>$D$20,C25<$E$20),C25-$D$20,IF(C25<=$D$20,0,$E$20-$D$20))) -> 0 | F25: =IF(AND(C25<$D$20,C25<$E$20,C25<$F$20),0,IF((C25-D25-E25)>=($F$20-$E$20),$F$20-$E$20,C25-D25-E25)) -> 0 | H25: =IF(D25=$D$20,$H$20,0) -> 0 | I25: =$E25*$I$20/($E$20-$D$20) -> 0 | J25: =$F25*$J$20/($F$20-$E$20) -> 0 | L25: =H25+I25+J25+K25 -> 0
A26: KDS6 | B26: Lê Nho Khánh | D26: =IF(C26<$D$20,0,$D$20) -> 0 | E26: =IF(C26<$D$20,0,IF(AND(C26>$D$20,C26<$E$20),C26-$D$20,IF(C26<=$D$20,0,$E$20-$D$20))) -> 0 | F26: =IF(AND(C26<$D$20,C26<$E$20,C26<$F$20),0,IF((C26-D26-E26)>=($F$20-$E$20),$F$20-$E$20,C26-D26-E26)) -> 0 | H26: =IF(D26=$D$20,$H$20,0) -> 0 | I26: =$E26*$I$20/($E$20-$D$20) -> 0 | J26: =$F26*$J$20/($F$20-$E$20) -> 0 | L26: =H26+I26+J26+K26 -> 0
A27: KDS8 | B27: Nguyễn Đức Trung | D27: =IF(C27<$D$20,0,$D$20) -> 0 | E27: =IF(C27<$D$20,0,IF(AND(C27>$D$20,C27<$E$20),C27-$D$20,IF(C27<=$D$20,0,$E$20-$D$20))) -> 0 | F27: =IF(AND(C27<$D$20,C27<$E$20,C27<$F$20),0,IF((C27-D27-E27)>=($F$20-$E$20),$F$20-$E$20,C27-D27-E27)) -> 0 | H27: =IF(D27=$D$20,$H$20,0) -> 0 | I27: =$E27*$I$20/($E$20-$D$20) -> 0 | J27: =$F27*$J$20/($F$20-$E$20) -> 0 | L27: =H27+I27+J27+K27 -> 0
A28: KDS9 | B28: Nguyễn Minh Đại | C28: 0 | D28: =IF(C28<$D$20,0,$D$20) -> 0 | E28: =IF(C28<$D$20,0,IF(AND(C28>$D$20,C28<$E$20),C28-$D$20,IF(C28<=$D$20,0,$E$20-$D$20))) -> 0 | F28: =IF(AND(C28<$D$20,C28<$E$20,C28<$F$20),0,IF((C28-D28-E28)>=($F$20-$E$20),$F$20-$E$20,C28-D28-E28)) -> 0 | H28: =IF(D28=$D$20,$H$20,0) -> 0 | I28: =$E28*$I$20/($E$20-$D$20) -> 0 | J28: =$F28*$J$20/($F$20-$E$20) -> 0 | L28: =H28+I28+J28+K28 -> 0
D29: =IF(C29<$D$20,0,$D$20) -> 0 | E29: =IF(AND(C29>$D$20,C29<$E$20),C29-$D$20,IF(C29<=$D$20,0,$E$20-$D$20)) -> 0 | F29: =IF(AND(C29>$E$20,E29<$F$20),C29-$E$20,IF(E29<=$E$20,0,$F$20-$E$20)) -> 0 | L29: =H29+I29+J29+K29 -> 0
A30: Maõ NV | B30: QUAÛN LYÙ ÑIEÀU XE | C30: Möùc ñaït | D30: =IF(C30<$D$20,0,$D$20) -> 765000 | E30: =IF(AND(C30>$D$20,C30<$E$20),C30-$D$20,IF(C30<=$D$20,0,$E$20-$D$20)) -> 225000 | F30: =IF(AND(C30>$E$20,E30<$F$20),C30-$E$20,IF(E30<=$E$20,0,$F$20-$E$20)) -> #VALUE! | G30: tieàn | H30: Coäng | L30: =H30+I30+J30+K30 -> #VALUE!
D31: =IF(C31<$D$20,0,$D$20) -> 0 | E31: =IF(AND(C31>$D$20,C31<$E$20),C31-$D$20,IF(C31<=$D$20,0,$E$20-$D$20)) -> 0 | F31: =IF(AND(C31>$E$20,E31<$F$20),C31-$E$20,IF(E31<=$E$20,0,$F$20-$E$20)) -> 0 | G31: 30 | L31: =H31+I31+J31+K31 -> 0
A32: =#REF! -> #REF! | B32: =#REF! -> #REF! | C32: 459 | D32: =IF(C32<$D$20,0,$D$20) -> 0 | E32: =IF(AND(C32>$D$20,C32<$E$20),C32-$D$20,IF(C32<=$D$20,0,$E$20-$D$20)) -> 0 | F32: =IF(AND(C32>$E$20,E32<$F$20),C32-$E$20,IF(E32<=$E$20,0,$F$20-$E$20)) -> 0 | G32: =F32*G31 -> 0 | H32: =E32+G32 -> 0 | L32: =H32+I32+J32+K32 -> 0
L33: =H33+I33+J33+K33 -> 0
A34: Maõ NV | B34: QUAÛN LYÙ SALE TPHCM | C34: Möùc ñaït | D34: Möùc 1: 2,295t | E34: Möùc 2: 2,970t | H34: Ñaït möùc 1 | I34: Ñaït möùc 2 | L34: Coäng
D35: 2295000 | E35: 2970000 | H35: 2000 | I35: 4000
A36: KDS4 | B36: Trịnh Minh Hảo (Trưởng BP sale) | C36: 0 | D36: =IF(C36<$D$35,0,$D$35) -> 0 | E36: =IF(AND(C36<$D$35,C36<$E$35),0,IF((C36-D36)>$E$35-$D$35,E35-D35,(C36-D36))) -> 0 | H36: =D36*H35/D35 -> 0 | I36: =E36*$I$35/($E$35-$D$35) -> 0 | L36: =H36+I36+J36+K36 -> 0
A38: Maõ NV | B38: QUAÛN LYÙ SALE TÆNH | C38: Möùc ñaït | D38: Möùc 1: 1,350t | E38: Möùc 2: 1,750t | H38: Ñaït möùc 1 | I38: Ñaït möùc 2 | L38: Coäng
D39: 1350000 | E39: 1750000 | H39: 2000 | I39: 4000
A40: KDS1 | B40: Nguyễn Tuấn Anh | C40: 0 | D40: =IF(C40<$D$39,0,$D$39) -> 0 | E40: =IF(AND(C40<$D$39,C40<$E$39),0,IF((C40-D40)>$E$39-$D$39,E39-D39,(C40-D40))) -> 0 | H40: =D40*H39/D39 -> 0 | I40: =E40*I39/(E39-D39) -> 0 | L40: =H40+I40+J40+K40 -> 0
A42: Maõ NV | B42: SALE ADMIN | C42: Möùc ñaït | D42: Möùc 1: 3,645t | E42: Möùc 2: 4,725t | H42: Ñaït möùc 1 | I42: Ñaït möùc 2 | L42: Coäng
D43: 3645000 | E43: 4725000 | H43: 1000 | I43: 3000
A44: KDV2 | B44: Thạch Minh Châu | C44: =C40+C36 -> 0 | D44: =IF(C44<$D$43,0,$D$43) -> 0 | E44: =IF(AND(C44<$D$43,C44<$E$43),0,IF((C44-D44)>($E$43-$D$43),$E$43-$D$43,(C44-D44))) -> 0 | H44: =D44*$H$43/$D$43 -> 0 | I44: =E44*$I$43/($E$43-$D$43) -> 0 | L44: =H44+I44+J44+K44 -> 0
...

Sheet TH ngay phep
B2: BAÛNG TOÅNG HÔÏP NGAØY PHEÙP
D3: Thaùng 1 | E3: Thaùng 2 | F3: Thaùng 3 | G3: Thaùng 4 | H3: Thaùng 5 | I3: Thaùng 6 | J3: Thaùng 7 | K3: Thaùng 8 | L3: Thaùng 9 | M3: Thaùng 10 | N3: Thaùng 11 | O3: Thaùng 12 | P3: Toång hôïp
A4: =#REF! -> #REF! | B4: 1 | C4: Nguyeãn Vaên Thaûo | P4: =SUM(D4:O4) -> 0
A5: =#REF! -> #REF! | B5: 2 | C5: Nguyeãn Ngoïc Höng | P5: =SUM(D5:O5) -> 0
A6: =#REF! -> #REF! | B6: 3 | C6: Ngoâ .T. Phan Hieàn | D6: 1 | E6: 3 | F6: 1 | G6: 1 | I6: 2 | P6: =SUM(D6:O6) -> 8
A7: =#REF! -> #REF! | B7: 4 | C7: Nguyeãn T. Hoàng Aùnh | E7: 1 | F7: 1 | G7: 1 | I7: 2 | P7: =SUM(D7:O7) -> 5
A8: =#REF! -> #REF! | B8: 5 | C8: Ninh Phöông Haïnh | E8: 3 | G8: 1 | H8: 5 | I8: 3 | P8: =SUM(D8:O8) -> 12
A9: =#REF! -> #REF! | B9: 6 | C9: Leâ Hoaøng Tuaán | P9: =SUM(D9:O9) -> 0
A10: =#REF! -> #REF! | B10: 7 | C10: Phaïm Vieät Nam | P10: =SUM(D10:O10) -> 0
A11: =#REF! -> #REF! | B11: 8 | C11: Ñoàng Anh Tuaán | E11: 1 | F11: 1 | P11: =SUM(D11:O11) -> 2
A12: =#REF! -> #REF! | B12: 9 | C12: Nguyeãn Hoàng Nam | D12: 2 | E12: 5 | P12: =SUM(D12:O12) -> 7
B13: 10 | C13: Döông Leâ Hoàng Phieán | E13: 6 | G13: 8 | P13: =SUM(D13:O13) -> 14
B14: 11 | C14: Leâ Coâng Nhaát Trung | E14: 1 | G14: 2 | I14: 1 | P14: =SUM(D14:O14) -> 4
B15: 12 | C15: Leâ Thanh Huy
B16: 13 | C16: Ngoâ Theá Giang
B17: 14 | C17: Traàn Vaên Vò Toaøn | P17: =SUM(D17:O17) -> 0
B18: 15 | C18: Nguyeãn Vaên Baûy
B19: 16 | C19: Phaïm Thanh Tuøng | P19: =SUM(D19:O19) -> 0
B20: 17 | C20: Huyønh Thanh Lieâm | E20: 1 | P20: =SUM(D20:O20) -> 1
B21: 18 | C21: Nguyeãn Ñoã Q. Phöông | D21: 1 | E21: 1 | F21: 1 | G21: 1 | I21: 3 | P21: =SUM(D21:O21) -> 7
B22: 19 | C22: Hoaøng Giaùng Sinh
B23: 20 | C23: Cao Hieäp Thöông | E23: 1
B24: 22 | C24: Ngoâ Maïnh Linh trưởng bộ phận | E24: 1
B25: 23 | C25: Nguyeãn Cöôøng | E25: 2 | I25: 1
B26: 24 | C26: Nguyeãn Troïng Thaùi | E26: 1
B27: 25 | C27: Nguyeãn Huyønh Coâng Thaêng | E27: 1
B28: 26 | C28: Buøi Ngoïc Tuaán | E28: 1
B29: 27 | C29: Ñaëng Duy Phöông | E29: 1
B30: 28 | C30: Phan Thanh Tuøng (Trưởng bộ phận) | E30: 1
B31: 29 | C31: Nguyeãn Tuaán Anh | E31: 1
B32: 30 | C32: Ñoàng Anh Tuaán | E32: 1
B33: 31 | C33: Nguyeãn Thò Thô | E33: 1
B34: 32 | C34: Phaïm Thaønh | E34: 1
B35: 33 | C35: Phaïm Vaên Phuù | E35: 1
B36: 34 | C36: Buøi Minh Kieät | E36: 1
B37: 35 | C37: Phaïm Thò Nhaãn | E37: 1
... B48: 46 | C48: Leâ Hoaøng Phuùc | E48: 1
A49: =#REF! -> #REF! | C49: =#REF! -> #REF! | D49: 0 | E49: =#REF! -> #REF! | P49: =SUM(D49:O49) -> #REF!

Sheet phep
AL2: BAÛNG TOÅNG HÔÏP NGAØY PHEÙP
AN3: Ngaøy pheùp coøn trong naêm tröôùc | AO3: Thaùng 1 | AP3: Thaùng 2 | AQ3: Thaùng 3 | AR3: Thaùng 4 | AS3: Thaùng 5 | AT3: Thaùng 6 | AU3: Thaùng 7 | AV3: Thaùng 8 | AW3: Thaùng 9 | AX3: Thaùng 10 | AY3: Thaùng 11 | AZ3: Thaùng 12 | BA3: Toång hôïp
B4: =#REF! -> #REF! | AL4: 1 | AM4: Nguyeãn Vaên Thaûo | AW4: =#REF! -> #REF! | BA4: =SUM(AO4:AZ4) -> #REF!
B5: =#REF! -> #REF! | AL5: 2 | AM5: Nguyeãn Ngoïc Höng | BA5: =SUM(AO5:AZ5) -> 0
B6: =#REF! -> #REF! | AM6: Nguyễn Thọ Ngọc | AS6: 1 | AW6: 2 | AX6: 1 | AY6: 1 | AZ6: 2 | BA6: =SUM(AO6:AZ6) -> 7
B7: =#REF! -> #REF! | AL7: 3 | AM7: Ngoâ .T. Phan Hieàn | AO7: 1 | AP7: 3 | AQ7: 1 | AR7: 1 | AS7: 1 | AT7: 2 | AV7: 1 | BA7: =SUM(AO7:AZ7) -> 10
B8: =#REF! -> #REF! | AL8: 4 | AM8: Nguyeãn T. Hoàng Aùnh | AP8: 1 | AQ8: 1 | AR8: 1 | AS8: 2 | AT8: 2 | AV8: 3 | AX8: 1 | BA8: =SUM(AO8:AZ8) -> 11
B9: =#REF! -> #REF! | AL9: 5 | AM9: Ninh Phöông Haïnh | AP9: 3 | AR9: 1 | AS9: 6 | AT9: 3 | BA9: =SUM(AO9:AZ9) -> 13
B10: =#REF! -> #REF! | AL10: 6 | AM10: Leâ Hoaøng Tuaán | BA10: =SUM(AO10:AZ10) -> 0
B11: =#REF! -> #REF! | AL11: 7 | AM11: Phaïm Vieät Nam | BA11: =SUM(AO11:AZ11) -> 0
B12: =#REF! -> #REF! | AL12: 8 | AM12: Ñoàng Anh Tuaán | AP12: 1 | AV12: 1 | BA12: =SUM(AO12:AZ12) -> 2
B13: =#REF! -> #REF! | AL13: 11 | AM13: Leâ Coâng Nhaát Trung | AP13: 1 | AR13: 2 | AT13: 1 | AX13: 1 | BA13: =SUM(AO13:AZ13) -> 5
B14: =#REF! -> #REF! | AL14: 12 | AM14: Leâ Thanh Huy
B15: =#REF! -> #REF! | AL15: 13 | AM15: Ngoâ Theá Giang
B16: =#REF! -> #REF! | AL16: 14 | AM16: Traàn Vaên Vò Toaøn | AV16: 3 | AW16: 7 | AZ16: 1 | BA16: =SUM(AO16:AZ16) -> 11
B17: =#REF! -> #REF! | AL17: 15 | AM17: Nguyeãn Vaên Baûy
B18: =#REF! -> #REF! | AL18: 16 | AM18: Phaïm Thanh Tuøng | BA18: =SUM(AO18:AZ18) -> 0
B19: =#REF! -> #REF! | AL19: 17 | AM19: Huyønh Thanh Lieâm | AP19: 1 | AS19: 2 | AZ19: 6 | BA19: =SUM(AO19:AZ19) -> 9
B20: =#REF! -> #REF! | AL20: 18 | AM20: Nguyeãn Ñoã Q. Phöông | AO20: 1 | AP20: 1 | AQ20: 1 | AR20: 1 | AS20: 2 | AT20: 3 | AU20: 4 | BA20: =SUM(AO20:AZ20) -> 13
B21: =#REF! -> #REF! | AL21: 19 | AM21: Hoaøng Giaùng Sinh
B22: =#REF! -> #REF! | AL22: 20 | AM22: Cao Hieäp Thöông | AP22: 1 | AV22: 1 | AW22: 1 | AX22: 1 | BA22: =SUM(AO22:AZ22) -> 4
B23: =#REF! -> #REF! | AL23: 22 | AM23: Ngoâ Maïnh Linh trưởng bộ phận | AP23: 1 | AW23: 10 | AX23: 1 | BA23: =SUM(AO23:AZ23) -> 12
B24: =#REF! -> #REF! | AL24: 23 | AM24: Nguyeãn Cöôøng | AP24: 2 | AT24: 1 | AV24: 3 | AZ24: 1 | BA24: =SUM(AO24:AZ24) -> 7
B25: =#REF! -> #REF! | AL25: 28 | AM25: Phan Thanh Tuøng | AP25: 1 | AS25: 1 | AV25: 1 | AW25: 1 | AX25: 1 | AY25: 1 | BA25: =SUM(AO25:AZ25) -> 6
B26: =#REF! -> #REF! | AL26: 29 | AM26: Nguyeãn Tuaán Anh | AP26: 1 | AW26: 3 | BA26: =SUM(AO26:AZ26) -> 4
B27: =#REF! -> #REF! | AL27: 30 | AM27: Ñoàng Anh Tuaán | AP27: 1 | BA27: =SUM(AO27:AZ27) -> 1
B28: =#REF! -> #REF! | AL28: 31 | AM28: Nguyeãn Thò Thô | BA28: =SUM(AO28:AZ28) -> 0
B29: =#REF! -> #REF! | AL29: 33 | AM29: Phaïm Vaên Phuù | BA29: =SUM(AO29:AZ29) -> 0
B30: =#REF! -> #REF! | AL30: 35 | AM30: Phaïm Thò Nhaãn | BA30: =SUM(AO30:AZ30) -> 0
B31: =#REF! -> #REF! | AL31: 36 | AM31: Nguyeãn Hoàng Haûi (trưởng bộ phận) | AP31: 1 | AR31: 2 | AS31: 1 | AU31: 1 | AV31: 1 | BA31: =SUM(AO31:AZ31) -> 6
B32: =#REF! -> #REF! | AL32: 40 | AM32: Nguyeãn Thanh Tuøng | AP32: 1 | AW32: 1 | AY32: 1 | AZ32: 1 | BA32: =SUM(AO32:AZ32) -> 4 | BB32: 6/2014
B33: =#REF! -> #REF! | AL33: 41 | AM33: Nguyeãn Thaønh Ngoan | AP33: 1 | AU33: 1 | AV33: 1 | AX33: 2 | AY33: 4 | AZ33: 1 | BA33: =SUM(AO33:AZ33) -> 10 | BB33: 06/2014
B34: =#REF! -> #REF! | AL34: 42 | AM34: Nguyeãn Thanh Cöôøng | AP34: 1 | AR34: 1 | AZ34: 1 | BA34: =SUM(AO34:AZ34) -> 3 | BB34: 11/2014
B35: =#REF! -> #REF! | AL35: 43 | AM35: Nguyeãn Ngoïc Hieáu | AP35: 1 | AS35: 1 | AZ35: 1 | BA35: =SUM(AO35:AZ35) -> 3 | BB35: 11/2014
B36: =#REF! -> #REF! | AL36: 44 | AM36: Nguyễn Văn Linh | AP36: 1 | AY36: 1 | BA36: =SUM(AO36:AZ36) -> 2 | BB36: 8/2014
B37: =#REF! -> #REF! | AL37: 45 | AM37: Nguyeãn Vaên Chung | AP37: 1 | BA37: =SUM(AO37:AZ37) -> 1 | BB37: 3/2012
B38: =#REF! -> #REF! | AL38: 46 | AM38: Leâ Hoaøng Phuùc | AP38: 1 | BA38: =SUM(AO38:AZ38) -> 1 | BB38: 4/2013
B39: =#REF! -> #REF! | AM39: ='[2]Luong VP'!C26 -> Toång coäng | AO39: 0 | AP39: ='[2]Cham cong'!AL55 -> 0 | BA39: =SUM(AO39:AZ39) -> 0
B40: =#REF! -> #REF!
B41: =#REF! -> #REF!
...

Sheet Phép năm
A1: 12 | B1: DANH SAÙCH NGHÆ PHEÙP NAÊM
F3: TIME LAØM VIEÄC | I3: 2015 | V3: 2016 | AI3: Dö 2015 | AJ3: 6 thaùng | AK3: Dö 2016 | AM3: 2017
B4: DS THAM GIA BHXH | C4: Ngaøy vaøo laøm | D4: Nghæ | E4: Ñoùng BH | F4: NAÊM | G4: THAÙNG | H4: NGAØY | I4: 1 | J4: 2 | K4: 3 | L4: 4 | M4: 5 | N4: 6 | O4: 7 | P4: 8 | Q4: 9 | R4: 10 | S4: 11 | T4: 12 | V4: 1 | W4: 2 | X4: 3 | Y4: 4 | Z4: 5 | AA4: 6 | AB4: 7 | AC4: 8 | AD4: 9 | AE4: 10 | AF4: 11 | AG4: 12 | AM4: 1 | AN4: 2 | AO4: 3 | AP4: 4 | AQ4: 5 | AR4: 6 | AS4: 7 | AT4: 8 | AU4: 9 | AV4: 10 | AW4: 11 | AX4: 12
B5: Nguyeãn Vaên Thaûo | C5: 37347 | E5: 01/2004 | F5: =DATEDIF(C5,TODAY(),"Y") -> 16 | G5: =DATEDIF(C5,TODAY(),"YM") -> 5 | H5: =DATEDIF(C5,TODAY(),"MD") -> 22 | AH5: =SUM(V5:AG5) -> 0 | AY5: =SUM(AM5:AX5) -> 0
B6: Ngoâ Pa Ri | C6: 37987 | F6: =DATEDIF(C6,TODAY(),"Y") -> 14 | G6: =DATEDIF(C6,TODAY(),"YM") -> 8 | H6: =DATEDIF(C6,TODAY(),"MD") -> 22 | AH6: =SUM(V6:AG6) -> 0 | AY6: =SUM(AM6:AX6) -> 0
B7: Phoøng HCNS - NS
B8: Nguyeãn Ñoã Q. Phöông | C8: 40040 | E8: 06/2010 | F8: =DATEDIF(C8,TODAY(),"Y") -> 9 | G8: =DATEDIF(C8,TODAY(),"YM") -> 1 | H8: =DATEDIF(C8,TODAY(),"MD") -> 8 | AH8: =SUM(V8:AG8) -> 0 | AJ8: =SUM(V8:AA8) -> 0 | AK8: =IF(AI8>=AJ8,INT($F8/5)+$A$1-SUM(AB8:AG8),INT($F8/5)+$A$1-(SUM(V8:AG8)-AI8)) -> 13 | AY8: =SUM(AM8:AX8) -> 0
B9: Leâ Hoaøng Tuaán | C9: 41838 | E9: 4/2016 | F9: =DATEDIF(C9,TODAY(),"Y") -> 4 | G9: =DATEDIF(C9,TODAY(),"YM") -> 2 | H9: =DATEDIF(C9,TODAY(),"MD") -> 5 | AH9: =SUM(V9:AG9) -> 0 | AJ9: =SUM(V9:AA9) -> 0 | AK9: =IF(AI9>=AJ9,INT($F9/5)+$A$1-SUM(AB9:AG9),INT($F9/5)+$A$1-(SUM(V9:AG9)-AI9)) -> 12 | AY9: =SUM(AM9:AX9) -> 0
B10: Traàn Thò Thanh Xuaân | C10: 42298 | E10: 42614 | F10: =DATEDIF(C10,TODAY(),"Y") -> 2 | G10: =DATEDIF(C10,TODAY(),"YM") -> 11 | H10: =DATEDIF(C10,TODAY(),"MD") -> 2 | AD10: 1 | AF10: 1 | AG10: 1 | AH10: =SUM(V10:AG10) -> 3 | AJ10: =SUM(V10:AA10) -> 0 | AK10: =IF(AI10>=AJ10,INT($F10/5)+$A$1-SUM(AB10:AG10),INT($F10/5)+$A$1-(SUM(V10:AG10)-AI10)) -> 9 | AM10: 1 | AO10: 2 | AY10: =SUM(AM10:AX10) -> 3
B11: Đỗ Ngọc Thien Thanh | C11: 42842 | AS11: 3 | AT11: 2 | AY11: =SUM(AM11:AX11) -> 5
B12: Leâ Xuaân Kim | C12: 42464 | F12: =DATEDIF(C12,TODAY(),"Y") -> 2 | G12: =DATEDIF(C12,TODAY(),"YM") -> 5 | H12: =DATEDIF(C12,TODAY(),"MD") -> 19 | AC12: 2 | AH12: =SUM(V12:AG12) -> 2 | AJ12: =SUM(V12:AA12) -> 0 | AK12: =IF(AI12>=AJ12,INT($F12/5)+7-SUM(AB12:AG12),INT($F12/5)+7-(SUM(V12:AG12)-AI12)) -> 5
B13: Ban KSNB - NB
