Workbook

Sheet Sheet2
A1: D.01 | B1: 1 | C1: =VLOOKUP(A1,'Thang bảng lương'!$B$7:$K$44,2,0) -> 7490
A2: D.01 | B2: 2 | C2: =VLOOKUP(A2,'Thang bảng lương'!$B$7:$K$44,3,0) -> 9362.5
A3: D.01 | B3: 3 | C3: =VLOOKUP(A3,'Thang bảng lương'!$B$7:$K$44,4,0) -> 11235
A4: D.01 | B4: 4 | C4: =VLOOKUP(A4,'Thang bảng lương'!$B$7:$K$44,5,0) -> 13107.5
A5: D.01 | B5: 5 | C5: =VLOOKUP(A5,'Thang bảng lương'!$B$7:$K$44,6,0) -> 14980
A6: D.01 | B6: 6 | C6: =VLOOKUP(A6,'Thang bảng lương'!$B$7:$K$44,7,0) -> 16852.5
A7: D.01 | B7: 7 | C7: =VLOOKUP(A7,'Thang bảng lương'!$B$7:$K$44,8,0) -> 18725
A8: D.01 | B8: 8 | C8: =VLOOKUP(A8,'Thang bảng lương'!$B$7:$K$44,9,0) -> 20597.5
A9: D.01 | B9: 9 | C9: =VLOOKUP(A9,'Thang bảng lương'!$B$7:$K$44,10,0) -> 22470
A10: D.02 | B10: 1 | C10: =VLOOKUP(A10,'Thang bảng lương'!$B$7:$K$44,2,0) -> 7490
A11: D.02 | B11: 2 | C11: =VLOOKUP(A11,'Thang bảng lương'!$B$7:$K$44,3,0) -> 8988
A12: D.02 | B12: 3 | C12: =VLOOKUP(A12,'Thang bảng lương'!$B$7:$K$44,4,0) -> 10486
A13: D.02 | B13: 4 | C13: =VLOOKUP(A13,'Thang bảng lương'!$B$7:$K$44,5,0) -> 11984
A14: D.02 | B14: 5 | C14: =VLOOKUP(A14,'Thang bảng lương'!$B$7:$K$44,6,0) -> 13482
A15: D.02 | B15: 6 | C15: =VLOOKUP(A15,'Thang bảng lương'!$B$7:$K$44,7,0) -> 14980
A16: D.02 | B16: 7 | C16: =VLOOKUP(A16,'Thang bảng lương'!$B$7:$K$44,8,0) -> 16478
A17: D.02 | B17: 8 | C17: =VLOOKUP(A17,'Thang bảng lương'!$B$7:$K$44,9,0) -> 17976
A18: D.02 | B18: 9 | C18: =VLOOKUP(A18,'Thang bảng lương'!$B$7:$K$44,10,0) -> 19474
A19: D.03 | B19: 1 | C19: =VLOOKUP(A19,'Thang bảng lương'!$B$7:$K$44,2,0) -> 6366.5
A20: D.03 | B20: 2 | C20: =VLOOKUP(A20,'Thang bảng lương'!$B$7:$K$44,3,0) -> 7490
A21: D.03 | B21: 3 | C21: =VLOOKUP(A21,'Thang bảng lương'!$B$7:$K$44,4,0) -> 8613.5
A22: D.03 | B22: 4 | C22: =VLOOKUP(A22,'Thang bảng lương'!$B$7:$K$44,5,0) -> 9737
A23: D.03 | B23: 5 | C23: =VLOOKUP(A23,'Thang bảng lương'!$B$7:$K$44,6,0) -> 10860.5
A24: D.03 | B24: 6 | C24: =VLOOKUP(A24,'Thang bảng lương'!$B$7:$K$44,7,0) -> 11984
A25: D.03 | B25: 7 | C25: =VLOOKUP(A25,'Thang bảng lương'!$B$7:$K$44,8,0) -> 13107.5
A26: D.03 | B26: 8 | C26: =VLOOKUP(A26,'Thang bảng lương'!$B$7:$K$44,9,0) -> 14231
A27: D.03 | B27: 9 | C27: =VLOOKUP(A27,'Thang bảng lương'!$B$7:$K$44,10,0) -> 15354.5
A28: D.04 | B28: 1 | C28: =VLOOKUP(A28,'Thang bảng lương'!$B$7:$K$44,2,0) -> 5617.5
A29: D.04 | B29: 2 | C29: =VLOOKUP(A29,'Thang bảng lương'!$B$7:$K$44,3,0) -> 6366.5
A30: D.04 | B30: 3 | C30: =VLOOKUP(A30,'Thang bảng lương'!$B$7:$K$44,4,0) -> 7115.5
A31: D.04 | B31: 4 | C31: =VLOOKUP(A31,'Thang bảng lương'!$B$7:$K$44,5,0) -> 7864.5
A32: D.04 | B32: 5 | C32: =VLOOKUP(A32,'Thang bảng lương'!$B$7:$K$44,6,0) -> 8613.5
A33: D.04 | B33: 6 | C33: =VLOOKUP(A33,'Thang bảng lương'!$B$7:$K$44,7,0) -> 9362.5
A34: D.04 | B34: 7 | C34: =VLOOKUP(A34,'Thang bảng lương'!$B$7:$K$44,8,0) -> 10111.5
A35: D.04 | B35: 8 | C35: =VLOOKUP(A35,'Thang bảng lương'!$B$7:$K$44,9,0) -> 10860.5
A36: D.04 | B36: 9 | C36: =VLOOKUP(A36,'Thang bảng lương'!$B$7:$K$44,10,0) -> 11609.5
A37: D.05 | B37: 1 | C37: =VLOOKUP(A37,'Thang bảng lương'!$B$7:$K$44,2,0) -> 3745
A38: D.05 | B38: 2 | C38: =VLOOKUP(A38,'Thang bảng lương'!$B$7:$K$44,3,0) -> 4494
A39: D.05 | B39: 3 | C39: =VLOOKUP(A39,'Thang bảng lương'!$B$7:$K$44,4,0) -> 5243
A40: D.05 | B40: 4 | C40: =VLOOKUP(A40,'Thang bảng lương'!$B$7:$K$44,5,0) -> 5992
...

Sheet Thang bảng lương
A1: A. MỨC LƯƠNG TỐI THIỂU: Mức lương tối thiểu doanh nghiệp áp dụng: | E1: =F2 -> 3745000 | G1: ñ/thaùng
A2: B. HỆ THỐNG THANG LƯƠNG, BẢNG LƯƠNG | F2: =3500000*107% -> 3745000
A3: I. Thang lương chức vụ quản lý doanh nghiệp: | H3: (ĐVT: 1.000đ)
A4: Chức danh công việc | B4: Ngạch lương | C4: Bậc
C5: 1 | D5: 2 | E5: 3 | F5: 4 | G5: 5 | H5: 6 | I5: 7 | J5: 8 | K5: 9
A6: 1. Tổng Giám đốc, Giám đốc
A7: Hệ số | C7: 2 | D7: 2.5 | E7: 3 | F7: 3.5 | G7: 4 | H7: 4.5 | I7: 5 | J7: 5.5 | K7: 6
A8: Mức lương tháng | B8: D.01 | C8: =C7*$E$1/1000 -> 7490 | D8: =D7*$E$1/1000 -> 9362.5 | E8: =E7*$E$1/1000 -> 11235 | F8: =F7*$E$1/1000 -> 13107.5 | G8: =G7*$E$1/1000 -> 14980 | H8: =H7*$E$1/1000 -> 16852.5 | I8: =I7*$E$1/1000 -> 18725 | J8: =J7*$E$1/1000 -> 20597.5 | K8: =K7*$E$1/1000 -> 22470
A9: Mức lương ngày | C9: =C8/26 -> 288.07692 | D9: =D8/26 -> 360.09615 | E9: =E8/26 -> 432.11538 | F9: =F8/26 -> 504.13462 | G9: =G8/26 -> 576.15385 | H9: =H8/26 -> 648.17308 | I9: =I8/26 -> 720.19231 | J9: =J8/26 -> 792.21154 | K9: =K8/26 -> 864.23077
A10: 2. Kế toán trưởng, Trưởng phòng
A11: Hệ số | C11: 2 | D11: 2.4 | E11: 2.8 | F11: 3.2 | G11: 3.6 | H11: 4 | I11: 4.4 | J11: 4.8 | K11: 5.2
A12: Mức lương tháng | B12: D.02 | C12: =C11*$E$1/1000 -> 7490 | D12: =D11*$E$1/1000 -> 8988 | E12: =E11*$E$1/1000 -> 10486 | F12: =F11*$E$1/1000 -> 11984 | G12: =G11*$E$1/1000 -> 13482 | H12: =H11*$E$1/1000 -> 14980 | I12: =I11*$E$1/1000 -> 16478 | J12: =J11*$E$1/1000 -> 17976 | K12: =K11*$E$1/1000 -> 19474
A13: Mức lương ngày | C13: =C12/26 -> 288.07692 | D13: =D12/26 -> 345.69231 | E13: =E12/26 -> 403.30769 | F13: =F12/26 -> 460.92308 | G13: =G12/26 -> 518.53846 | H13: =H12/26 -> 576.15385 | I13: =I12/26 -> 633.76923 | J13: =J12/26 -> 691.38462 | K13: =K12/26 -> 749
A14: II. Thang lương viên chức, chuyên môn, thừa hành, nghiệp vụ:
A15: Chức danh công việc | B15: Ngạch lương | C15: Baäc
C16: 1 | D16: 2 | E16: 3 | F16: 4 | G16: 5 | H16: 6 | I16: 7 | J16: 8 | K16: 9
A17: 1. Trợ lý GĐ, trưởng đầu ngành, chuyên viên
A18: Hệ số | C18: 1.7 | D18: 2 | E18: 2.3 | F18: 2.6 | G18: 2.9 | H18: 3.2 | I18: 3.5 | J18: 3.8 | K18: 4.1
A19: Mức lương tháng | B19: D.03 | C19: =C18*$E$1/1000 -> 6366.5 | D19: =D18*$E$1/1000 -> 7490 | E19: =E18*$E$1/1000 -> 8613.5 | F19: =F18*$E$1/1000 -> 9737 | G19: =G18*$E$1/1000 -> 10860.5 | H19: =H18*$E$1/1000 -> 11984 | I19: =I18*$E$1/1000 -> 13107.5 | J19: =J18*$E$1/1000 -> 14231 | K19: =K18*$E$1/1000 -> 15354.5
A20: Mức lương ngày | C20: =C19/26 -> 244.86538 | D20: =D19/26 -> 288.07692 | E20: =E19/26 -> 331.28846 | F20: =F19/26 -> 374.5 | G20: =G19/26 -> 417.71154 | H20: =H19/26 -> 460.92308 | I20: =I19/26 -> 504.13462 | J20: =J19/26 -> 547.34615 | K20: =K19/26 -> 590.55769
A21: 2. kỹ sư, Giám sát.
A22: Hệ số | C22: 1.5 | D22: 1.7 | E22: 1.9 | F22: 2.1 | G22: 2.3 | H22: 2.5 | I22: 2.7 | J22: 2.9 | K22: 3.1
A23: Mức lương tháng | B23: D.04 | C23: =C22*$E$1/1000 -> 5617.5 | D23: =D22*$E$1/1000 -> 6366.5 | E23: =E22*$E$1/1000 -> 7115.5 | F23: =F22*$E$1/1000 -> 7864.5 | G23: =G22*$E$1/1000 -> 8613.5 | H23: =H22*$E$1/1000 -> 9362.5 | I23: =I22*$E$1/1000 -> 10111.5 | J23: =J22*$E$1/1000 -> 10860.5 | K23: =K22*$E$1/1000 -> 11609.5
A24: Mức lương ngày | C24: =C23/26 -> 216.05769 | D24: =D23/26 -> 244.86538 | E24: =E23/26 -> 273.67308 | F24: =F23/26 -> 302.48077 | G24: =G23/26 -> 331.28846 | H24: =H23/26 -> 360.09615 | I24: =I23/26 -> 388.90385 | J24: =J23/26 -> 417.71154 | K24: =K23/26 -> 446.51923
A25: 3. NV Kinh doanh
A26: Hệ số | C26: 1 | D26: 1.2 | E26: 1.4 | F26: 1.6 | G26: 1.8 | H26: 2 | I26: 2.2 | J26: 2.4 | K26: 2.6
A27: Mức lương tháng | B27: D.05 | C27: =C26*$E$1/1000 -> 3745 | D27: =D26*$E$1/1000 -> 4494 | E27: =E26*$E$1/1000 -> 5243 | F27: =F26*$E$1/1000 -> 5992 | G27: =G26*$E$1/1000 -> 6741 | H27: =H26*$E$1/1000 -> 7490 | I27: =I26*$E$1/1000 -> 8239 | J27: =J26*$E$1/1000 -> 8988 | K27: =K26*$E$1/1000 -> 9737
A28: Mức lương ngày | C28: =C27/26 -> 144.03846 | D28: =D27/26 -> 172.84615 | E28: =E27/26 -> 201.65385 | F28: =F27/26 -> 230.46154 | G28: =G27/26 -> 259.26923 | H28: =H27/26 -> 288.07692 | I28: =I27/26 -> 316.88462 | J28: =J27/26 -> 345.69231 | K28: =K27/26 -> 374.5
A29: 3. Lái xe, K.thuật viên, Ktoán viên.
A30: Hệ số | C30: 1 | D30: 1.1 | E30: 1.2 | F30: 1.3 | G30: 1.4 | H30: 1.5 | I30: 1.6 | J30: 1.7 | K30: 1.8
A31: Mức lương tháng | B31: D.06 | C31: =C30*$E$1/1000 -> 3745 | D31: =D30*$E$1/1000 -> 4119.5 | E31: =E30*$E$1/1000 -> 4494 | F31: =F30*$E$1/1000 -> 4868.5 | G31: =G30*$E$1/1000 -> 5243 | H31: =H30*$E$1/1000 -> 5617.5 | I31: =I30*$E$1/1000 -> 5992 | J31: =J30*$E$1/1000 -> 6366.5 | K31: =K30*$E$1/1000 -> 6741
A32: Mức lương ngày | C32: =C31/26 -> 144.03846 | D32: =D31/26 -> 158.44231 | E32: =E31/26 -> 172.84615 | F32: =F31/26 -> 187.25 | G32: =G31/26 -> 201.65385 | H32: =H31/26 -> 216.05769 | I32: =I31/26 -> 230.46154 | J32: =J31/26 -> 244.86538 | K32: =K31/26 -> 259.26923
A33: 4. NV văn phòng, NV V.Tư
A34: Hệ số | C34: 1 | D34: 1.1 | E34: 1.2 | F34: 1.3 | G34: 1.4 | H34: 1.5 | I34: 1.6 | J34: 1.7 | K34: 1.8
A35: Mức lương tháng | B35: D.07 | C35: =C34*$E$1/1000 -> 3745 | D35: =D34*$E$1/1000 -> 4119.5 | E35: =E34*$E$1/1000 -> 4494 | F35: =F34*$E$1/1000 -> 4868.5 | G35: =G34*$E$1/1000 -> 5243 | H35: =H34*$E$1/1000 -> 5617.5 | I35: =I34*$E$1/1000 -> 5992 | J35: =J34*$E$1/1000 -> 6366.5 | K35: =K34*$E$1/1000 -> 6741
A36: Mức lương ngày | C36: =C35/26 -> 144.03846 | D36: =D35/26 -> 158.44231 | E36: =E35/26 -> 172.84615 | F36: =F35/26 -> 187.25 | G36: =G35/26 -> 201.65385 | H36: =H35/26 -> 216.05769 | I36: =I35/26 -> 230.46154 | J36: =J35/26 -> 244.86538 | K36: =K35/26 -> 259.26923
A37: 5. Nhân viên văn thư, NVgiao hàng, phụ xe
A38: Hệ số | C38: 1 | D38: 1.05 | E38: 1.1 | F38: 1.15 | G38: 1.2 | H38: 1.25 | I38: 1.3 | J38: 1.35 | K38: 1.4
A39: Mức lương tháng | B39: D.08 | C39: =C38*$E$1/1000 -> 3745 | D39: =D38*$E$1/1000 -> 3932.25 | E39: =E38*$E$1/1000 -> 4119.5 | F39: =F38*$E$1/1000 -> 4306.75 | G39: =G38*$E$1/1000 -> 4494 | H39: =H38*$E$1/1000 -> 4681.25 | I39: =I38*$E$1/1000 -> 4868.5 | J39: =J38*$E$1/1000 -> 5055.75 | K39: =K38*$E$1/1000 -> 5243
A40: Mức lương ngày | C40: =C39/26 -> 144.03846 | D40: =D39/26 -> 151.24038 | E40: =E39/26 -> 158.44231 | F40: =F39/26 -> 165.64423 | G40: =G39/26 -> 172.84615 | H40: =H39/26 -> 180.04808 | I40: =I39/26 -> 187.25 | J40: =J39/26 -> 194.45192 | K40: =K39/26 -> 201.65385
...

Sheet Diễn giải
A2: 1 | B2: Tiêu chí xây dựng bảng lương
B3: - Người lao động được hưởng đúng mức năng lực, tài năng thể hiện tại Công ty;
B4: - Bằng cấp chỉ thể hiện mong muốn của người lao động chứ không thể hiện mưc lương và vị trí làm việc;
B5: - Đi gần nhất với luật lao động, mức lương tối thiểu vùng ...;
B6: - Là công cụ để Công ty quản lý năng suất lao động của người Lao động;
B7: - Người Lao động chủ động phấn đấu cho thu nhập của chính mình;
B8: - Kiểm soát thời gian làm việc của lao động;
B9: - Kiểm soát hiệu quả công việc lao động;
B10: - Kiểm soát thực hiện kế hoạch của Công ty/lao động;
B11: - Thống kê được chính xác hao phí lao động cho từng đầu công việc để tìm ra được phương pháp quản lý, cải tiến, đầu tư hiệu quả.
A12: 2 | B12: Lương tối thiểu
B13: - Áp dụng mức lương tối thiểu vùng 2016 cho khu vực Tp.HCM là 3.484.400vnđ
A14: 3 | B14: Hệ thống thang bảng lương
B15: - Áp dụng 09 ngạch lương, ký hiệu từ D.01 đến D.09;
B16: - Áp dụng 09 bậc lương, ký hiệu từ 1 đến 9;
B17: - Áp dụng 08 nhóm chức danh công việc;
B18: - Bước nhảy mỗi bậc lương:
C19: + Ngạch D.01: bước nhảy là 0,5. Hệ số bắt đầu là 2 tương ứng với bậc 1
C20: + Ngạch D.02: bước nhảy là 0,4. Hệ số bắt đầu là 2 tương ứng với bậc 1
C21: + Ngạch D.03: bước nhảy là 0,3. Hệ số bắt đầu là 1,7 tương ứng với bậc 1
C22: + Ngạch D.04: bước nhảy là 0,2. Hệ số bắt đầu là 1,5 tương ứng với bậc 1
C23: + Ngạch D.05: bước nhảy là 0,2. Hệ số bắt đầu là 1 tương ứng với bậc 1
C24: + Ngạch D.06: bước nhảy là 0,1. Hệ số bắt đầu là 1 tương ứng với bậc 1
C25: + Ngạch D.07: bước nhảy là 0,1. Hệ số bắt đầu là 1 tương ứng với bậc 1
C26: + Ngạch D.08: bước nhảy là 0,05. Hệ số bắt đầu là 1 tương ứng với bậc 1
C27: + Ngạch D.09: bước nhảy là 0,05. Hệ số bắt đầu là 1 tương ứng với bậc 1
A28: 4 | B28: Thâm niên làm việc
B29: - Mỗi 12 tháng làm việc liên tiếp sẽ được tính thâm niên là 1 năm làm việc;
B30: - Người lao động nghỉ việc quay lại làm việc thì thâm niên sẽ được tính thời gian làm việc gần nhất;
B31: - Mỗi năm làm việc được hưởng 1%
C32: Công thức tính: Phụ cấp thâm niên = lương CB hệ số x số năm làm việc /100
A33: 5 | B33: Ngày công làm việc
B34: - Ngày công làm việc được tính trung bình 26 ngày công/tháng (áp dụng cho các thông số tính TB tháng);
B35: - Ngày công làm việc là tổng số ngày trong tháng trừ đi tổng số ngày chủ nhật trong tháng;
A36: 6 | B36: Giờ làm việc
B37: - Tổng số giờ làm việc trong 1 ngày: 8 giờ;
B38: - Giờ tăng ca được tính sau giờ làm việc Công ty quy định;
B39: - Tính tiền tăng ca:
C40: + Tăng ca ngày thường = số công tăng ca x 1,5 x lương CB hệ số
C41: + Tăng ca ngày chủ nhật = số công tăng ca x 2 x lương CB hệ số
...

Sheet Bang luong
A1: CÔNG TY TNHH CÔNG NGHỆ SINH HỌC SÀI GÒN XANH
A2: Nhà máy Xử lý Bùn thải Sài Gòn Xanh | J2: BẢNG LƯƠNG THÁNG 11 /2015 | Y2: Tỷ lệ đóng BH | AA2: 0.105
G3: =3500000*107% -> 3745000 | K3: 26 | S3: 1 | T3: 300000
A4: STT | B4: Mã Nhân viên | C4: Họ và Tên | D4: Chức vụ | E4: Ngày vào làm việc | F4: Số năm vào làm | G4: Lương tối thiểu | H4: Ngạch lương | I4: hệ số lương | J4: lương CB hệ số | K4: Ngày công lv | L4: Lương Định mức | M4: Ngày phép, LT có lương | N4: Giờ tăng ca | O4: Giờ làm việc CN | P4: Ngày LV lễ tết | Q4: Thành tiền lương CB | R4: lương vượt định mức | S4: Phụ Cấp thâm niên | T4: Phụ cấp chuyên cần | U4: Phụ cấp chuyên môn | V4: Phụ cấp trách nhiệm | W4: Phụ cấp công tác | X4: Phụ cấp điện thoại | Y4: Tổng thu nhập | Z4: Trừ tạm ứng | AA4: Trừ BHXH | AB4: Thực lãnh | AC4: Thực lãnh | AD4: Ký Nhận | AF4: Tièn lương dóng BH
A5: G | C5: QUẢN LÝ SẢN XUẤT | Y5: =SUM(Y6:Y9) -> #N/A | Z5: =SUM(Z6:Z9) -> #REF! | AA5: =SUM(AA6:AA9) -> 1125600 | AB5: =SUM(AB6:AB9) -> #N/A | AC5: =SUM(AC6:AC9) -> #N/A
A6: 1 | B6: NV45 | C6: Nguyễn Đình Huệ | D6: Quản đốc SX | E6: 38078 | F6: =IF(E6=0,0,INT((NOW()-E6)/365)) -> 15 | G6: =$G$3 -> 3745000 | H6: D.03 | I6: 1 | J6: =SUMIFS(Sheet2!$C$1:$C$81,Sheet2!$A$1:$A$81,'Bang luong'!H6,Sheet2!$B$1:$B$81,'Bang luong'!I6)*1000 -> 6366500 | K6: =VLOOKUP(C6,CC!$C$5:$AJ$67,34,0) -> #N/A | L6: =J6/26*K6 -> #N/A | M6: =VLOOKUP(C6,CC!$C$5:$AM$67,36,0) -> #N/A | N6: =VLOOKUP(C6,CC!$C$5:$BS$67,69,0) -> #N/A | O6: =VLOOKUP(C6,CC!$C$5:$BT$67,70,0) -> #N/A | P6: =VLOOKUP(C6,CC!$C$5:$AM$67,37,0) -> #N/A | Q6: =((J6/26)*K6)+(M6*(J6/26))+((N6/8)*1.5*(J6/26))+((O6/8)*2*J6/26)+(P6*3*(J6/26)) -> #N/A | S6: =IF((F6-$S$3)>0,F6%*J6,0) -> 954975 | T6: =(100%-SUMIF('chuyên cần'!$C$6:$AP$31,'Bang luong'!C6,'chuyên cần'!$AP$7:$AP$31))*$T$3 -> 300000 | U6: 2000000 | V6: 1000000 | W6: 500000 | X6: 200000 | Y6: =Q6+R6+S6+T6+U6+V6+W6+X6 -> #N/A | Z6: ='ung luong'!#REF! -> #REF! | AA6: =AF6*$AA$2 -> 422100 | AB6: =Y6-Z6-AA6 -> #N/A | AC6: =ROUND(AB6,-3) -> #N/A | AF6: 4020000
A7: 2 | B7: NV46 | C7: Nguyễn Văn Thanh | D7: Trợ lý SX | E7: 40868 | F7: =IF(E7=0,0,INT((NOW()-E7)/365)) -> 7 | G7: =$G$3 -> 3745000 | H7: D.04 | I7: 2 | J7: =SUMIFS(Sheet2!$C$1:$C$81,Sheet2!$A$1:$A$81,'Bang luong'!H7,Sheet2!$B$1:$B$81,'Bang luong'!I7)*1000 -> 6366500 | K7: =VLOOKUP(C7,CC!$C$5:$AJ$67,34,0) -> #N/A | L7: =J7/26*K7 -> #N/A | M7: =VLOOKUP(C7,CC!$C$5:$AM$67,36,0) -> #N/A | N7: =VLOOKUP(C7,CC!$C$5:$BS$67,69,0) -> #N/A | O7: =VLOOKUP(C7,CC!$C$5:$BT$67,70,0) -> #N/A | P7: =VLOOKUP(C7,CC!$C$5:$AM$67,37,0) -> #N/A | Q7: =((J7/26)*K7)+(M7*(J7/26))+((N7/8)*1.5*(J7/26))+((O7/8)*2*J7/26)+(P7*3*(J7/26)) -> #N/A | S7: =IF((F7-$S$3)>0,F7%*J7,0) -> 445655 | T7: =(100%-SUMIF('chuyên cần'!$C$6:$AP$31,'Bang luong'!C7,'chuyên cần'!$AP$7:$AP$31))*$T$3 -> 300000 | U7: 1000000 | V7: 500000 | W7: 500000 | X7: 200000 | Y7: =Q7+R7+S7+T7+U7+V7+W7+X7 -> #N/A | Z7: ='ung luong'!#REF! -> #REF! | AA7: =AF7*$AA$2 -> 351750 | AB7: =Y7-Z7-AA7 -> #N/A | AC7: =ROUND(AB7,-3) -> #N/A | AF7: 3350000
A8: 3 | B8: NV47 | C8: Chề A Sắt | D8: Giám Sát | E8: 41715 | F8: =IF(E8=0,0,INT((NOW()-E8)/365)) -> 5 | G8: =$G$3 -> 3745000 | H8: D.07 | I8: 4 | J8: =SUMIFS(Sheet2!$C$1:$C$81,Sheet2!$A$1:$A$81,'Bang luong'!H8,Sheet2!$B$1:$B$81,'Bang luong'!I8)*1000 -> 4868500 | K8: =VLOOKUP(C8,CC!$C$5:$AJ$67,34,0) -> #N/A | L8: =J8/26*K8 -> #N/A | M8: =VLOOKUP(C8,CC!$C$5:$AM$67,36,0) -> #N/A | N8: =VLOOKUP(C8,CC!$C$5:$BS$67,69,0) -> #N/A | O8: =VLOOKUP(C8,CC!$C$5:$BT$67,70,0) -> #N/A | P8: =VLOOKUP(C8,CC!$C$5:$AM$67,37,0) -> #N/A | Q8: =((J8/26)*K8)+(M8*(J8/26))+((N8/8)*1.5*(J8/26))+((O8/8)*2*J8/26)+(P8*3*(J8/26)) -> #N/A | S8: =IF((F8-$S$3)>0,F8%*J8,0) -> 243425 | T8: =(100%-SUMIF('chuyên cần'!$C$6:$AP$31,'Bang luong'!C8,'chuyên cần'!$AP$7:$AP$31))*$T$3 -> 300000 | U8: 500000 | V8: 500000 | X8: 200000 | Y8: =Q8+R8+S8+T8+U8+V8+W8+X8 -> #N/A | Z8: ='ung luong'!#REF! -> #REF! | AA8: =AF8*$AA$2 -> 351750 | AB8: =Y8-Z8-AA8 -> #N/A | AC8: =ROUND(AB8,-3) -> #N/A | AF8: 3350000
A9: 4 | B9: NV48 | C9: Ngô Đình Chung | D9: NV trạm cân | E9: 42086 | F9: =IF(E9=0,0,INT((NOW()-E9)/365)) -> 4 | G9: =$G$3 -> 3745000 | H9: D.07 | I9: 1 | J9: =SUMIFS(Sheet2!$C$1:$C$81,Sheet2!$A$1:$A$81,'Bang luong'!H9,Sheet2!$B$1:$B$81,'Bang luong'!I9)*1000 -> 3745000 | K9: =VLOOKUP(C9,CC!$C$5:$AJ$67,34,0) -> 27 | L9: =J9/26*K9 -> 3889038.5 | M9: =VLOOKUP(C9,CC!$C$5:$AM$67,36,0) -> 0 | N9: =VLOOKUP(C9,CC!$C$5:$BS$67,69,0) -> 0 | O9: =VLOOKUP(C9,CC!$C$5:$BT$67,70,0) -> 0 | P9: =VLOOKUP(C9,CC!$C$5:$AM$67,37,0) -> 0 | Q9: =((J9/26)*K9)+(M9*(J9/26))+((N9/8)*1.5*(J9/26))+((O9/8)*2*J9/26)+(P9*3*(J9/26)) -> 3889038.5 | S9: =IF((F9-$S$3)>0,F9%*J9,0) -> 149800 | T9: =(100%-SUMIF('chuyên cần'!$C$6:$AP$31,'Bang luong'!C9,'chuyên cần'!$AP$7:$AP$31))*$T$3 -> 300000 | U9: 500000 | V9: 500000 | X9: 200000 | Y9: =Q9+R9+S9+T9+U9+V9+W9+X9 -> 5538838.5 | Z9: ='ung luong'!#REF! -> #REF! | AA9: =AF9*$AA$2 -> 0 | AB9: =Y9-Z9-AA9 -> #REF! | AC9: =ROUND(AB9,-3) -> #REF!
C10: KHO | Y10: =SUM(Y11:Y12) -> #N/A | Z10: =SUM(Z11:Z12) -> #REF! | AA10: =SUM(AA11:AA12) -> 422100 | AB10: =SUM(AB11:AB12) -> #N/A | AC10: =SUM(AC11:AC12) -> #N/A
A11: 5 | B11: NV49 | C11: Đồng Anh Tuấn | D11: Thủ kho | E11: 40651 | F11: =IF(E11=0,0,INT((NOW()-E11)/365)) -> 8 | G11: =$G$3 -> 3745000 | H11: D.04 | I11: 3 | J11: =SUMIFS(Sheet2!$C$1:$C$81,Sheet2!$A$1:$A$81,'Bang luong'!H11,Sheet2!$B$1:$B$81,'Bang luong'!I11)*1000 -> 7115500 | K11: =VLOOKUP(C11,CC!$C$5:$AJ$67,34,0) -> #N/A | L11: =J11/26*K11 -> #N/A | M11: =VLOOKUP(C11,CC!$C$5:$AM$67,36,0) -> #N/A | N11: =VLOOKUP(C11,CC!$C$5:$BS$67,69,0) -> #N/A | O11: =VLOOKUP(C11,CC!$C$5:$BT$67,70,0) -> #N/A | P11: =VLOOKUP(C11,CC!$C$5:$AM$67,37,0) -> #N/A | Q11: =((J11/26)*K11)+(M11*(J11/26))+((N11/8)*1.5*(J11/26))+((O11/8)*2*J11/26)+(P11*3*(J11/26)) -> #N/A | S11: =IF((F11-$S$3)>0,F11%*J11,0) -> 569240 | T11: =(100%-SUMIF('chuyên cần'!$C$6:$AP$31,'Bang luong'!C11,'chuyên cần'!$AP$7:$AP$31))*$T$3 -> 300000 | U11: 1000000 | V11: 500000 | W11: 500000 | X11: 200000 | Y11: =Q11+R11+S11+T11+U11+V11+W11+X11 -> #N/A | Z11: ='ung luong'!#REF! -> #REF! | AA11: =AF11*$AA$2 -> 422100 | AB11: =Y11-Z11-AA11 -> #N/A | AC11: =ROUND(AB11,-3) -> #N/A | AF11: 4020000
A12: 6 | B12: NV50 | C12: Nguyễn Trường Thạch | D12: NV kho | F12: =IF(E12=0,0,INT((NOW()-E12)/365)) -> 0 | G12: =$G$3 -> 3745000 | H12: D.07 | I12: 1 | J12: =SUMIFS(Sheet2!$C$1:$C$81,Sheet2!$A$1:$A$81,'Bang luong'!H12,Sheet2!$B$1:$B$81,'Bang luong'!I12)*1000 -> 3745000 | K12: =VLOOKUP(C12,CC!$C$5:$AJ$67,34,0) -> #N/A | L12: =J12/26*K12 -> #N/A | M12: =VLOOKUP(C12,CC!$C$5:$AM$67,36,0) -> #N/A | N12: =VLOOKUP(C12,CC!$C$5:$BS$67,69,0) -> #N/A | O12: =VLOOKUP(C12,CC!$C$5:$BT$67,70,0) -> #N/A | P12: =VLOOKUP(C12,CC!$C$5:$AM$67,37,0) -> #N/A | Q12: =((J12/26)*K12)+(M12*(J12/26))+((N12/8)*1.5*(J12/26))+((O12/8)*2*J12/26)+(P12*3*(J12/26)) -> #N/A | S12: =IF((F12-$S$3)>0,F12%*J12,0) -> 0 | T12: =(100%-SUMIF('chuyên cần'!$C$6:$AP$31,'Bang luong'!C12,'chuyên cần'!$AP$7:$AP$31))*$T$3 -> 300000 | U12: 500000 | V12: 500000 | X12: 200000 | Y12: =Q12+R12+S12+T12+U12+V12+W12+X12 -> #N/A | Z12: ='ung luong'!#REF! -> #REF! | AA12: =AF12*$AA$2 -> 0 | AB12: =Y12-Z12-AA12 -> #N/A | AC12: =ROUND(AB12,-3) -> #N/A
A13: H | C13: CHUYÊN VIÊN KỸ THUẬT | Y13: =SUM(Y14:Y16) -> #N/A | Z13: =SUM(Z14:Z16) -> #REF! | AA13: =SUM(AA14:AA16) -> 348285 | AB13: =SUM(AB14:AB16) -> #N/A | AC13: =SUM(AC14:AC16) -> #N/A
A14: 7 | B14: NV51 | C14: Lê Công Nhất Trung | D14: KS Môi trường | E14: 41487 | F14: =IF(E14=0,0,INT((NOW()-E14)/365)) -> 6 | G14: =$G$3 -> 3745000 | H14: D.04 | I14: 3 | J14: =SUMIFS(Sheet2!$C$1:$C$81,Sheet2!$A$1:$A$81,'Bang luong'!H14,Sheet2!$B$1:$B$81,'Bang luong'!I14)*1000 -> 7115500 | K14: =VLOOKUP(C14,CC!$C$5:$AJ$67,34,0) -> #N/A | L14: =J14/26*K14 -> #N/A | M14: =VLOOKUP(C14,CC!$C$5:$AM$67,36,0) -> #N/A | N14: =VLOOKUP(C14,CC!$C$5:$BS$67,69,0) -> #N/A | O14: =VLOOKUP(C14,CC!$C$5:$BT$67,70,0) -> #N/A | P14: =VLOOKUP(C14,CC!$C$5:$AM$67,37,0) -> #N/A | Q14: =((J14/26)*K14)+(M14*(J14/26))+((N14/8)*1.5*(J14/26))+((O14/8)*2*J14/26)+(P14*3*(J14/26)) -> #N/A | S14: =IF((F14-$S$3)>0,F14%*J14,0) -> 426930 | T14: =(100%-SUMIF('chuyên cần'!$C$6:$AP$31,'Bang luong'!C14,'chuyên cần'!$AP$7:$AP$31))*$T$3 -> 300000 | U14: 1000000 | V14: 500000 | X14: 200000 | Y14: =Q14+R14+S14+T14+U14+V14+W14+X14 -> #N/A | Z14: ='ung luong'!#REF! -> #REF! | AA14: =AF14*$AA$2 -> 348285 | AB14: =Y14-Z14-AA14 -> #N/A | AC14: =ROUND(AB14,-3) -> #N/A | AF14: 3317000
A15: 8 | B15: NV52 | C15: Hồ Phan Thiết Toàn | D15: KS Nông nghiệp | E15: 42114 | F15: =IF(E15=0,0,INT((NOW()-E15)/365)) -> 4 | G15: =$G$3 -> 3745000 | H15: D.04 | I15: 3 | J15: =SUMIFS(Sheet2!$C$1:$C$81,Sheet2!$A$1:$A$81,'Bang luong'!H15,Sheet2!$B$1:$B$81,'Bang luong'!I15)*1000 -> 7115500 | K15: =VLOOKUP(C15,CC!$C$5:$AJ$67,34,0) -> #N/A | L15: =J15/26*K15 -> #N/A | M15: =VLOOKUP(C15,CC!$C$5:$AM$67,36,0) -> #N/A | N15: =VLOOKUP(C15,CC!$C$5:$BS$67,69,0) -> #N/A | O15: =VLOOKUP(C15,CC!$C$5:$BT$67,70,0) -> #N/A | P15: =VLOOKUP(C15,CC!$C$5:$AM$67,37,0) -> #N/A | Q15: =((J15/26)*K15)+(M15*(J15/26))+((N15/8)*1.5*(J15/26))+((O15/8)*2*J15/26)+(P15*3*(J15/26)) -> #N/A | S15: =IF((F15-$S$3)>0,F15%*J15,0) -> 284620 | T15: =(100%-SUMIF('chuyên cần'!$C$6:$AP$31,'Bang luong'!C15,'chuyên cần'!$AP$7:$AP$31))*$T$3 -> 300000 | U15: 1000000 | V15: 500000 | X15: 200000 | Y15: =Q15+R15+S15+T15+U15+V15+W15+X15 -> #N/A | Z15: ='ung luong'!#REF! -> #REF! | AA15: =AF15*$AA$2 -> 0 | AB15: =Y15-Z15-AA15 -> #N/A | AC15: =ROUND(AB15,-3) -> #N/A
A16: 9 | B16: NV89 | C16: Trần Văn Hà | D16: KTV Môi trường | E16: 42248 | F16: =IF(E16=0,0,INT((NOW()-E16)/365)) -> 4 | G16: =$G$3 -> 3745000 | H16: D.06 | I16: 1 | J16: =SUMIFS(Sheet2!$C$1:$C$81,Sheet2!$A$1:$A$81,'Bang luong'!H16,Sheet2!$B$1:$B$81,'Bang luong'!I16)*1000 -> 3745000 | K16: =VLOOKUP(C16,CC!$C$5:$AJ$67,34,0) -> #N/A | L16: =J16/26*K16 -> #N/A | M16: =VLOOKUP(C16,CC!$C$5:$AM$67,36,0) -> #N/A | N16: =VLOOKUP(C16,CC!$C$5:$BS$67,69,0) -> #N/A | O16: =VLOOKUP(C16,CC!$C$5:$BT$67,70,0) -> #N/A | P16: =VLOOKUP(C16,CC!$C$5:$AM$67,37,0) -> #N/A | Q16: =((J16/26)*K16)+(M16*(J16/26))+((N16/8)*1.5*(J16/26))+((O16/8)*2*J16/26)+(P16*3*(J16/26)) -> #N/A | S16: =IF((F16-$S$3)>0,F16%*J16,0) -> 149800 | T16: =(100%-SUMIF('chuyên cần'!$C$6:$AP$31,'Bang luong'!C16,'chuyên cần'!$AP$7:$AP$31))*$T$3 -> 300000 | U16: 500000 | V16: 500000 | X16: 200000 | Y16: =Q16+R16+S16+T16+U16+V16+W16+X16 -> #N/A | Z16: ='ung luong'!#REF! -> #REF! | AA16: =AF16*$AA$2 -> 0 | AB16: =Y16-Z16-AA16 -> #N/A | AC16: =ROUND(AB16,-3) -> #N/A
A17: J | C17: CÔNG NHÂN KỸ THUẬT | Y17: =SUM(Y18:Y32) -> #N/A | Z17: =SUM(Z18:Z32) -> #REF! | AA17: =SUM(AA18:AA32) -> 3155070 | AB17: =SUM(AB18:AB32) -> #N/A | AC17: =SUM(AC18:AC32) -> #N/A
A18: 10 | B18: NV53 | C18: Trần Ngọc Minh | D18: NV bảo trì | E18: 41108 | F18: =IF(E18=0,0,INT((NOW()-E18)/365)) -> 7 | G18: =$G$3 -> 3745000 | H18: D.06 | I18: 1 | J18: =SUMIFS(Sheet2!$C$1:$C$81,Sheet2!$A$1:$A$81,'Bang luong'!H18,Sheet2!$B$1:$B$81,'Bang luong'!I18)*1000 -> 3745000 | K18: =VLOOKUP(C18,CC!$C$5:$AJ$67,34,0) -> #N/A | L18: =J18/26*K18 -> #N/A | M18: =VLOOKUP(C18,CC!$C$5:$AM$67,36,0) -> #N/A | N18: =VLOOKUP(C18,CC!$C$5:$BS$67,69,0) -> #N/A | O18: =VLOOKUP(C18,CC!$C$5:$BT$67,70,0) -> #N/A | P18: =VLOOKUP(C18,CC!$C$5:$AM$67,37,0) -> #N/A | Q18: =((J18/26)*K18)+(M18*(J18/26))+((N18/8)*1.5*(J18/26))+((O18/8)*2*J18/26)+(P18*3*(J18/26)) -> #N/A | R18: =VLOOKUP(C18,'Công tổng'!$C$53:$BY$67,66,0)-L18 -> #N/A | S18: =IF((F18-$S$3)>0,F18%*J18,0) -> 262150 | T18: =(100%-SUMIF('chuyên cần'!$C$6:$AP$31,'Bang luong'!C18,'chuyên cần'!$AP$7:$AP$31))*$T$3 -> 300000 | U18: 500000 | V18: 500000 | X18: 200000 | Y18: =Q18+R18+S18+T18+U18+V18+W18+X18 -> #N/A | Z18: ='ung luong'!F127 -> 0 | AA18: =AF18*$AA$2 -> 351750 | AB18: =Y18-Z18-AA18 -> #N/A | AC18: =ROUND(AB18,-3) -> #N/A | AF18: 3350000
A19: 11 | B19: NV54 | C19: Đào Công Thắng | D19: QL xe cơ giới | E19: 41611 | F19: =IF(E19=0,0,INT((NOW()-E19)/365)) -> 5 | G19: =$G$3 -> 3745000 | H19: D.04 | I19: 3 | J19: =SUMIFS(Sheet2!$C$1:$C$81,Sheet2!$A$1:$A$81,'Bang luong'!H19,Sheet2!$B$1:$B$81,'Bang luong'!I19)*1000 -> 7115500 | K19: =VLOOKUP(C19,CC!$C$5:$AJ$67,34,0) -> #N/A | L19: =J19/26*K19 -> #N/A | M19: =VLOOKUP(C19,CC!$C$5:$AM$67,36,0) -> #N/A | N19: =VLOOKUP(C19,CC!$C$5:$BS$67,69,0) -> #N/A | O19: =VLOOKUP(C19,CC!$C$5:$BT$67,70,0) -> #N/A | P19: =VLOOKUP(C19,CC!$C$5:$AM$67,37,0) -> #N/A | Q19: =((J19/26)*K19)+(M19*(J19/26))+((N19/8)*1.5*(J19/26))+((O19/8)*2*J19/26)+(P19*3*(J19/26)) -> #N/A | S19: =IF((F19-$S$3)>0,F19%*J19,0) -> 355775 | Y19: =Q19+R19+S19+T19+U19+V19+W19+X19 -> #N/A | Z19: ='ung luong'!#REF! -> #REF! | AA19: =AF19*$AA$2 -> 351750 | AB19: =Y19-Z19-AA19 -> #N/A | AC19: =ROUND(AB19,-3) -> #N/A | AF19: 3350000
A20: 12 | B20: NV56 | C20: Chung Văn Hiệp | D20: Lái xe cơ giới | E20: 41739 | F20: =IF(E20=0,0,INT((NOW()-E20)/365)) -> 5 | G20: =$G$3 -> 3745000 | H20: D.06 | I20: 1 | J20: =SUMIFS(Sheet2!$C$1:$C$81,Sheet2!$A$1:$A$81,'Bang luong'!H20,Sheet2!$B$1:$B$81,'Bang luong'!I20)*1000 -> 3745000 | K20: =VLOOKUP(C20,CC!$C$5:$AJ$67,34,0) -> #N/A | L20: =J20/26*K20 -> #N/A | M20: =VLOOKUP(C20,CC!$C$5:$AM$67,36,0) -> #N/A | N20: =VLOOKUP(C20,CC!$C$5:$BS$67,69,0) -> #N/A | O20: =VLOOKUP(C20,CC!$C$5:$BT$67,70,0) -> #N/A | P20: =VLOOKUP(C20,CC!$C$5:$AM$67,37,0) -> #N/A | Q20: =((J20/26)*K20)+(M20*(J20/26))+((N20/8)*1.5*(J20/26))+((O20/8)*2*J20/26)+(P20*3*(J20/26)) -> #N/A | R20: =VLOOKUP(C20,'Công tổng'!$C$53:$BY$67,66,0)-L20 -> #N/A | S20: =IF((F20-$S$3)>0,F20%*J20,0) -> 187250 | T20: =(100%-SUMIF('chuyên cần'!$C$6:$AP$31,'Bang luong'!C20,'chuyên cần'!$AP$7:$AP$31))*$T$3 -> 300000 | Y20: =Q20+R20+S20+T20+U20+V20+W20+X20 -> #N/A | Z20: ='ung luong'!#REF! -> #REF! | AA20: =AF20*$AA$2 -> 351750 | AB20: =Y20-Z20-AA20 -> #N/A | AC20: =ROUND(AB20,-3) -> #N/A | AF20: 3350000
A21: 13 | B21: NV57 | C21: Lê Tấn Phát | D21: Lái xe cơ giới | E21: 37257 | F21: =IF(E21=0,0,INT((NOW()-E21)/365)) -> 17 | G21: =$G$3 -> 3745000 | H21: D.06 | I21: 2 | J21: =SUMIFS(Sheet2!$C$1:$C$81,Sheet2!$A$1:$A$81,'Bang luong'!H21,Sheet2!$B$1:$B$81,'Bang luong'!I21)*1000 -> 4119500 | K21: =VLOOKUP(C21,CC!$C$5:$AJ$67,34,0) -> 27 | L21: =J21/26*K21 -> 4277942.3 | M21: =VLOOKUP(C21,CC!$C$5:$AM$67,36,0) -> 0 | N21: =VLOOKUP(C21,CC!$C$5:$BS$67,69,0) -> 0 | O21: =VLOOKUP(C21,CC!$C$5:$BT$67,70,0) -> 0 | P21: =VLOOKUP(C21,CC!$C$5:$AM$67,37,0) -> 0 | Q21: =((J21/26)*K21)+(M21*(J21/26))+((N21/8)*1.5*(J21/26))+((O21/8)*2*J21/26)+(P21*3*(J21/26)) -> 4277942.3 | R21: =VLOOKUP(C21,'Công tổng'!$C$53:$BY$67,66,0)-L21 -> #N/A | S21: =IF((F21-$S$3)>0,F21%*J21,0) -> 700315 | T21: =(100%-SUMIF('chuyên cần'!$C$6:$AP$31,'Bang luong'!C21,'chuyên cần'!$AP$7:$AP$31))*$T$3 -> 300000 | Y21: =Q21+R21+S21+T21+U21+V21+W21+X21 -> #N/A | Z21: ='ung luong'!#REF! -> #REF! | AA21: =AF21*$AA$2 -> 351750 | AB21: =Y21-Z21-AA21 -> #N/A | AC21: =ROUND(AB21,-3) -> #N/A | AF21: 3350000
A22: 14 | B22: NV58 | C22: Triệu Minh Tú | D22: Lái xe cơ giới | E22: 37622 | F22: =IF(E22=0,0,INT((NOW()-E22)/365)) -> 16 | G22: =$G$3 -> 3745000 | H22: D.06 | I22: 2 | J22: =SUMIFS(Sheet2!$C$1:$C$81,Sheet2!$A$1:$A$81,'Bang luong'!H22,Sheet2!$B$1:$B$81,'Bang luong'!I22)*1000 -> 4119500 | K22: =VLOOKUP(C22,CC!$C$5:$AJ$67,34,0) -> #N/A | L22: =J22/26*K22 -> #N/A | M22: =VLOOKUP(C22,CC!$C$5:$AM$67,36,0) -> #N/A | N22: =VLOOKUP(C22,CC!$C$5:$BS$67,69,0) -> #N/A | O22: =VLOOKUP(C22,CC!$C$5:$BT$67,70,0) -> #N/A | P22: =VLOOKUP(C22,CC!$C$5:$AM$67,37,0) -> #N/A | Q22: =((J22/26)*K22)+(M22*(J22/26))+((N22/8)*1.5*(J22/26))+((O22/8)*2*J22/26)+(P22*3*(J22/26)) -> #N/A | R22: =VLOOKUP(C22,'Công tổng'!$C$53:$BY$67,66,0)-L22 -> #N/A | S22: =IF((F22-$S$3)>0,F22%*J22,0) -> 659120 | T22: =(100%-SUMIF('chuyên cần'!$C$6:$AP$31,'Bang luong'!C22,'chuyên cần'!$AP$7:$AP$31))*$T$3 -> 300000 | Y22: =Q22+R22+S22+T22+U22+V22+W22+X22 -> #N/A | Z22: ='ung luong'!F82 -> 3000000 | AA22: =AF22*$AA$2 -> 351750 | AB22: =Y22-Z22-AA22 -> #N/A | AC22: =ROUND(AB22,-3) -> #N/A | AF22: 3350000
A23: 15 | B23: NV59 | C23: Triệu Minh Thắng | D23: Lái xe cơ giới | E23: 40596 | F23: =IF(E23=0,0,INT((NOW()-E23)/365)) -> 8 | G23: =$G$3 -> 3745000 | H23: D.06 | I23: 1 | J23: =SUMIFS(Sheet2!$C$1:$C$81,Sheet2!$A$1:$A$81,'Bang luong'!H23,Sheet2!$B$1:$B$81,'Bang luong'!I23)*1000 -> 3745000 | K23: =VLOOKUP(C23,CC!$C$5:$AJ$67,34,0) -> #N/A | L23: =J23/26*K23 -> #N/A | M23: =VLOOKUP(C23,CC!$C$5:$AM$67,36,0) -> #N/A | N23: =VLOOKUP(C23,CC!$C$5:$BS$67,69,0) -> #N/A | O23: =VLOOKUP(C23,CC!$C$5:$BT$67,70,0) -> #N/A | P23: =VLOOKUP(C23,CC!$C$5:$AM$67,37,0) -> #N/A | Q23: =((J23/26)*K23)+(M23*(J23/26))+((N23/8)*1.5*(J23/26))+((O23/8)*2*J23/26)+(P23*3*(J23/26)) -> #N/A | R23: =VLOOKUP(C23,'Công tổng'!$C$53:$BY$67,66,0)-L23 -> #N/A | S23: =IF((F23-$S$3)>0,F23%*J23,0) -> 299600 | T23: =(100%-SUMIF('chuyên cần'!$C$6:$AP$31,'Bang luong'!C23,'chuyên cần'!$AP$7:$AP$31))*$T$3 -> 300000 | Y23: =Q23+R23+S23+T23+U23+V23+W23+X23 -> #N/A | Z23: ='ung luong'!#REF! -> #REF! | AA23: =AF23*$AA$2 -> 348285 | AB23: =Y23-Z23-AA23 -> #N/A | AC23: =ROUND(AB23,-3) -> #N/A | AF23: 3317000
A24: 16 | B24: NV60 | C24: Thạch Giàu | D24: Lái xe cơ giới | E24: 41321 | F24: =IF(E24=0,0,INT((NOW()-E24)/365)) -> 6 | G24: =$G$3 -> 3745000 | H24: D.06 | I24: 1 | J24: =SUMIFS(Sheet2!$C$1:$C$81,Sheet2!$A$1:$A$81,'Bang luong'!H24,Sheet2!$B$1:$B$81,'Bang luong'!I24)*1000 -> 3745000 | K24: =VLOOKUP(C24,CC!$C$5:$AJ$67,34,0) -> 27 | L24: =J24/26*K24 -> 3889038.5 | M24: =VLOOKUP(C24,CC!$C$5:$AM$67,36,0) -> 0 | N24: =VLOOKUP(C24,CC!$C$5:$BS$67,69,0) -> 0 | O24: =VLOOKUP(C24,CC!$C$5:$BT$67,70,0) -> 0 | P24: =VLOOKUP(C24,CC!$C$5:$AM$67,37,0) -> 0 | Q24: =((J24/26)*K24)+(M24*(J24/26))+((N24/8)*1.5*(J24/26))+((O24/8)*2*J24/26)+(P24*3*(J24/26)) -> 3889038.5 | R24: =VLOOKUP(C24,'Công tổng'!$C$53:$BY$67,66,0)-L24 -> #N/A | S24: =IF((F24-$S$3)>0,F24%*J24,0) -> 224700 | T24: =(100%-SUMIF('chuyên cần'!$C$6:$AP$31,'Bang luong'!C24,'chuyên cần'!$AP$7:$AP$31))*$T$3 -> 300000 | Y24: =Q24+R24+S24+T24+U24+V24+W24+X24 -> #N/A | Z24: ='ung luong'!#REF! -> #REF! | AA24: 348000 | AB24: =Y24-Z24-AA24 -> #N/A | AC24: =ROUND(AB24,-3) -> #N/A | AF24: 3317000
A25: 17 | B25: NV61 | C25: Nguyễn Quốc Việt | D25: Lái xe cơ giới | E25: 41589 | F25: =IF(E25=0,0,INT((NOW()-E25)/365)) -> 5 | G25: =$G$3 -> 3745000 | H25: D.06 | I25: 1 | J25: =SUMIFS(Sheet2!$C$1:$C$81,Sheet2!$A$1:$A$81,'Bang luong'!H25,Sheet2!$B$1:$B$81,'Bang luong'!I25)*1000 -> 3745000 | K25: =VLOOKUP(C25,CC!$C$5:$AJ$67,34,0) -> #N/A | L25: =J25/26*K25 -> #N/A | M25: =VLOOKUP(C25,CC!$C$5:$AM$67,36,0) -> #N/A | N25: =VLOOKUP(C25,CC!$C$5:$BS$67,69,0) -> #N/A | O25: =VLOOKUP(C25,CC!$C$5:$BT$67,70,0) -> #N/A | P25: =VLOOKUP(C25,CC!$C$5:$AM$67,37,0) -> #N/A | Q25: =((J25/26)*K25)+(M25*(J25/26))+((N25/8)*1.5*(J25/26))+((O25/8)*2*J25/26)+(P25*3*(J25/26)) -> #N/A | R25: =VLOOKUP(C25,'Công tổng'!$C$53:$BY$67,66,0)-L25 -> #N/A | S25: =IF((F25-$S$3)>0,F25%*J25,0) -> 187250 | T25: =(100%-SUMIF('chuyên cần'!$C$6:$AP$31,'Bang luong'!C25,'chuyên cần'!$AP$7:$AP$31))*$T$3 -> 300000 | Y25: =Q25+R25+S25+T25+U25+V25+W25+X25 -> #N/A | Z25: ='ung luong'!#REF! -> #REF! | AA25: =AF25*$AA$2 -> 348285 | AB25: =Y25-Z25-AA25 -> #N/A | AC25: =ROUND(AB25,-3) -> #N/A | AF25: 3317000
A26: 18 | B26: NV62 | C26: Nguyễn Trọng Minh | D26: Lái xe cơ giới | E26: 38838 | F26: =IF(E26=0,0,INT((NOW()-E26)/365)) -> 13 | G26: =$G$3 -> 3745000 | H26: D.07 | I26: 4 | J26: =SUMIFS(Sheet2!$C$1:$C$81,Sheet2!$A$1:$A$81,'Bang luong'!H26,Sheet2!$B$1:$B$81,'Bang luong'!I26)*1000 -> 4868500 | K26: =VLOOKUP(C26,CC!$C$5:$AJ$67,34,0) -> 27 | L26: =J26/26*K26 -> 5055750 | M26: =VLOOKUP(C26,CC!$C$5:$AM$67,36,0) -> 0 | N26: =VLOOKUP(C26,CC!$C$5:$BS$67,69,0) -> 0 | O26: =VLOOKUP(C26,CC!$C$5:$BT$67,70,0) -> 0 | P26: =VLOOKUP(C26,CC!$C$5:$AM$67,37,0) -> 0 | Q26: =((J26/26)*K26)+(M26*(J26/26))+((N26/8)*1.5*(J26/26))+((O26/8)*2*J26/26)+(P26*3*(J26/26)) -> 5055750 | S26: =IF((F26-$S$3)>0,F26%*J26,0) -> 632905 | T26: =(100%-SUMIF('chuyên cần'!$C$6:$AP$31,'Bang luong'!C26,'chuyên cần'!$AP$7:$AP$31))*$T$3 -> 300000 | Y26: =Q26+R26+S26+T26+U26+V26+W26+X26 -> 5988655 | Z26: ='ung luong'!#REF! -> #REF! | AA26: =AF26*$AA$2 -> 351750 | AB26: =Y26-Z26-AA26 -> #REF! | AC26: =ROUND(AB26,-3) -> #REF! | AF26: 3350000
A27: 19 | B27: NV63 | C27: Trần Thanh Hậu | D27: Lái xe cơ giới | E27: 41852 | F27: =IF(E27=0,0,INT((NOW()-E27)/365)) -> 5 | G27: =$G$3 -> 3745000 | H27: D.06 | I27: 1 | J27: =SUMIFS(Sheet2!$C$1:$C$81,Sheet2!$A$1:$A$81,'Bang luong'!H27,Sheet2!$B$1:$B$81,'Bang luong'!I27)*1000 -> 3745000 | K27: =VLOOKUP(C27,CC!$C$5:$AJ$67,34,0) -> 27 | L27: =J27/26*K27 -> 3889038.5 | M27: =VLOOKUP(C27,CC!$C$5:$AM$67,36,0) -> 0 | N27: =VLOOKUP(C27,CC!$C$5:$BS$67,69,0) -> 0 | O27: =VLOOKUP(C27,CC!$C$5:$BT$67,70,0) -> 0 | P27: =VLOOKUP(C27,CC!$C$5:$AM$67,37,0) -> 0 | Q27: =((J27/26)*K27)+(M27*(J27/26))+((N27/8)*1.5*(J27/26))+((O27/8)*2*J27/26)+(P27*3*(J27/26)) -> 3889038.5 | R27: =VLOOKUP(C27,'Công tổng'!$C$53:$BY$67,66,0)-L27 -> #N/A | S27: =IF((F27-$S$3)>0,F27%*J27,0) -> 187250 | T27: =(100%-SUMIF('chuyên cần'!$C$6:$AP$31,'Bang luong'!C27,'chuyên cần'!$AP$7:$AP$31))*$T$3 -> 300000 | Y27: =Q27+R27+S27+T27+U27+V27+W27+X27 -> #N/A | Z27: ='ung luong'!F107 -> 4000000 | AA27: =AF27*$AA$2 -> 0 | AB27: =Y27-Z27-AA27 -> #N/A | AC27: =ROUND(AB27,-3) -> #N/A
A28: 20 | B28: NV64 | C28: Phan Văn Bạn | D28: Lái xe cơ giới | E28: 41640 | F28: =IF(E28=0,0,INT((NOW()-E28)/365)) -> 5 | G28: =$G$3 -> 3745000 | H28: D.06 | I28: 1 | J28: =SUMIFS(Sheet2!$C$1:$C$81,Sheet2!$A$1:$A$81,'Bang luong'!H28,Sheet2!$B$1:$B$81,'Bang luong'!I28)*1000 -> 3745000 | K28: =VLOOKUP(C28,CC!$C$5:$AJ$67,34,0) -> #N/A | L28: =J28/26*K28 -> #N/A | M28: =VLOOKUP(C28,CC!$C$5:$AM$67,36,0) -> #N/A | N28: =VLOOKUP(C28,CC!$C$5:$BS$67,69,0) -> #N/A | O28: =VLOOKUP(C28,CC!$C$5:$BT$67,70,0) -> #N/A | P28: =VLOOKUP(C28,CC!$C$5:$AM$67,37,0) -> #N/A | Q28: =((J28/26)*K28)+(M28*(J28/26))+((N28/8)*1.5*(J28/26))+((O28/8)*2*J28/26)+(P28*3*(J28/26)) -> #N/A | R28: =VLOOKUP(C28,'Công tổng'!$C$53:$BY$67,66,0)-L28 -> #N/A | S28: =IF((F28-$S$3)>0,F28%*J28,0) -> 187250 | T28: =(100%-SUMIF('chuyên cần'!$C$6:$AP$31,'Bang luong'!C28,'chuyên cần'!$AP$7:$AP$31))*$T$3 -> 300000 | Y28: =Q28+R28+S28+T28+U28+V28+W28+X28 -> #N/A | Z28: ='ung luong'!#REF! -> #REF! | AA28: =AF28*$AA$2 -> 0 | AB28: =Y28-Z28-AA28 -> #N/A | AC28: =ROUND(AB28,-3) -> #N/A
A29: 21 | B29: NV65 | C29: Châu Thành Nhân | D29: Lái xe cơ giới | E29: 41997 | F29: =IF(E29=0,0,INT((NOW()-E29)/365)) -> 4 | G29: =$G$3 -> 3745000 | H29: D.06 | I29: 1 | J29: =SUMIFS(Sheet2!$C$1:$C$81,Sheet2!$A$1:$A$81,'Bang luong'!H29,Sheet2!$B$1:$B$81,'Bang luong'!I29)*1000 -> 3745000 | K29: =VLOOKUP(C29,CC!$C$5:$AJ$67,34,0) -> 27 | L29: =J29/26*K29 -> 3889038.5 | M29: =VLOOKUP(C29,CC!$C$5:$AM$67,36,0) -> 0 | N29: =VLOOKUP(C29,CC!$C$5:$BS$67,69,0) -> 0 | O29: =VLOOKUP(C29,CC!$C$5:$BT$67,70,0) -> 0 | P29: =VLOOKUP(C29,CC!$C$5:$AM$67,37,0) -> 0 | Q29: =((J29/26)*K29)+(M29*(J29/26))+((N29/8)*1.5*(J29/26))+((O29/8)*2*J29/26)+(P29*3*(J29/26)) -> 3889038.5 | R29: =VLOOKUP(C29,'Công tổng'!$C$53:$BY$67,66,0)-L29 -> -3889038.5 | S29: =IF((F29-$S$3)>0,F29%*J29,0) -> 149800 | T29: =(100%-SUMIF('chuyên cần'!$C$6:$AP$31,'Bang luong'!C29,'chuyên cần'!$AP$7:$AP$31))*$T$3 -> 300000 | Y29: =Q29+R29+S29+T29+U29+V29+W29+X29 -> 449800 | Z29: ='ung luong'!F103 -> 0 | AA29: =AF29*$AA$2 -> 0 | AB29: =Y29-Z29-AA29 -> 449800 | AC29: =ROUND(AB29,-3) -> 450000
A30: 22 | B30: NV66 | C30: Nguyễn Văn Chạy | D30: Lái xe cơ giới | E30: 41786 | F30: =IF(E30=0,0,INT((NOW()-E30)/365)) -> 5 | G30: =$G$3 -> 3745000 | H30: D.09 | I30: 1 | J30: =SUMIFS(Sheet2!$C$1:$C$81,Sheet2!$A$1:$A$81,'Bang luong'!H30,Sheet2!$B$1:$B$81,'Bang luong'!I30)*1000 -> 3745000 | K30: =VLOOKUP(C30,CC!$C$5:$AJ$67,34,0) -> 27 | L30: =J30/26*K30 -> 3889038.5 | M30: =VLOOKUP(C30,CC!$C$5:$AM$67,36,0) -> 0 | N30: =VLOOKUP(C30,CC!$C$5:$BS$67,69,0) -> 0 | O30: =VLOOKUP(C30,CC!$C$5:$BT$67,70,0) -> 0 | P30: =VLOOKUP(C30,CC!$C$5:$AM$67,37,0) -> 0 | Q30: =((J30/26)*K30)+(M30*(J30/26))+((N30/8)*1.5*(J30/26))+((O30/8)*2*J30/26)+(P30*3*(J30/26)) -> 3889038.5 | R30: =VLOOKUP(C30,'Công tổng'!$C$53:$BY$67,66,0)-L30 -> -3889038.5 | S30: =IF((F30-$S$3)>0,F30%*J30,0) -> 187250 | T30: =(100%-SUMIF('chuyên cần'!$C$6:$AP$31,'Bang luong'!C30,'chuyên cần'!$AP$7:$AP$31))*$T$3 -> 300000 | Y30: =Q30+R30+S30+T30+U30+V30+W30+X30 -> 487250 | Z30: ='ung luong'!F99 -> 4000000 | AA30: =AF30*$AA$2 -> 0 | AB30: =Y30-Z30-AA30 -> -3512750 | AC30: =ROUND(AB30,-3) -> -3513000
A31: 23 | B31: NV67 | C31: Hà Hoàng Hùng | D31: Lái xe cơ giới | E31: 41876 | F31: =IF(E31=0,0,INT((NOW()-E31)/365)) -> 5 | G31: =$G$3 -> 3745000 | H31: D.09 | I31: 1 | J31: =SUMIFS(Sheet2!$C$1:$C$81,Sheet2!$A$1:$A$81,'Bang luong'!H31,Sheet2!$B$1:$B$81,'Bang luong'!I31)*1000 -> 3745000 | K31: =VLOOKUP(C31,CC!$C$5:$AJ$67,34,0) -> 27 | L31: =J31/26*K31 -> 3889038.5 | M31: =VLOOKUP(C31,CC!$C$5:$AM$67,36,0) -> 0 | N31: =VLOOKUP(C31,CC!$C$5:$BS$67,69,0) -> 0 | O31: =VLOOKUP(C31,CC!$C$5:$BT$67,70,0) -> 0 | P31: =VLOOKUP(C31,CC!$C$5:$AM$67,37,0) -> 0 | Q31: =((J31/26)*K31)+(M31*(J31/26))+((N31/8)*1.5*(J31/26))+((O31/8)*2*J31/26)+(P31*3*(J31/26)) -> 3889038.5 | R31: =VLOOKUP(C31,'Công tổng'!$C$53:$BY$67,66,0)-L31 -> -3889038.5 | S31: =IF((F31-$S$3)>0,F31%*J31,0) -> 187250 | T31: =(100%-SUMIF('chuyên cần'!$C$6:$AP$31,'Bang luong'!C31,'chuyên cần'!$AP$7:$AP$31))*$T$3 -> 300000 | Y31: =Q31+R31+S31+T31+U31+V31+W31+X31 -> 487250 | Z31: ='ung luong'!F100 -> 3500000 | AA31: =AF31*$AA$2 -> 0 | AB31: =Y31-Z31-AA31 -> -3012750 | AC31: =ROUND(AB31,-3) -> -3013000
A32: 24 | B32: NV68 | C32: Nguyễn Thanh Nhàn | D32: Lái xe cơ giới | E32: 42201 | F32: =IF(E32=0,0,INT((NOW()-E32)/365)) -> 4 | G32: =$G$3 -> 3745000 | H32: D.09 | I32: 1 | J32: =SUMIFS(Sheet2!$C$1:$C$81,Sheet2!$A$1:$A$81,'Bang luong'!H32,Sheet2!$B$1:$B$81,'Bang luong'!I32)*1000 -> 3745000 | K32: =VLOOKUP(C32,CC!$C$5:$AJ$67,34,0) -> #N/A | L32: =J32/26*K32 -> #N/A | M32: =VLOOKUP(C32,CC!$C$5:$AM$67,36,0) -> #N/A | N32: =VLOOKUP(C32,CC!$C$5:$BS$67,69,0) -> #N/A | O32: =VLOOKUP(C32,CC!$C$5:$BT$67,70,0) -> #N/A | P32: =VLOOKUP(C32,CC!$C$5:$AM$67,37,0) -> #N/A | Q32: =((J32/26)*K32)+(M32*(J32/26))+((N32/8)*1.5*(J32/26))+((O32/8)*2*J32/26)+(P32*3*(J32/26)) -> #N/A | R32: =VLOOKUP(C32,'Công tổng'!$C$53:$BY$67,66,0)-L32 -> #N/A | S32: =IF((F32-$S$3)>0,F32%*J32,0) -> 149800 | T32: =(100%-SUMIF('chuyên cần'!$C$6:$AP$31,'Bang luong'!C32,'chuyên cần'!$AP$7:$AP$31))*$T$3 -> 300000 | Y32: =Q32+R32+S32+T32+U32+V32+W32+X32 -> #N/A | Z32: ='ung luong'!#REF! -> #REF! | AA32: =AF32*$AA$2 -> 0 | AB32: =Y32-Z32-AA32 -> #N/A | AC32: =ROUND(AB32,-3) -> #N/A
Y33: =SUM(Y34:Y49) -> #N/A | Z33: =SUM(Z34:Z49) -> #REF! | AA33: =SUM(AA34:AA49) -> 1393140 | AB33: =SUM(AB34:AB49) -> #N/A | AC33: =SUM(AC34:AC49) -> #N/A
A34: 25 | B34: NV69 | C34: Lâm Ban | D34: Công nhân | E34: 40462 | F34: =IF(E34=0,0,INT((NOW()-E34)/365)) -> 8 | G34: =$G$3 -> 3745000 | H34: D.09 | I34: 1 | J34: =SUMIFS(Sheet2!$C$1:$C$81,Sheet2!$A$1:$A$81,'Bang luong'!H34,Sheet2!$B$1:$B$81,'Bang luong'!I34)*1000 -> 3745000 | K34: =VLOOKUP(C34,CC!$C$5:$AJ$67,34,0) -> #N/A | L34: =J34/26*K34 -> #N/A | M34: =VLOOKUP(C34,CC!$C$5:$AM$67,36,0) -> #N/A | N34: =VLOOKUP(C34,CC!$C$5:$BS$67,69,0) -> #N/A | O34: =VLOOKUP(C34,CC!$C$5:$BT$67,70,0) -> #N/A | P34: =VLOOKUP(C34,CC!$C$5:$AM$67,37,0) -> #N/A | Q34: =((J34/26)*K34)+(M34*(J34/26))+((N34/8)*1.5*(J34/26))+((O34/8)*2*J34/26)+(P34*3*(J34/26)) -> #N/A | R34: =VLOOKUP(C34,'Công tổng'!$C$53:$BY$67,66,0)-L34 -> #N/A | S34: =IF((F34-$S$3)>0,F34%*J34,0) -> 299600 | T34: =(100%-SUMIF('chuyên cần'!$C$6:$AP$31,'Bang luong'!C34,'chuyên cần'!$AP$7:$AP$31))*$T$3 -> 300000 | Y34: =Q34+R34+S34+T34+U34+V34+W34+X34 -> #N/A | Z34: ='ung luong'!#REF! -> #REF! | AA34: =AF34*$AA$2 -> 348285 | AB34: =Y34-Z34-AA34 -> #N/A | AC34: =ROUND(AB34,-3) -> #N/A | AF34: 3317000
A35: 26 | B35: NV70 | C35: Ngô Văn Thanh | D35: Công nhân | E35: 40596 | F35: =IF(E35=0,0,INT((NOW()-E35)/365)) -> 8 | G35: =$G$3 -> 3745000 | H35: D.09 | I35: 1 | J35: =SUMIFS(Sheet2!$C$1:$C$81,Sheet2!$A$1:$A$81,'Bang luong'!H35,Sheet2!$B$1:$B$81,'Bang luong'!I35)*1000 -> 3745000 | K35: =VLOOKUP(C35,CC!$C$5:$AJ$67,34,0) -> #N/A | L35: =J35/26*K35 -> #N/A | M35: =VLOOKUP(C35,CC!$C$5:$AM$67,36,0) -> #N/A | N35: =VLOOKUP(C35,CC!$C$5:$BS$67,69,0) -> #N/A | O35: =VLOOKUP(C35,CC!$C$5:$BT$67,70,0) -> #N/A | P35: =VLOOKUP(C35,CC!$C$5:$AM$67,37,0) -> #N/A | Q35: =((J35/26)*K35)+(M35*(J35/26))+((N35/8)*1.5*(J35/26))+((O35/8)*2*J35/26)+(P35*3*(J35/26)) -> #N/A | R35: =VLOOKUP(C35,'Công tổng'!$C$53:$BY$67,66,0)-L35 -> #N/A | S35: =IF((F35-$S$3)>0,F35%*J35,0) -> 299600 | T35: =(100%-SUMIF('chuyên cần'!$C$6:$AP$31,'Bang luong'!C35,'chuyên cần'!$AP$7:$AP$31))*$T$3 -> 300000 | Y35: =Q35+R35+S35+T35+U35+V35+W35+X35 -> #N/A | Z35: ='ung luong'!#REF! -> #REF! | AA35: =AF35*$AA$2 -> 348285 | AB35: =Y35-Z35-AA35 -> #N/A | AC35: =ROUND(AB35,-3) -> #N/A | AF35: 3317000
A36: 27 | B36: NV71 | C36: Triệu Quốc Minh | D36: Công nhân | E36: 41682 | F36: =IF(E36=0,0,INT((NOW()-E36)/365)) -> 5 | G36: =$G$3 -> 3745000 | H36: D.09 | I36: 1 | J36: =SUMIFS(Sheet2!$C$1:$C$81,Sheet2!$A$1:$A$81,'Bang luong'!H36,Sheet2!$B$1:$B$81,'Bang luong'!I36)*1000 -> 3745000 | K36: =VLOOKUP(C36,CC!$C$5:$AJ$67,34,0) -> #N/A | L36: =J36/26*K36 -> #N/A | M36: =VLOOKUP(C36,CC!$C$5:$AM$67,36,0) -> #N/A | N36: =VLOOKUP(C36,CC!$C$5:$BS$67,69,0) -> #N/A | O36: =VLOOKUP(C36,CC!$C$5:$BT$67,70,0) -> #N/A | P36: =VLOOKUP(C36,CC!$C$5:$AM$67,37,0) -> #N/A | Q36: =((J36/26)*K36)+(M36*(J36/26))+((N36/8)*1.5*(J36/26))+((O36/8)*2*J36/26)+(P36*3*(J36/26)) -> #N/A | R36: =VLOOKUP(C36,'Công tổng'!$C$53:$BY$67,66,0)-L36 -> #N/A | S36: =IF((F36-$S$3)>0,F36%*J36,0) -> 187250 | T36: =(100%-SUMIF('chuyên cần'!$C$6:$AP$31,'Bang luong'!C36,'chuyên cần'!$AP$7:$AP$31))*$T$3 -> 300000 | Y36: =Q36+R36+S36+T36+U36+V36+W36+X36 -> #N/A | Z36: ='ung luong'!#REF! -> #REF! | AA36: =AF36*$AA$2 -> 0 | AB36: =Y36-Z36-AA36 -> #N/A | AC36: =ROUND(AB36,-3) -> #N/A
A37: 28 | B37: NV72 | C37: Triệu Minh Tuấn | D37: Công nhân | E37: 41706 | F37: =IF(E37=0,0,INT((NOW()-E37)/365)) -> 5 | G37: =$G$3 -> 3745000 | H37: D.09 | I37: 1 | J37: =SUMIFS(Sheet2!$C$1:$C$81,Sheet2!$A$1:$A$81,'Bang luong'!H37,Sheet2!$B$1:$B$81,'Bang luong'!I37)*1000 -> 3745000 | K37: =VLOOKUP(C37,CC!$C$5:$AJ$67,34,0) -> 27 | L37: =J37/26*K37 -> 3889038.5 | M37: =VLOOKUP(C37,CC!$C$5:$AM$67,36,0) -> 0 | N37: =VLOOKUP(C37,CC!$C$5:$BS$67,69,0) -> 0 | O37: =VLOOKUP(C37,CC!$C$5:$BT$67,70,0) -> 0 | P37: =VLOOKUP(C37,CC!$C$5:$AM$67,37,0) -> 0 | Q37: =((J37/26)*K37)+(M37*(J37/26))+((N37/8)*1.5*(J37/26))+((O37/8)*2*J37/26)+(P37*3*(J37/26)) -> 3889038.5 | R37: =VLOOKUP(C37,'Công tổng'!$C$53:$BY$67,66,0)-L37 -> #N/A | S37: =IF((F37-$S$3)>0,F37%*J37,0) -> 187250 | T37: =(100%-SUMIF('chuyên cần'!$C$6:$AP$31,'Bang luong'!C37,'chuyên cần'!$AP$7:$AP$31))*$T$3 -> 300000 | Y37: =Q37+R37+S37+T37+U37+V37+W37+X37 -> #N/A | Z37: ='ung luong'!F125 -> 3000000 | AA37: =AF37*$AA$2 -> 0 | AB37: =Y37-Z37-AA37 -> #N/A | AC37: =ROUND(AB37,-3) -> #N/A
A38: 29 | B38: NV73 | C38: Nguyễn Văn Phụng | D38: Công nhân | E38: 41786 | F38: =IF(E38=0,0,INT((NOW()-E38)/365)) -> 5 | G38: =$G$3 -> 3745000 | H38: D.09 | I38: 1 | J38: =SUMIFS(Sheet2!$C$1:$C$81,Sheet2!$A$1:$A$81,'Bang luong'!H38,Sheet2!$B$1:$B$81,'Bang luong'!I38)*1000 -> 3745000 | K38: =VLOOKUP(C38,CC!$C$5:$AJ$67,34,0) -> 27 | L38: =J38/26*K38 -> 3889038.5 | M38: =VLOOKUP(C38,CC!$C$5:$AM$67,36,0) -> 0.5 | N38: =VLOOKUP(C38,CC!$C$5:$BS$67,69,0) -> 0 | O38: =VLOOKUP(C38,CC!$C$5:$BT$67,70,0) -> 0 | P38: =VLOOKUP(C38,CC!$C$5:$AM$67,37,0) -> 0 | Q38: =((J38/26)*K38)+(M38*(J38/26))+((N38/8)*1.5*(J38/26))+((O38/8)*2*J38/26)+(P38*3*(J38/26)) -> 3961057.7 | R38: =VLOOKUP(C38,'Công tổng'!$C$53:$BY$67,66,0)-L38 -> #N/A | S38: =IF((F38-$S$3)>0,F38%*J38,0) -> 187250 | T38: =(100%-SUMIF('chuyên cần'!$C$6:$AP$31,'Bang luong'!C38,'chuyên cần'!$AP$7:$AP$31))*$T$3 -> 300000 | Y38: =Q38+R38+S38+T38+U38+V38+W38+X38 -> #N/A | Z38: ='ung luong'!#REF! -> #REF! | AA38: =AF38*$AA$2 -> 0 | AB38: =Y38-Z38-AA38 -> #N/A | AC38: =ROUND(AB38,-3) -> #N/A
A39: 30 | B39: NV74 | C39: Nguyễn Văn Lâm | D39: Công nhân | E39: 41956 | F39: =IF(E39=0,0,INT((NOW()-E39)/365)) -> 4 | G39: =$G$3 -> 3745000 | H39: D.09 | I39: 1 | J39: =SUMIFS(Sheet2!$C$1:$C$81,Sheet2!$A$1:$A$81,'Bang luong'!H39,Sheet2!$B$1:$B$81,'Bang luong'!I39)*1000 -> 3745000 | K39: =VLOOKUP(C39,CC!$C$5:$AJ$67,34,0) -> #N/A | L39: =J39/26*K39 -> #N/A | M39: =VLOOKUP(C39,CC!$C$5:$AM$67,36,0) -> #N/A | N39: =VLOOKUP(C39,CC!$C$5:$BS$67,69,0) -> #N/A | O39: =VLOOKUP(C39,CC!$C$5:$BT$67,70,0) -> #N/A | P39: =VLOOKUP(C39,CC!$C$5:$AM$67,37,0) -> #N/A | Q39: =((J39/26)*K39)+(M39*(J39/26))+((N39/8)*1.5*(J39/26))+((O39/8)*2*J39/26)+(P39*3*(J39/26)) -> #N/A | R39: =VLOOKUP(C39,'Công tổng'!$C$53:$BY$67,66,0)-L39 -> #N/A | S39: =IF((F39-$S$3)>0,F39%*J39,0) -> 149800 | T39: =(100%-SUMIF('chuyên cần'!$C$6:$AP$31,'Bang luong'!C39,'chuyên cần'!$AP$7:$AP$31))*$T$3 -> 300000 | Y39: =Q39+R39+S39+T39+U39+V39+W39+X39 -> #N/A | Z39: ='ung luong'!#REF! -> #REF! | AA39: =AF39*$AA$2 -> 0 | AB39: =Y39-Z39-AA39 -> #N/A | AC39: =ROUND(AB39,-3) -> #N/A
A40: 31 | B40: NV75 | C40: Nguyễn Minh Tuấn | D40: Công nhân | E40: 41967 | F40: =IF(E40=0,0,INT((NOW()-E40)/365)) -> 4 | G40: =$G$3 -> 3745000 | H40: D.09 | I40: 1 | J40: =SUMIFS(Sheet2!$C$1:$C$81,Sheet2!$A$1:$A$81,'Bang luong'!H40,Sheet2!$B$1:$B$81,'Bang luong'!I40)*1000 -> 3745000 | K40: =VLOOKUP(C40,CC!$C$5:$AJ$67,34,0) -> 27 | L40: =J40/26*K40 -> 3889038.5 | M40: =VLOOKUP(C40,CC!$C$5:$AM$67,36,0) -> 0 | N40: =VLOOKUP(C40,CC!$C$5:$BS$67,69,0) -> 0 | O40: =VLOOKUP(C40,CC!$C$5:$BT$67,70,0) -> 0 | P40: =VLOOKUP(C40,CC!$C$5:$AM$67,37,0) -> 0 | Q40: =((J40/26)*K40)+(M40*(J40/26))+((N40/8)*1.5*(J40/26))+((O40/8)*2*J40/26)+(P40*3*(J40/26)) -> 3889038.5 | R40: =VLOOKUP(C40,'Công tổng'!$C$53:$BY$67,66,0)-L40 -> -3889038.5 | S40: =IF((F40-$S$3)>0,F40%*J40,0) -> 149800 | T40: =(100%-SUMIF('chuyên cần'!$C$6:$AP$31,'Bang luong'!C40,'chuyên cần'!$AP$7:$AP$31))*$T$3 -> 300000 | Y40: =Q40+R40+S40+T40+U40+V40+W40+X40 -> 449800 | Z40: ='ung luong'!F91 -> 3000000 | AA40: =AF40*$AA$2 -> 0 | AB40: =Y40-Z40-AA40 -> -2550200 | AC40: =ROUND(AB40,-3) -> -2550000
...

Sheet he so
C1: SỐ THÁNG | D1: HỆ SỐ
C2: 0 | D2: 0 | E2: 0.01 | F2: 3 năm đầu ko tăng, bắt đầu năm thứ 4 sẽ có thâm niên 3%, thêm 1 năm tăng 1%
C3: 1 | D3: 0
C4: 2 | D4: 0
C5: 3 | D5: 0
C6: 4 | D6: 0
C7: 5 | D7: 0
C8: 6 | D8: 0
C9: 7 | D9: 0
C10: 8 | D10: 0
C11: 9 | D11: 0
C12: 10 | D12: 0
C13: 11 | D13: 0
C14: 12 | D14: 0
B15: =+C15 -> 13 | C15: 13 | D15: 0
C16: 14 | D16: 0
C17: 15 | D17: 0
C18: 16 | D18: 0
C19: 17 | D19: 0
C20: 18 | D20: 0
C21: 19 | D21: 0
C22: 20 | D22: 0
C23: 21 | D23: 0
C24: 22 | D24: 0
C25: 23 | D25: 0
C26: 24 | D26: 0
B27: =B15+12 -> 25 | C27: 25 | D27: 0
C28: 26 | D28: 0
C29: 27 | D29: 0
C30: 28 | D30: 0
C31: 29 | D31: 0
C32: 30 | D32: 0
C33: 31 | D33: 0
C34: 32 | D34: 0
C35: 33 | D35: 0
C36: 34 | D36: 0
C37: 35 | D37: 0
C38: 36 | D38: 0
B39: =B27+12 -> 37 | C39: 37 | D39: 0.03
C40: 38 | D40: =$D$39 -> 0.03
...

Sheet the luong
A2: THẺ LƯƠNG | B2: ='BANG LUONG 1'!$P$2 -> 43702
A3: Mã Nhân viên | B3: NV43 | C3: 1
A4: Họ và Tên | B4: =VLOOKUP($B3,'BANG LUONG 1'!$B$5:$AB$53,C4,0) -> Triệu Minh Tuấn | C4: 2
A5: Chức vụ | B5: =VLOOKUP($B3,'BANG LUONG 1'!$B$5:$AJ$53,C5,0) -> Công nhân | C5: 3
A6: Ngày vào làm việc | B6: =VLOOKUP($B3,'BANG LUONG 1'!$B$4:$AJ$55,4,0) -> 41706 | C6: 4
A7: % thâm niên | B7: =VLOOKUP(B3,'BANG LUONG 1'!$B$4:$AJ$55,6,0) -> 0.05 | C7: 5
A8: Lương tối thiểu | B8: ='thang luong moi'!$F$5 -> 4012500 | C8: 6
A9: Ngạch lương | B9: =VLOOKUP(B3,'BANG LUONG 1'!$B$4:$AJ$55,8,0) -> B.05 | C9: 7
A10: hệ số lương | B10: =VLOOKUP(B3,'BANG LUONG 1'!$B$4:$AJ$55,9,0) -> 1 | C10: 8
A11: lương CB hệ số | B11: =VLOOKUP(B3,'BANG LUONG 1'!$B$4:$AJ$55,11,0) -> 4213125 | C11: 9
A12: Ngày công lv | B12: =VLOOKUP(B3,'BANG LUONG 1'!$B$4:$AJ$55,12,0) -> 27 | C12: 10
A13: Lương Định mức | B13: =VLOOKUP(B3,'BANG LUONG 1'!$B$4:$AJ$55,13,0) -> 4375168.3 | C13: 11
A14: Ngày phép năm | B14: =VLOOKUP(B3,'BANG LUONG 1'!$B$4:$AJ$55,14,0) -> 0 | C14: 12 | D14: =B11/26*B14 -> 0
A15: Giờ tăng ca | B15: =VLOOKUP(B3,'BANG LUONG 1'!$B$4:$AJ$55,15,0) -> 0 | C15: 13 | D15: =B11/26/8*1.5*B15 -> 0
A16: Giờ làm việc CN | B16: =VLOOKUP(B3,'BANG LUONG 1'!$B$4:$AJ$55,16,0) -> 0 | C16: 14 | D16: =B11/26/8*2*B16 -> 0
A17: Ngày nghỉ lễ tết | B17: =VLOOKUP(B3,'BANG LUONG 1'!$B$4:$AJ$55,17,0) -> 0 | D17: =(B11/26)*B17 -> 0
A18: Ngày LV lễ tết | B18: =VLOOKUP(B3,'BANG LUONG 1'!$B$4:$AJ$55,18,0) -> 0 | C18: 15 | D18: =(B11/26*B18)*3 -> 0
A19: Thành tiền lương CB | B19: =VLOOKUP(B3,'BANG LUONG 1'!$B$4:$AJ$55,19,0) -> 4375168.3 | C19: 16 | D19: =B13+D15+D16+D14+D18+D17 -> 4375168.3
A20: lương vượt định mức | B20: =VLOOKUP(B3,'BANG LUONG 1'!$B$4:$AJ$55,20,0) -> -4375168.3 | C20: 17
A21: Phụ Cấp thâm niên | B21: =VLOOKUP(B3,'BANG LUONG 1'!$B$4:$AJ$55,22,0) -> 210656.25 | C21: 18
A22: Phụ cấp chuyên cần | B22: =VLOOKUP(B3,'BANG LUONG 1'!$B$4:$AJ$55,23,0) -> 300000 | C22: 19
A23: Phụ Cấp | B23: =VLOOKUP(B3,'BANG LUONG 1'!$B$4:$AJ$55,24,0) -> 0 | C23: 22
A24: Tổng thu nhập | B24: =VLOOKUP(B3,'BANG LUONG 1'!$B$4:$AJ$55,26,0) -> 510656.25 | C24: 24
A25: Trừ tạm ứng | B25: =VLOOKUP(B3,'BANG LUONG 1'!$B$4:$AJ$55,27,0) -> 3000000 | C25: 25
A26: Trừ BHXH | B26: =VLOOKUP(B3,'BANG LUONG 1'!$B$4:$AJ$55,28,0) -> 480585 | C26: 26
A27: Tiền cơm (KD ) | B27: =VLOOKUP(B3,'BANG LUONG 1'!$B$4:$AJ$55,32,0) -> 0
A28: Tiền cơm (SX) | B28: =VLOOKUP(B3,'BANG LUONG 1'!$B$4:$AJ$55,33,0) -> 0
A29: Cộng tiền trừ nhầm tháng trước | B29: =VLOOKUP(B3,'BANG LUONG 1'!$B$4:$AJ$55,34,0) -> 0 | E29: =B4 -> Triệu Minh Tuấn
A30: Thực lãnh | B30: =VLOOKUP(B3,'BANG LUONG 1'!$B$4:$AJ$55,35,0) -> -2970000
A31: THẺ LƯƠNG | B31: ='BANG LUONG 1'!$P$2 -> 43702
A32: Mã Nhân viên | B32: NV44 | C32: 1
A33: Họ và Tên | B33: =VLOOKUP($B32,'BANG LUONG 1'!$B$5:$AB$50,C33,0) -> Kim Em | C33: 2
A34: Chức vụ | B34: =VLOOKUP($B32,'BANG LUONG 1'!$B$5:$AJ$50,C34,0) -> Công nhân | C34: 3
A35: Ngày vào làm việc | B35: =VLOOKUP($B32,'BANG LUONG 1'!$B$4:$AJ$55,4,0) -> 42413 | C35: 4
A36: % thâm niên | B36: =VLOOKUP(B32,'BANG LUONG 1'!$B$4:$AJ$55,6,0) -> 0.03 | C36: 5
A37: Lương tối thiểu | B37: ='thang luong moi'!$F$5 -> 4012500 | C37: 6
A38: Ngạch lương | B38: =VLOOKUP(B32,'BANG LUONG 1'!$B$4:$AJ$55,8,0) -> B.05 | C38: 7
A39: hệ số lương | B39: =VLOOKUP(B32,'BANG LUONG 1'!$B$4:$AJ$55,9,0) -> 1 | C39: 8
A40: lương CB hệ số | B40: =VLOOKUP(B32,'BANG LUONG 1'!$B$4:$AJ$55,11,0) -> 4213125 | C40: 9
A41: Ngày công lv | B41: =VLOOKUP(B32,'BANG LUONG 1'!$B$4:$AJ$55,12,0) -> 27 | C41: 10
...

Sheet thang luong moi
A1: CÔNG TY TNHH CNSH SÀI GÒN XANH
C2: HỆ THỐNG THANG LƯƠNG, BẢNG LƯƠNG
A4: I/ MỨC LƯƠNG TỐI THIỂU:
A5: Mức lương tối thiểu mà doanh nghiệp đang áp dụng: | F5: 4012500 | G5: đồng/tháng
A7: II/ HỆ THỐNG THANG LƯƠNG: | F7: ĐVT: đồng
A9: 1- BẢNG LƯƠNG CHỨC VỤ QUẢN LÝ DOANH NGHIỆP
A11: CHỨC DANH CÔNG VIỆC | B11: MÃ SỐ | C11: BẬC/ HỆ SỐ/ MỨC LƯƠNG
C12: 1 | D12: 2 | E12: 3 | F12: 4 | G12: 5 | H12: 6 | I12: 7
A13: 01- TỔNG GIÁM ĐỐC
A14: Hệ số | C14: 6.5 | D14: =C14+1.5 -> 8 | E14: =D14+1.5 -> 9.5 | F14: =E14+1.5 -> 11 | G14: =F14+1.5 -> 12.5 | H14: =G14+1.5 -> 14 | I14: =H14+1.5 -> 15.5
A15: Mức lương tháng | B15: C.01 | C15: =C14*$F$5 -> 26081250 | D15: =D14*$F$5 -> 32100000 | E15: =E14*$F$5 -> 38118750 | F15: =F14*$F$5 -> 44137500 | G15: =G14*$F$5 -> 50156250 | H15: =H14*$F$5 -> 56175000 | I15: =I14*$F$5 -> 62193750
A16: Mức lương ngày | C16: =C15/26 -> 1003125 | D16: =D15/26 -> 1234615.4 | E16: =E15/26 -> 1466105.8 | F16: =F15/26 -> 1697596.2 | G16: =G15/26 -> 1929086.5 | H16: =H15/26 -> 2160576.9 | I16: =I15/26 -> 2392067.3
A17: 02- PHÓ TỔNG GIÁM ĐỐC/ GĐ ĐIỀU HÀNH
A18: Hệ số | C18: 3.5 | D18: =C18+1.5 -> 5 | E18: =D18+1.5 -> 6.5 | F18: =E18+1.5 -> 8 | G18: =F18+1.5 -> 9.5 | H18: =G18+1.5 -> 11 | I18: =H18+1.5 -> 12.5
A19: Mức lương tháng | B19: C.02 | C19: =C18*$F$5 -> 14043750 | D19: =D18*$F$5 -> 20062500 | E19: =E18*$F$5 -> 26081250 | F19: =F18*$F$5 -> 32100000 | G19: =G18*$F$5 -> 38118750 | H19: =H18*$F$5 -> 44137500 | I19: =I18*$F$5 -> 50156250
A20: Mức lương ngày | C20: =C19/26 -> 540144.23 | D20: =D19/26 -> 771634.62 | E20: =E19/26 -> 1003125 | F20: =F19/26 -> 1234615.4 | G20: =G19/26 -> 1466105.8 | H20: =H19/26 -> 1697596.2 | I20: =I19/26 -> 1929086.5
A21: 03- KẾ TOÁN TRƯỞNG/ Q.GIÁM ĐỐC / TRƯỞNG BAN
A22: Hệ số | C22: 2.5 | D22: =C22+1 -> 3.5 | E22: =D22+1 -> 4.5 | F22: =E22+1 -> 5.5 | G22: =F22+1 -> 6.5 | H22: =G22+1 -> 7.5 | I22: =H22+1 -> 8.5
A23: Mức lương tháng | B23: C.03 | C23: =C22*$F$5 -> 10031250 | D23: =D22*$F$5 -> 14043750 | E23: =E22*$F$5 -> 18056250 | F23: =F22*$F$5 -> 22068750 | G23: =G22*$F$5 -> 26081250 | H23: =H22*$F$5 -> 30093750 | I23: =I22*$F$5 -> 34106250
A24: Mức lương ngày | C24: =C23/26 -> 385817.31 | D24: =D23/26 -> 540144.23 | E24: =E23/26 -> 694471.15 | F24: =F23/26 -> 848798.08 | G24: =G23/26 -> 1003125 | H24: =H23/26 -> 1157451.9 | I24: =I23/26 -> 1311778.8
A26: 2- BẢNG LƯƠNG VIÊN CHỨC CHUYÊN MÔN, THỪA HÀNH, PHỤC VỤ
A28: CHỨC DANH CÔNG VIỆC | B28: MÃ SỐ | C28: BẬC/ HỆ SỐ/ MỨC LƯƠNG
C29: 1 | D29: 2 | E29: 3 | F29: 4 | G29: 5 | H29: 6 | I29: 7
A30: 01- CHUYÊN GIA CAO CẤP/ NGHỆ NHÂN
A31: Hệ số | C31: 2.5 | D31: =C31+0.8 -> 3.3 | E31: =D31+0.8 -> 4.1 | F31: =E31+0.8 -> 4.9 | G31: =F31+0.8 -> 5.7 | H31: =G31+0.8 -> 6.5 | I31: =H31+0.8 -> 7.3
A32: Mức lương tháng | B32: D.01 | C32: =C31*$F$5 -> 10031250 | D32: =D31*$F$5 -> 13241250 | E32: =E31*$F$5 -> 16451250 | F32: =F31*$F$5 -> 19661250 | G32: =G31*$F$5 -> 22871250 | H32: =H31*$F$5 -> 26081250 | I32: =I31*$F$5 -> 29291250
A33: Mức lương ngày | C33: =C32/26 -> 385817.31 | D33: =D32/26 -> 509278.85 | E33: =E32/26 -> 632740.38 | F33: =F32/26 -> 756201.92 | G33: =G32/26 -> 879663.46 | H33: =H32/26 -> 1003125 | I33: =I32/26 -> 1126586.5
A34: 02- TRƯỞNG BỘ PHẬN, KẾ TOÁN TỔNG HỢP, CHUYÊN VIÊN
A35: Hệ số | C35: 1.6 | D35: =C35+0.2 -> 1.8 | E35: =D35+0.2 -> 2 | F35: =E35+0.2 -> 2.2 | G35: =F35+0.2 -> 2.4 | H35: =G35+0.2 -> 2.6 | I35: =H35+0.2 -> 2.8
A36: Mức lương tháng | B36: D.02 | C36: =C35*$F$5 -> 6420000 | D36: =D35*$F$5 -> 7222500 | E36: =E35*$F$5 -> 8025000 | F36: =F35*$F$5 -> 8827500 | G36: =G35*$F$5 -> 9630000 | H36: =H35*$F$5 -> 10432500 | I36: =I35*$F$5 -> 11235000
A37: Mức lương ngày | C37: =C36/26 -> 246923.08 | D37: =D36/26 -> 277788.46 | E37: =E36/26 -> 308653.85 | F37: =F36/26 -> 339519.23 | G37: =G36/26 -> 370384.62 | H37: =H36/26 -> 401250 | I37: =I36/26 -> 432115.38
A38: 03- KẾ TOÁN VIÊN, NV HCNS, THỦ QUỸ, NV KỸ THUẬT ...
A39: Hệ số | C39: 1.3 | D39: =C39+0.1 -> 1.4 | E39: =D39+0.1 -> 1.5 | F39: =E39+0.1 -> 1.6 | G39: =F39+0.1 -> 1.7 | H39: =G39+0.1 -> 1.8 | I39: =H39+0.1 -> 1.9
A40: Mức lương tháng | B40: D.03 | C40: =C39*$F$5 -> 5216250 | D40: =D39*$F$5 -> 5617500 | E40: =E39*$F$5 -> 6018750 | F40: =F39*$F$5 -> 6420000 | G40: =G39*$F$5 -> 6821250 | H40: =H39*$F$5 -> 7222500 | I40: =I39*$F$5 -> 7623750
A41: Mức lương ngày | C41: =C40/26 -> 200625 | D41: =D40/26 -> 216057.69 | E41: =E40/26 -> 231490.38 | F41: =F40/26 -> 246923.08 | G41: =G40/26 -> 262355.77 | H41: =H40/26 -> 277788.46 | I41: =I40/26 -> 293221.15
A42: 04- NV KINH DOANH/ SALE ADMIN
A43: Hệ số | C43: 1.2 | D43: =C43+0.2 -> 1.4 | E43: =D43+0.2 -> 1.6 | F43: =E43+0.2 -> 1.8 | G43: =F43+0.2 -> 2 | H43: =G43+0.2 -> 2.2 | I43: =H43+0.2 -> 2.4
A44: Mức lương tháng | B44: D.04 | C44: =C43*$F$5 -> 4815000 | D44: =D43*$F$5 -> 5617500 | E44: =E43*$F$5 -> 6420000 | F44: =F43*$F$5 -> 7222500 | G44: =G43*$F$5 -> 8025000 | H44: =H43*$F$5 -> 8827500 | I44: =I43*$F$5 -> 9630000
A45: Mức lương ngày | C45: =C44/26 -> 185192.31 | D45: =D44/26 -> 216057.69 | E45: =E44/26 -> 246923.08 | F45: =F44/26 -> 277788.46 | G45: =G44/26 -> 308653.85 | H45: =H44/26 -> 339519.23 | I45: =I44/26 -> 370384.62
A46: 05- VĂN THƯ, LỄ TÂN
...

Sheet Bang luong (chaun)
A1: CÔNG TY TNHH CÔNG NGHỆ SINH HỌC SÀI GÒN XANH
A2: Nhà máy Xử lý Bùn thải Sài Gòn Xanh | J2: BẢNG LƯƠNG THÁNG 02 /2016 | K2: BẢNG LƯƠNG THÁNG 02 /2016 | T2: 42429 | AC2: Tỷ lệ đóng BH | AH2: 0.105
G3: =3500000*107% -> 3745000 | M3: 26 | V3: 1 | W3: 300000
A4: STT | B4: Mã Nhân viên | C4: Họ và Tên | D4: Chức vụ | E4: Ngày vào làm việc | F4: Số năm vào làm | G4: Lương tối thiểu | H4: Ngạch lương | I4: hệ số lương | J4: lương CB hệ số | K4: lương CB hệ số | M4: Ngày công lv | N4: Lương Định mức | O4: Ngày phép năm | P4: Giờ tăng ca | Q4: Giờ làm việc CN | R4: Ngày nghỉ lễ tết | S4: Ngày LV lễ tết | T4: Thành tiền lương CB | U4: lương vượt định mức | V4: Phụ Cấp thâm niên | W4: Phụ cấp chuyên cần | X4: Phụ cấp | Y4: Phụ cấp | Z4: Phụ cấp khác | AA4: Phụ cấp | AB4: PHỤ CẤP | AC4: Tổng thu nhập | AD4: =AE6-AD6 -> 1203750 | AF4: VALUE | AG4: Trừ tạm ứng | AH4: Trừ BHXH | AI4: Thực lãnh | AJ4: Thực lãnh | AK4: Ký Nhận | AM4: Tièn lương dóng BH
A5: G | C5: QUẢN LÝ SẢN XUẤT | AC5: =SUM(AC6:AC11) -> #N/A | AG5: =SUM(AG6:AG11) -> #REF! | AH5: =SUM(AH6:AH11) -> 1125600 | AI5: =SUM(AI6:AI11) -> #N/A | AJ5: =SUM(AJ6:AJ11) -> #N/A
A6: 1 | B6: NV44 | C6: Lê Quốc Chương | D6: Giám Đốc Nhà máy | E6: 42339 | F6: =IF(E6=0,0,INT((NOW()-E6)/365)) -> 3 | G6: =$G$3 -> 3745000 | H6: C.03 | I6: 3 | J6: 16852500 | K6: =VLOOKUP(H6,'thang luong moi'!B:I,'Bang luong (chaun)'!I6+1,0) -> 18056250 | L6: =(K6-J6)/K6 -> 0.066666667 | M6: =VLOOKUP(C6,CC!$C$5:$AJ$67,34,0) -> #N/A | N6: =K6/26*M6 -> #N/A | O6: =VLOOKUP(C6,CC!$C$5:$AM$67,36,0) -> #N/A | P6: =VLOOKUP(C6,CC!$C$5:$BS$67,69,0) -> #N/A | Q6: =VLOOKUP(C6,CC!$C$5:$BT$67,70,0) -> #N/A | R6: =VLOOKUP(C6,CC!$C$5:$AM$67,37,0) -> #N/A | S6: =VLOOKUP(C6,CC!$C$5:$AM$67,35,0) -> #N/A | T6: =((K6/26)*M6)+(O6*(K6/26))+((P6/8)*1.5*(K6/26))+((Q6/8)*2*K6/26)+(S6*3*(K6/26)+(K6/26)*R6) -> #N/A | V6: =IF((F6-$V$3)>0,F6%*K6,0) -> 541687.5 | Z6: 8148000 | AB6: =8148000-1872500 -> 6275500 | AC6: =T6+V6+W6+Z6+U6 -> #N/A | AD6: =J6+AB6 -> 23128000 | AE6: =K6+AB6 -> 24331750 | AF6: 25000000 | AG6: ='ung luong'!#REF! -> #REF! | AH6: =AM6*$AH$2 -> 0 | AI6: =AC6-AG6-AH6 -> #N/A | AJ6: =ROUND(AI6,-3) -> #N/A
A7: =A6+1 -> 2 | B7: NV45 | C7: Nguyễn Đình Huệ | D7: Quản đốc SX | E7: 38078 | F7: =IF(E7=0,0,INT((NOW()-E7)/365)) -> 15 | G7: =$G$3 -> 3745000 | H7: D.02 | I7: 2 | J7: 6366500 | K7: =VLOOKUP(H7,'thang luong moi'!B:I,'Bang luong (chaun)'!I7+1,0) -> 7222500 | L7: =(K7-J7)/K7 -> 0.11851852 | M7: =VLOOKUP(C7,CC!$C$5:$AJ$67,34,0) -> #N/A | N7: =K7/26*M7 -> #N/A | O7: =VLOOKUP(C7,CC!$C$5:$AM$67,36,0) -> #N/A | P7: =VLOOKUP(C7,CC!$C$5:$BS$67,69,0) -> #N/A | Q7: =VLOOKUP(C7,CC!$C$5:$BT$67,70,0) -> #N/A | R7: =VLOOKUP(C7,CC!$C$5:$AM$67,37,0) -> #N/A | S7: =VLOOKUP(C7,CC!$C$5:$AM$67,35,0) -> #N/A | T7: =((K7/26)*M7)+(O7*(K7/26))+((P7/8)*1.5*(K7/26))+((Q7/8)*2*K7/26)+(S7*3*(K7/26)+(K7/26)*R7) -> #N/A | V7: =IF((F7-$V$3)>0,F7%*K7,0) -> 1083375 | W7: =(100%-SUMIF('chuyên cần'!$C$6:$AP$31,'Bang luong (chaun)'!C7,'chuyên cần'!$AP$7:$AP$31))*$W$3 -> 300000 | Z7: 2999685 | AB7: 4000000 | AC7: =T7+V7+W7+Z7+U7 -> #N/A | AD7: =J7+AB7 -> 10366500 | AE7: =K7+AB7 -> 11222500 | AF7: 10741000 | AG7: ='ung luong'!#REF! -> #REF! | AH7: =AM7*$AH$2 -> 422100 | AI7: =AC7-AG7-AH7 -> #N/A | AJ7: =ROUND(AI7,-3) -> #N/A | AM7: 4020000
